Workbook

Sheet Mode d'emploi
A1: Cahier de recette complet : tests d'écran de la branche d'intégration
A3: Version testée | B3: Branche integration/recette-2026-10-29, déployée sur le poste local (domain1, http://localhost:8080/prestige), copie de travail laborex_v1_db.
A4: Résultat de Claude | B4: 422 tests joués par l'écran, 369 OK, 53 en échec. Chaque test a été joué seul, par le vrai chemin de l'écran, et retire ses données à la fin.
A5: Base | B5: Une copie de travail uniquement, jamais une base de production.
A6: Une ligne | B6: Un test d'écran. « Scénario » dit ce qui est fait et ce qui est attendu ; « Contrôles faits par Claude » liste chaque vérification (✓ conforme, ✗ écart) avec la valeur mesurée entre crochets.
A7: À remplir | B7: Rejouer le scénario à l'écran, noter ce que vous voyez dans « Résultat testeur », choisir le « Statut testeur » (OK, Échec, Bloqué, Non joué), votre nom et la date.
A8: Comparaison | B8: « Concorde ? » se remplit seul : « Oui » si votre statut est celui de Claude, « Non » sinon (ligne en jaune) ; ce sont ces lignes à examiner ensemble.
A9: Catégorie et suite | B9: Pour les échecs déjà triés : la cause retenue et ce qui est prévu.
A10: Onglets | B10: Synthèse, puis un onglet par module (dossier des tests).

Sheet Synthèse
A1: SYNTHÈSE — 422 tests, 369 OK, 53 en échec selon Claude
A3: Module | B3: N° | C3: Tests | D3: OK Claude | E3: Échec Claude | F3: Joués testeur | G3: Concordants | H3: Discordants
A4: Achats et contrôles | B4: 1 à 2 | C4: 2 | D4: 2 | E4: 0 | F4: =COUNTA('Achats et contrôles'!$I$5:$I$6) | G4: =COUNTIF('Achats et contrôles'!$L$5:$L$6,"Oui") | H4: =COUNTIF('Achats et contrôles'!$L$5:$L$6,"Non")
A5: Analyses | B5: 3 à 6 | C5: 4 | D5: 4 | E5: 0 | F5: =COUNTA('Analyses'!$I$5:$I$8) | G5: =COUNTIF('Analyses'!$L$5:$L$8,"Oui") | H5: =COUNTIF('Analyses'!$L$5:$L$8,"Non")
A6: Audit | B6: 7 à 9 | C6: 3 | D6: 3 | E6: 0 | F6: =COUNTA('Audit'!$I$5:$I$7) | G6: =COUNTIF('Audit'!$L$5:$L$7,"Oui") | H6: =COUNTIF('Audit'!$L$5:$L$7,"Non")
A7: Corrections d'audit | B7: 10 à 23 | C7: 14 | D7: 14 | E7: 0 | F7: =COUNTA('Corrections d'audit'!$I$5:$I$18) | G7: =COUNTIF('Corrections d'audit'!$L$5:$L$18,"Oui") | H7: =COUNTIF('Corrections d'audit'!$L$5:$L$18,"Non")
A8: Caisse | B8: 24 à 25 | C8: 2 | D8: 2 | E8: 0 | F8: =COUNTA('Caisse'!$I$5:$I$6) | G8: =COUNTIF('Caisse'!$L$5:$L$6,"Oui") | H8: =COUNTIF('Caisse'!$L$5:$L$6,"Non")
A9: Campagnes et WhatsApp | B9: 26 à 33 | C9: 8 | D9: 7 | E9: 1 | F9: =COUNTA('Campagnes et WhatsApp'!$I$5:$I$12) | G9: =COUNTIF('Campagnes et WhatsApp'!$L$5:$L$12,"Oui") | H9: =COUNTIF('Campagnes et WhatsApp'!$L$5:$L$12,"Non")
A10: Carnet dépôt | B10: 34 à 34 | C10: 1 | D10: 1 | E10: 0 | F10: =COUNTA('Carnet dépôt'!$I$5:$I$5) | G10: =COUNTIF('Carnet dépôt'!$L$5:$L$5,"Oui") | H10: =COUNTIF('Carnet dépôt'!$L$5:$L$5,"Non")
A11: Clients | B11: 35 à 38 | C11: 4 | D11: 4 | E11: 0 | F11: =COUNTA('Clients'!$I$5:$I$8) | G11: =COUNTIF('Clients'!$L$5:$L$8,"Oui") | H11: =COUNTIF('Clients'!$L$5:$L$8,"Non")
A12: Ergonomie | B12: 39 à 41 | C12: 3 | D12: 3 | E12: 0 | F12: =COUNTA('Ergonomie'!$I$5:$I$7) | G12: =COUNTIF('Ergonomie'!$L$5:$L$7,"Oui") | H12: =COUNTIF('Ergonomie'!$L$5:$L$7,"Non")
A13: Espace produit | B13: 42 à 42 | C13: 1 | D13: 0 | E13: 1 | F13: =COUNTA('Espace produit'!$I$5:$I$5) | G13: =COUNTIF('Espace produit'!$L$5:$L$5,"Oui") | H13: =COUNTIF('Espace produit'!$L$5:$L$5,"Non")
A14: Menus et articles | B14: 43 à 43 | C14: 1 | D14: 1 | E14: 0 | F14: =COUNTA('Menus et articles'!$I$5:$I$5) | G14: =COUNTIF('Menus et articles'!$L$5:$L$5,"Oui") | H14: =COUNTIF('Menus et articles'!$L$5:$L$5,"Non")
A15: Étape 2 | B15: 44 à 44 | C15: 1 | D15: 1 | E15: 0 | F15: =COUNTA('Étape 2'!$I$5:$I$5) | G15: =COUNTIF('Étape 2'!$L$5:$L$5,"Oui") | H15: =COUNTIF('Étape 2'!$L$5:$L$5,"Non")
A16: Étape 3 | B16: 45 à 46 | C16: 2 | D16: 2 | E16: 0 | F16: =COUNTA('Étape 3'!$I$5:$I$6) | G16: =COUNTIF('Étape 3'!$L$5:$L$6,"Oui") | H16: =COUNTIF('Étape 3'!$L$5:$L$6,"Non")
A17: Étape 5 | B17: 47 à 47 | C17: 1 | D17: 1 | E17: 0 | F17: =COUNTA('Étape 5'!$I$5:$I$5) | G17: =COUNTIF('Étape 5'!$L$5:$L$5,"Oui") | H17: =COUNTIF('Étape 5'!$L$5:$L$5,"Non")
A18: Facturation | B18: 48 à 48 | C18: 1 | D18: 1 | E18: 0 | F18: =COUNTA('Facturation'!$I$5:$I$5) | G18: =COUNTIF('Facturation'!$L$5:$L$5,"Oui") | H18: =COUNTIF('Facturation'!$L$5:$L$5,"Non")
A19: Filtres des écrans | B19: 49 à 52 | C19: 4 | D19: 3 | E19: 1 | F19: =COUNTA('Filtres des écrans'!$I$5:$I$8) | G19: =COUNTIF('Filtres des écrans'!$L$5:$L$8,"Oui") | H19: =COUNTIF('Filtres des écrans'!$L$5:$L$8,"Non")
A20: Inventaire | B20: 53 à 53 | C20: 1 | D20: 1 | E20: 0 | F20: =COUNTA('Inventaire'!$I$5:$I$5) | G20: =COUNTIF('Inventaire'!$L$5:$L$5,"Oui") | H20: =COUNTIF('Inventaire'!$L$5:$L$5,"Non")
A21: Journal | B21: 54 à 65 | C21: 12 | D21: 10 | E21: 2 | F21: =COUNTA('Journal'!$I$5:$I$16) | G21: =COUNTIF('Journal'!$L$5:$L$16,"Oui") | H21: =COUNTIF('Journal'!$L$5:$L$16,"Non")
A22: Lot 3 | B22: 66 à 68 | C22: 3 | D22: 2 | E22: 1 | F22: =COUNTA('Lot 3'!$I$5:$I$7) | G22: =COUNTIF('Lot 3'!$L$5:$L$7,"Oui") | H22: =COUNTIF('Lot 3'!$L$5:$L$7,"Non")
A23: Lot 4 | B23: 69 à 70 | C23: 2 | D23: 2 | E23: 0 | F23: =COUNTA('Lot 4'!$I$5:$I$6) | G23: =COUNTIF('Lot 4'!$L$5:$L$6,"Oui") | H23: =COUNTIF('Lot 4'!$L$5:$L$6,"Non")
A24: Application mobile | B24: 71 à 71 | C24: 1 | D24: 0 | E24: 1 | F24: =COUNTA('Application mobile'!$I$5:$I$5) | G24: =COUNTIF('Application mobile'!$L$5:$L$5,"Oui") | H24: =COUNTIF('Application mobile'!$L$5:$L$5,"Non")
A25: Performances | B25: 72 à 82 | C25: 11 | D25: 8 | E25: 3 | F25: =COUNTA('Performances'!$I$5:$I$15) | G25: =COUNTIF('Performances'!$L$5:$L$15,"Oui") | H25: =COUNTIF('Performances'!$L$5:$L$15,"Non")
A26: Pilotage | B26: 83 à 83 | C26: 1 | D26: 1 | E26: 0 | F26: =COUNTA('Pilotage'!$I$5:$I$5) | G26: =COUNTIF('Pilotage'!$L$5:$L$5,"Oui") | H26: =COUNTIF('Pilotage'!$L$5:$L$5,"Non")
A27: Points du 28-10 | B27: 84 à 91 | C27: 8 | D27: 8 | E27: 0 | F27: =COUNTA('Points du 28-10'!$I$5:$I$12) | G27: =COUNTIF('Points du 28-10'!$L$5:$L$12,"Oui") | H27: =COUNTIF('Points du 28-10'!$L$5:$L$12,"Non")
A28: Productivité | B28: 92 à 97 | C28: 6 | D28: 6 | E28: 0 | F28: =COUNTA('Productivité'!$I$5:$I$10) | G28: =COUNTIF('Productivité'!$L$5:$L$10,"Oui") | H28: =COUNTIF('Productivité'!$L$5:$L$10,"Non")
A29: Divers | B29: 98 à 104 | C29: 7 | D29: 5 | E29: 2 | F29: =COUNTA('Divers'!$I$5:$I$11) | G29: =COUNTIF('Divers'!$L$5:$L$11,"Oui") | H29: =COUNTIF('Divers'!$L$5:$L$11,"Non")
A30: Récapitulatifs | B30: 105 à 105 | C30: 1 | D30: 1 | E30: 0 | F30: =COUNTA('Récapitulatifs'!$I$5:$I$5) | G30: =COUNTIF('Récapitulatifs'!$L$5:$L$5,"Oui") | H30: =COUNTIF('Récapitulatifs'!$L$5:$L$5,"Non")
A31: Règlements | B31: 106 à 106 | C31: 1 | D31: 1 | E31: 0 | F31: =COUNTA('Règlements'!$I$5:$I$5) | G31: =COUNTIF('Règlements'!$L$5:$L$5,"Oui") | H31: =COUNTIF('Règlements'!$L$5:$L$5,"Non")
A32: Retours des officines | B32: 107 à 388 | C32: 282 | D32: 245 | E32: 37 | F32: =COUNTA('Retours des officines'!$I$5:$I$286) | G32: =COUNTIF('Retours des officines'!$L$5:$L$286,"Oui") | H32: =COUNTIF('Retours des officines'!$L$5:$L$286,"Non")
A33: Sécurité | B33: 389 à 401 | C33: 13 | D33: 12 | E33: 1 | F33: =COUNTA('Sécurité'!$I$5:$I$17) | G33: =COUNTIF('Sécurité'!$L$5:$L$17,"Oui") | H33: =COUNTIF('Sécurité'!$L$5:$L$17,"Non")
A34: Stock | B34: 402 à 402 | C34: 1 | D34: 1 | E34: 0 | F34: =COUNTA('Stock'!$I$5:$I$5) | G34: =COUNTIF('Stock'!$L$5:$L$5,"Oui") | H34: =COUNTIF('Stock'!$L$5:$L$5,"Non")
A35: Centre de support | B35: 403 à 417 | C35: 15 | D35: 12 | E35: 3 | F35: =COUNTA('Centre de support'!$I$5:$I$19) | G35: =COUNTIF('Centre de support'!$L$5:$L$19,"Oui") | H35: =COUNTIF('Centre de support'!$L$5:$L$19,"Non")
A36: Ventes | B36: 418 à 422 | C36: 5 | D36: 5 | E36: 0 | F36: =COUNTA('Ventes'!$I$5:$I$9) | G36: =COUNTIF('Ventes'!$L$5:$L$9,"Oui") | H36: =COUNTIF('Ventes'!$L$5:$L$9,"Non")
A37: Total | C37: =SUM(C4:C36) | D37: =SUM(D4:D36) | E37: =SUM(E4:E36) | F37: =SUM(F4:F36) | G37: =SUM(G4:G36) | H37: =SUM(H4:H36)

Sheet Achats et contrôles
A1: CAHIER DE RECETTE — Achats et contrôles
A2: 2 tests : 2 OK, 0 en échec selon Claude
A4: N° | B4: Test | C4: Scénario : ce qui est fait et ce qui est attendu | D4: Contrôles faits par Claude (valeur mesurée) | E4: Résultat Claude | F4: Écart constaté par Claude | G4: Catégorie et suite | H4: Résultat testeur | I4: Statut testeur | J4: Testeur | K4: Date | L4: Concorde ? | M4: Commentaire
A5: 1 | B5: achats/test-controle-achats-inventaire.js | C5: ETAT DE CONTROLE DES ACHATS : INVENTAIRE D'UN BON (retours du 13/10, point 5). - un bon de livraison entre en stock RAYON : l'inventaire cree depuis la ligne est un inventaire de l'emplacement (type « emplacement »), pas un inventaire reserve, et chaque produit y part de son stock rayon ; - la question puis le resultat s'affichent EN ENTIER dans la page (bandeau), sans fenetre surgissante ; - « Annuler » ne cree rien. Par l'ecran, admin. Inventaires crees retires a la fin. | D5: 11 / 11 conformes ✓ Précondition : un bon avec des produits en stock [ABJ/641734 : 3] ✓ Question affichée dans la page, en entier, sans fenêtre [{"visible":true,"texte":"Créer un inventaire des produits du bon ABJ/641734 ? Il portera sur le stock rayon, celui où le bon est entré. Créer l'inventaire Annuler","tronque":false,"boite":false}] ✓ La question dit que l'inventaire porte sur le stock rayon [Créer un inventaire des produits du bon ABJ/641734 ? Il portera sur le stock rayon, celui où le bon est entré. Créer l'inventaire Annuler] ✓ Annuler : rien n'est créé, le bandeau disparaît ✓ Un inventaire créé [1] ✓ Inventaire de l'emplacement (stock rayon), pas un inventaire réserve [emplacement / 1] ✓ Tous les produits du bon y sont ✓ Chaque produit part de son stock rayon ✓ Résultat affiché en entier dans la page, sans fenêtre [Inventaire créé : 3 article(s), sur le stock rayon. Il s'appelle « Inventaire rayon BL ABJ/641734 30102026-095216 » dans la liste des inventaires. Fermer] ✓ Aucune fenêtre du navigateur [] ✓ Inventaires d'essai retirés | E5: OK | L5: =IF(I5="","",IF(I5=E5,"Oui","Non"))
A6: 2 | B6: achats/test-controle-achats.js | C6: Point 17 : etat de controle des achats. - filtre sur le statut du controle (Controle / Non controle / Tous) ; - filtre sur les ecarts (Avec ecarts / Sans ecart / Tous) ; - bouton Details par ligne ; - impression respectant les filtres et rappelant les criteres. | D6: 16 / 16 conformes ✓ ecran Etat de controle des achats ouvert ✓ le filtre de statut propose Controle / Non controle / Tous [["TOUS","CONTROLE","NON_CONTROLE"]] ✓ le filtre d ecarts propose Avec / Sans / Tous [["TOUS","AVEC_ECART","SANS_ECART"]] ✓ la colonne Details est presente sur chaque ligne ✓ la liste sans filtre repond [total=17255] ✓ les deux statuts se partagent exactement la liste [controles=3972 non=13283 total=17255] ✓ les deux valeurs d ecart se partagent exactement la liste [avec=3162 sans=14093 total=17255] ✓ le bon prepare en ecart est bien retenu par le filtre [avec ecart=3162] ✓ les deux filtres se combinent [combine=3099] ✓ l impression aboutit [{"msg":"/data/reports/pdf/controle_achats_2026_10_30_09_58_54.pdf","success":true}] ✓ le PDF a bien ete ecrit [D:\payara5\payara5\glassfish\domains\domain1\applications\prestige\data\reports\pdf\controle_achats_2026_10_30_09_58_54.pdf] ✓ le fichier est un PDF non vide [octets=641250] ✓ les criteres retenus sont rappeles sur l etat [longueur texte=5254902] ✓ l etat est regroupe par grossiste avec sous-totaux ✓ le total general est edite ✓ aucune erreur JavaScript | E6: OK | L6: =IF(I6="","",IF(I6=E6,"Oui","Non"))

Sheet Analyses
A1: CAHIER DE RECETTE — Analyses
A2: 4 tests : 4 OK, 0 en échec selon Claude
A4: N° | B4: Test | C4: Scénario : ce qui est fait et ce qui est attendu | D4: Contrôles faits par Claude (valeur mesurée) | E4: Résultat Claude | F4: Écart constaté par Claude | G4: Catégorie et suite | H4: Résultat testeur | I4: Statut testeur | J4: Testeur | K4: Date | L4: Concorde ? | M4: Commentaire
A5: 3 | B5: analyse/test-analyse-tierspayant.js | C5: Point 5 : analyse tiers payant. - export Excel du resultat complet, aux deux niveaux ; - le choix d'un groupe tiers payant declenche la recherche ; - creation d'une suggestion a partir des produits du RESULTAT COURANT, avec le nombre integre. | D5: 13 / 13 conformes ✓ ecran Analyse tiers payant ouvert ✓ les deux grilles sont alimentees [{"tp":519,"produits":4364}] ✓ boutons Excel et Créer une suggestion presents [{"excel":true,"excelTp":true,"excelProd":true,"suggestion":true}] ✓ export Excel TIERSPAYANT : classeur valide [{"status":200,"taille":32757,"signature":"PK"}] ✓ export Excel PRODUIT : classeur valide [{"status":200,"taille":246770,"signature":"PK"}] ✓ choisir un groupe tiers payant lance la recherche [groupe=WILLIS TOWERS WATSON appels avant=2 apres=3] ✓ la suggestion est creee [{"success":true,"count":4186,"produitsDuResultat":4364,"produitsCommandables":4364}] ✓ la suggestion de tout le resultat est creee en moins de 60 s [25 s pour 4186 produits] ✓ le nombre de produits integres est annonce [{"success":true,"count":4186,"produitsDuResultat":4364,"produitsCommandables":4364}] ✓ le perimetre du resultat courant est rappele [{"success":true,"count":4186,"produitsDuResultat":4364,"produitsCommandables":4364}] ✓ la suggestion ne retient que les produits du resultat filtre [cip=3532111 -> {"success":true,"count":1,"produitsDuResultat":1,"produitsCommandables":1}] ✓ une recherche sans resultat ne cree pas de suggestion [{"msg":"Aucun produit dans le résultat courant : la suggestion n'a pas été créée.","success":false}] ✓ aucune erreur JavaScript | E5: OK | L5: =IF(I5="","",IF(I5=E5,"Oui","Non"))
A6: 4 | B6: analyse/test-selecteur-periodes.js | C6: Le selecteur de periodes de comparaison. Deux choses sont verifiees ici, et ce sont les deux ou une erreur passerait inapercue. 1. LA REGLE DES BORNES. « 3 derniers mois » designe les trois mois REVOLUS, et le mois en cours est rappele EN PLUS, marque comme tel. Compter le mois entame comme un mois complet ferait lire un effondrement du chiffre d'affaires le 2 du mois -- un chiffre faux, mais plausible. 2. LA BASCULE A DEUX. Une seule periode donne les chiffres bruts ; a partir de deux, les ecarts apparaissent. Afficher une colonne d'ecart vide sans rien dire laisserait croire a une stagnation. | D6: 35 / 35 conformes ✓ Le fichier de configuration est charge ✓ Il liste les deux menus demandes [cazonegeomanager, balancesalecahs] ✓ Il porte les quatre choix [TROIS_SEMAINES, TROIS_MOIS, SIX_MOIS, TROIS_ANS, LIBRE] ✓ Il expose le point d'accroche ✓ La balance porte son propre selecteur (onglet Analyse) ✓ L'injecteur le laisse tel quel ✓ Il propose 3 dernieres semaines par defaut (retours des tests 4) [TROIS_SEMAINES] ✓ Une seconde application n'en pose pas un deuxieme [1] ✓ L'onglet Balance n'a pas de liste deroulante de periode ✓ La balance a bien ses onglets (Balance, Analyse comparative, Evolution par mode, Balance (ancienne) cachee) [Balance | Analyse comparative | &Eacute;volution par mode de paiement | Balance (ancienne)] ✓ Le second est l'analyse comparative [Balance | Analyse comparative | &Eacute;volution par mode de paiement | Balance (ancienne)] ✓ L'ecran qui avait deja son selecteur n'en recoit pas un second [1] ✓ Et il lit la MEME liste de choix [TROIS_SEMAINES, TROIS_MOIS, SIX_MOIS, TROIS_ANS, LIBRE] ✓ Un ecran hors liste ne recoit rien ✓ 3 derniers mois rend 4 tranches [2026-07 | 2026-08 | 2026-09 | 2026-10] ✓ Ce sont les 3 mois revolus, plus le mois en cours [2026-07 | 2026-08 | 2026-09 | 2026-10 attendu 2026-07 | 2026-08 | 2026-09 | 2026-10] ✓ Seule la derniere tranche est marquee en cours [2026-07=false | 2026-08=false | 2026-09=false | 2026-10=true] ✓ Les tranches revolues sont completes [2026-07-01..2026-07-31 | 2026-08-01..2026-08-31 | 2026-09-01..2026-09-30 | 2026-10-01..2026-10-30] ✓ La tranche en cours s'arrete aujourd'hui [2026-10-30] ✓ 6 derniers mois rend 7 tranches [7] ✓ Ce sont les 6 mois revolus, plus le mois en cours [2026-04 | 2026-05 | 2026-06 | 2026-07 | 2026-08 | 2026-09 | 2026-10] ✓ 3 dernieres semaines rend 4 tranches [2026-W41 | 2026-W42 | 2026-W43 | 2026-W44] ✓ Les semaines vont du lundi au dimanche [2026-10-05..2026-10-11 | 2026-10-12..2026-10-18 | 2026-10-19..2026-10-25 | 2026-10-26..2026-10-30] ✓ 3 dernieres annees rend 4 tranches [2023 | 2024 | 2025 | 2026] ✓ Ce sont les 3 annees revolues, plus celle en cours [2023 | 2024 | 2025 | 2026] ✓ Plusieurs periodes : le mode comparatif est annonce ✓ La premiere tranche n'a pas d'ecart [{"libelle":"2023","montantMobilePayment":0,"fin":"2023-12-31","montantTTC":0,"montantAchat":28454723,"montantEsp":0,"montantRemise":0,"enCours":false,"nbreVente":0,"montantMobile":0,"debut":"2023-01-01","montantNet":0,"marge":0,"montantCB":0,"panierMoyen":0,"montantTp":0,"parModes":{},"montantDiff":] ✓ Les suivantes en ont un [ | 581767223 | 666240336 | 201062768] ✓ Une seule periode : le mode comparatif est refuse [{"total":1,"graphique":{"series":[{"valeurs":{"montantNet":[0],"panierMoyen":[0],"montantTp":[0],"montantMobilePayment":[0],"montantAchat":[0],"montantEsp":[0],"nbreVente":[0]},"libelle":"Valeur"}],"i] ✓ Et son ecart reste vide [{"libelle":"29/10","montantMobilePayment":0,"fin":"2026-10-29","montantTTC":0,"montantAchat":0,"montantEsp":0,"montantRemise":0,"enCours":false,"nbreVente":0,"montantMobile":0,"debut":"2026-10-29","montantNet":0,"marge":0,"montantCB":0,"panierMoyen":0,"montantTp":0,"parModes":{},"montantDiff":0,"eca] ✓ L'analyse d'une tranche donne les MEMES chiffres que la balance de la meme periode [analyse 0/0 vs balance 0/0] ✓ L'export Excel de l'analyse repond [{"statut":200,"taille":6144,"type":"application/vnd.ms-excel"}] ✓ La classe « periode-en-cours » existe en CSS ✓ Les classes « classe-abc-* » existent en CSS ✓ Aucune erreur JavaScript | E6: OK | L6: =IF(I6="","",IF(I6=E6,"Oui","Non"))
A7: 5 | B7: analyse/test-stats-famille-rayon-vide.js | C7: STATISTIQUES PAR FAMILLE / RAYON / GROSSISTE SUR UNE PERIODE SANS VENTE (journaux du 13/10). Avant : NullPointerException (total HT vide) puis NumberFormatException « Infinite or NaN » (division par zero), avalees : totaux et pourcentages absents, et sur une periode ou le HT total est nul la liste etait tronquee au premier rayon. - periode vide : reponse complete, totaux a 0, aucune erreur dans le journal du serveur ; - periode avec ventes : memes resultats qu'avant (pourcentages identiques, somme des lignes = total). Lecture seule. | D7: 16 / 16 conformes ✓ familles, période sans vente : réponse complète, totaux à 0 [{"totalRemiseVeto":0,"montantCumulHT":0,"MARGE POURCENTAGE":0,"totalCaVeto":0,"montantRemise":0,"totalRemiseVetoVNO":0,"totalRemiseVO":0,"pourcentageCumulTH":0,"totalRemiseVNO":0,"MONTANT NET TTC":0,"] ✓ familles, période sans vente : aucune erreur dans le journal du serveur [] ✓ familles, période avec ventes : lignes complètes, somme des lignes = total [11 lignes, 154253420 / 154253420] ✓ familles, période avec ventes : pourcentages calculés [28] ✓ rayons, période sans vente : réponse complète, totaux à 0 [{"totalRemiseVeto":0,"montantCumulHT":0,"MARGE POURCENTAGE":0,"totalCaVeto":0,"montantRemise":0,"totalRemiseVetoVNO":0,"totalRemiseVO":0,"pourcentageCumulTH":0,"totalRemiseVNO":0,"MONTANT NET TTC":0,"] ✓ rayons, période sans vente : aucune erreur dans le journal du serveur [] ✓ rayons, période avec ventes : lignes complètes, somme des lignes = total [35 lignes, 154253420 / 154253420] ✓ rayons, période avec ventes : pourcentages calculés [28] ✓ grossistes, période sans vente : réponse complète, totaux à 0 [{"totalRemiseVeto":0,"montantCumulHT":0,"MARGE POURCENTAGE":0,"totalCaVeto":0,"montantRemise":0,"totalRemiseVetoVNO":0,"totalRemiseVO":0,"pourcentageCumulTH":0,"totalRemiseVNO":0,"MONTANT NET TTC":0,"] ✓ grossistes, période sans vente : aucune erreur dans le journal du serveur [] ✓ grossistes, période avec ventes : lignes complètes, somme des lignes = total [41 lignes, 154253420 / 154253420] ✓ grossistes, période avec ventes : pourcentages calculés [28] ✓ veto, période sans vente : réponse complète, totaux à 0 [{"totalRemiseVeto":0,"montantCumulHT":0,"MARGE POURCENTAGE":0,"totalCaVeto":0,"montantRemise":0,"totalRemiseVetoVNO":0,"totalRemiseVO":0,"pourcentageCumulTH":0,"totalRemiseVNO":0,"MONTANT NET TTC":0,"] ✓ veto, période sans vente : aucune erreur dans le journal du serveur [] ✓ veto, période avec ventes : lignes complètes, somme des lignes = total [11 lignes, 154253420 / 154253420] ✓ veto, période avec ventes : pourcentages calculés [28] | E7: OK | L7: =IF(I7="","",IF(I7=E7,"Oui","Non"))
A8: 6 | B8: analyse/test-unites-vendues-vno-vo.js | C8: UNITES VENDUES : COLONNES « Nbre.VNO » ET « Nbre.VO » (demande du 16/10). La requete calculait le total de l'article puis le rangeait en VNO ou en VO selon le type d'UNE vente prise au hasard parmi les siennes : les deux colonnes changeaient d'un appel a l'autre. Ce que le test etablit (lecture seule) : - deux appels de suite donnent les memes colonnes ; - pour chaque article : Nbre.VNO = quantite des ventes au comptant (type 1), Nbre.VO = quantite des ventes VO, calculees en SQL avec les memes filtres (periode, emplacement, cloturees, non annulees, montant > 0, hors depot) ; - Nbre.VNO + Nbre.VO = quantite vendue. | D8: 3 / 3 conformes ✓ Deux appels de suite : mêmes colonnes VNO / VO [4756 articles] ✓ Chaque article : Nbre.VNO et Nbre.VO = quantités vendues au comptant et en VO (SQL) [0 écarts sur 4756 ; ] ✓ Nbre.VNO + Nbre.VO = quantité vendue [0 écarts] | E8: OK | L8: =IF(I8="","",IF(I8=E8,"Oui","Non"))

Sheet Audit
A1: CAHIER DE RECETTE — Audit
A2: 3 tests : 3 OK, 0 en échec selon Claude
A4: N° | B4: Test | C4: Scénario : ce qui est fait et ce qui est attendu | D4: Contrôles faits par Claude (valeur mesurée) | E4: Résultat Claude | F4: Écart constaté par Claude | G4: Catégorie et suite | H4: Résultat testeur | I4: Statut testeur | J4: Testeur | K4: Date | L4: Concorde ? | M4: Commentaire
A5: 7 | B5: audit/test-audit-analyse.js | C5: AUDIT & RAPPROCHEMENTS, onglet Analyse (besoins du 11/10, point 6). Par l'ecran (menu Centre de support) : - un ecart connu est pose dans chaque controle, puis l'analyse est lancee depuis l'ecran ; - un reassort reserve -> rayon posterieur au dernier mouvement n'est pas un ecart de stock ; un ecart apres reassort se compte depuis le stock rayon apres reassort ; - chaque tuile passe au rouge et son detail montre la ligne posee, avec l'ecart attendu : stock reel / historique (+7), stock negatif (-3), caisse ouverte depuis 3 jours, billetage (-10 000 000, pour rester parmi les plus gros ecarts rendus sur une base reelle), differe (reste du 4 000 / releve 5 000), carnet depot (+1 000) ; controles de coherence listes ; - l'analyse n'ecrit rien (sommes de controle des tables lues identiques avant et apres) ; - aucune fenetre ; sans le droit P_SM_AUDIT, l'API refuse. Tout ce qui est pose est retire a la fin, rapports conserves par « Lancer l'analyse » compris. | D5: 17 / 17 conformes ✓ Analyse à l'ouverture en moins de 10 s avec 300 clients en différé et 7200 règlements [{"ms":4087}] ✓ Menu « Audit & rapprochements » (≤ 25 caractères) dans le Centre de support [Audit & rapprochements] ✓ L'analyse n'écrit rien (sommes de contrôle de 10 tables identiques) ✓ Stock / historique : tuile rouge, produit modifié présent avec un écart de +7 [{"cip":"3000147","libelle":"A 313 POM TB/50G","emplacement":"OFFICINE","stockReel":7,"stockHistorique":0,"ecart":7,"dernierMouvement":"19/07/2026 16:21","produitId":"14824102650702805490"}] ✓ Stock / historique : un réassort réserve → rayon après le dernier mouvement n'est pas un écart ✓ Stock / historique : écart compté depuis le réassort (stock historique = rayon après réassort, +2) [{"cip":"8637783","libelle":"A CERUMEN UNIDOSE 2ML B/ 10 AFR","emplacement":"OFFICINE","stockReel":27,"stockHistorique":25,"ecart":2,"dernierMouvement":"30/10/2026 14:24","produitId":"14113164653813600217"}] ✓ Stocks négatifs : produit à −3 présent [{"cip":"8486901D","libelle":"CLOTRIMAZOLE UBI 200MG VAG/10 BT/3 DET","emplacement":"OFFICINE","stockReel":-3,"produitId":"57339880756001606"}] ✓ Caisses ouvertes : caisse ouverte il y a 3 jours présente (3 jours) [{"caissier":"Essai E2E SA","ouverture":"27/10/2026 08:30","jours":3,"caisse":"E2E-AUD-OUV"}] ✓ Billetage : manquant de 10 000 000 sur la caisse de la veille [{"caissier":"Essai E2E SA","ouverture":"29/10/2026 08:00","fermeture":"29/10/2026 18:00","attendu":100000000,"billetage":90000000,"ecart":-10000000,"caisse":"E2E-AUD-FER"}] ✓ Différés : reste dû 4 000 / relevé 5 000 (écart −1 000) [{"client":"ZZAUDIT Differe","ventes":10000,"reglements":5000,"soldeReleve":5000,"resteDu":4000,"ecart":-1000,"clientId":"E2E-AUD-C"}] ✓ Carnets dépôt : ZZ E2E AUDIT DEPOT avec un écart de +1 000 [{"depot":"ZZ E2E AUDIT DEPOT","solde":1000,"ventes":0,"reglements":0,"retours":0,"soldeCalcule":0,"ecart":1000,"tiersPayantId":"E2E-AUD-TP"}] ✓ Contrôles de cohérence : les contrôles actifs sont listés [18] ✓ Le détail choisi s'explique en clair au-dessus de la liste [Contrôles de cohérence : Contrôles automatiques du centre de support, rejoués ic] ✓ Aucune fenêtre affichée [] ✓ Écart retiré : il disparaît à l'analyse suivante ✓ Sans le droit P_SM_AUDIT : analyse refusée par le serveur [{"msg":"Vous n'avez pas le droit de consulter l'audit.","success":false}] ✓ Données d'essai retirées | E5: OK | L5: =IF(I5="","",IF(I5=E5,"Oui","Non"))
A6: 8 | B6: audit/test-audit-rapports.js | C6: AUDIT & RAPPROCHEMENTS, onglet Rapports (besoins du 11/10, point 6). Par l'ecran : - ouvrir l'ecran ne conserve aucun rapport ; « Lancer l'analyse » en conserve un (auteur, periode, resultat) ; - rapport 1 avec un ecart de stock pose sur un produit, rapport 2 apres l'avoir retire et pose un stock negatif ; - onglet Rapports : les deux rapports, le plus recent en tete, nombre d'ecarts par controle ; - comparaison des deux : l'ecart de stock est « resolu », le stock negatif est « nouveau » ; - « Voir le rapport » l'affiche dans l'onglet Analyse avec un bandeau (ce n'est pas la situation actuelle) ; - PDF (contenu lu) et Excel ; le PDF s'ouvre dans un onglet du navigateur, aucune fenetre de message. Tout ce qui est pose (stocks, rapports du test) est retire a la fin. | D6: 18 / 18 conformes ✓ Ouvrir l'écran ne conserve aucun rapport ✓ « Lancer l'analyse » conserve le rapport 1 ✓ Rapport 1 : auteur et période du billetage enregistrés [Essai E2E SA 2026-10-01 2026-10-30] ✓ « Lancer l'analyse » conserve le rapport 2 ✓ Liste : les deux rapports, le plus récent en tête [30/10/2026 10:01 / 30/10/2026 10:01] ✓ Liste : nombre d'écarts par contrôle (stocks négatifs : 1 de plus dans le rapport 2) [[{"CONTROLES":4,"DIFFERES":0,"CAISSES_OUVERTES":9,"STOCK":23,"STOCK_NEGATIF":11,"BILLETAGE":103,"CARNETS":0},{"CONTROLES":4,"DIFFERES":0,"CAISSES_OUVERTES":9,"STOCK":22,"STOCK_NEGATIF":12,"BILLETAGE":103,"CARNETS":0}]] ✓ Aucun rapport coché : boutons inactifs ✓ Deux rapports cochés : « Comparer » actif, « Voir » et éditions inactifs ✓ Comparaison : l'écart de stock du produit modifié est résolu [8452598 3 HP KIT GEL/2 + CPR/4 KIT/14 (OFFICINE) : écart 7] ✓ Comparaison : le stock négatif est un nouvel écart [8486901D CLOTRIMAZOLE UBI 200MG VAG/10 BT/3 DET (OFFICINE) : stock -3] ✓ Un rapport coché : « Voir », PDF et Excel actifs ✓ « Voir » : rapport 1 dans l'onglet Analyse, bandeau affiché, écart du produit modifié présent [ongletAnalyse] ✓ « Revenir à l'analyse du jour » retire le bandeau sans conserver de rapport ✓ PDF : ouvert dans un onglet du navigateur [http://localhost:8080/prestige/api/v1/audit/rapports/38607071-6f76-40b7-992a-929dace1bb4e/pdf] ✓ PDF : titre, synthèse des contrôles et ligne du produit modifié [GRANDE PHARMACIE DE LA CAPITALE ✓ Excel : fichier .xls (classeur) téléchargé [{"type":"application/vnd.ms-excel","debut":[208,207,17,224],"taille":19456,"nom":"attachment; filename=\"audit_301020261001.xls\""}] ✓ Aucune fenêtre de message [] ✓ Données retirées (stocks, rapports du test) | E6: OK | L6: =IF(I6="","",IF(I6=E6,"Oui","Non"))
A7: 9 | B7: audit/test-audit-regularisations.js | C7: AUDIT & RAPPROCHEMENTS, onglet Regularisations (besoins du 11/10, point 6). Par l'ecran, sur des donnees du test : - historique pose sur deux produits sans aucun mouvement, en aout 2038 (aucune donnee reelle) : une entree au depot ecrite a l'envers (4 -> 1 pour +3), un deconditionnement gonfle (104 -> 204) et la vente de la meme seconde partant du stock d'avant ouverture (4 -> 99 pour 5) ; - une caisse oubliee (ouverte il y a 3 jours) d'un caissier d'essai ; - les quatre regularisations sont proposees ; sans commentaire, la validation est refusee a l'ecran ; - validees : entree 4 -> 7, deconditionnement 4 -> 104 puis vente 104 -> 99 (chaine coherente), caisse fermee au nom de son caissier avec le montant compte (billetage enregistre) ; - journal : une ligne par regularisation, auteur, commentaire, valeurs d'avant ; une regularisation appliquee n'est plus proposee, et la rejouer par l'API ne change rien ; - les ecarts a corriger ailleurs ouvrent leur ecran habituel ; sans le droit P_AUDIT_REGULARISER, l'API refuse ; - aucune fenetre. Tout ce qui est pose ou produit est retire a la fin. | D7: 17 / 17 conformes ✓ Proposées : entrée au dépôt à l'envers, déconditionnement gonflé, vente après ouverture, caisse oubliée [HISTO_DECON_204, HISTO_VENTE_DECON, HISTO_ENTREE_DEPOT, CAISSE_OUVERTE] ✓ Chaque proposition dit ce qui sera fait ✓ Sans commentaire : rien n'est appliqué, message dans la page [<span style="color:#c0392b">Le commentaire est obligatoire.</span>] ✓ Entrée au dépôt : 4 → 7 (hausse) [4>7] ✓ Déconditionnement : 104 → 204 ramené à 4 → 104 [4>104] ✓ Appliquées : elles ne sont plus proposées ✓ Vente : part de 104 (stock après ouverture) → 99 : chaîne 4 → 104 → 99 [104>99] ✓ Caisse : se valide seule, le montant compté se saisit alors [{"valider":true,"montant":true} bloquée avec d'autres : true] ✓ Caisse sans montant : refusée à l'écran [<span style="color:#c0392b">Indiquez le montant compté dans la caisse.</span>] ✓ Caisse fermée au nom de son caissier, billetage de 12 500 enregistré [is_Process|12500.00] ✓ Journal : 4 régularisations, auteur et valeurs d'avant enregistrés [4 4 4] ✓ Journal affiché : commentaire, objet et montant de la caisse [[{"date":"30/10/2026 10:02","auteur":"Essai E2E SA","type":"Caisse oubliée à fermer","objet":"ZZESSAI Caissier, caisse ouverte le 27/10/2026 08:30","lignes":1,"montant":12500,"commentaire":"Caisse oubliée, comptée le matin"},{"date":"30/10/2026 10:02","auteur":"Essai E2E SA","type":"Historique : ven] ✓ Rejouée par l'API : refusée (« plus d'objet »), historique inchangé [{"msg":"Cette régularisation n'a plus d'objet (déjà appliquée ?).","success":false}] ✓ Écarts à corriger ailleurs : liens vers leur écran (ajustement, caisse, différés, carnets, diagnostic) [ajustementmanager, ajustementmanager, gestcaissemanager, supportdiagnostic] ✓ Aucune fenêtre [] ✓ Sans le droit : consultation possible, validation refusée par le serveur [{"msg":"Vous n'avez pas le droit de valider les régularisations.","success":false}] ✓ Données du test retirées | E7: OK | L7: =IF(I7="","",IF(I7=E7,"Oui","Non"))

Sheet Corrections d'audit
A1: CAHIER DE RECETTE — Corrections d'audit
A2: 14 tests : 14 OK, 0 en échec selon Claude
A4: N° | B4: Test | C4: Scénario : ce qui est fait et ce qui est attendu | D4: Contrôles faits par Claude (valeur mesurée) | E4: Résultat Claude | F4: Écart constaté par Claude | G4: Catégorie et suite | H4: Résultat testeur | I4: Statut testeur | J4: Testeur | K4: Date | L4: Concorde ? | M4: Commentaire
A5: 10 | B5: audits/repro-assurances-liens.js | C5: REPRODUCTION — MODULE ASSURANCES : LIENS CLIENT / TIERS PAYANT (constats M1, M2, M3, M4). Regle metier de reference : un seul RO actif par client, un carnet n'est jamais RO. Clients d'essai crees par l'ecran client, tiers payants d'essai copies d'organismes existants. FAIL = defaut reproduit (mesure entre crochets). Lancement seul : node src/test/e2e/audits/repro-assurances-liens.js | D5: 15 / 15 conformes ✓ N8 attendu : un client assuré créé avec succès par l'écran existe en base (client / compte / ayant droit = 1 / 1 / 1) [réponse succès, identifiant fca6ca98-57b3-49dc-b44d-021b619bc340 ; en base client / compte / ayant droit : 1 / 1 / 1] ✓ M1 attendu : associer un carnet à un client assuré garde son assurance active et RO, le carnet n'est pas RO [réponse {"data":{"strLASTNAME":"ZZAUDIT M1","lgTIERSPAYANTID":"ZZAUDIT-TP-M1A","fullName ; liens avant M1A/enable/RO=1/prio=1 ; après M1A/enable/RO=1/prio=1 ; M1K/enable/RO=0/prio=2] ✓ M2 attendu : après « Modifier client / tiers payant » vers un organisme non rattaché, le client n'a qu'un seul RO actif [réponse {"msg":"Opération effectuée avec succèss","success":true,"refId":"1ab947df-fb98- ; RO actifs 1 ; liens M2A/enable/RO=0/prio=2 ; M2B/enable/RO=1/prio=1] ✓ M3 attendu : la complémentaire C remplaçant un lien supprimé est créée active avec une priorité ≥ 1, sans hériter du lien supprimé [réponse {"msg":"Opération effectuée avec succèss","success":true,"refId":"dff9800b-7f78- ; liens M3A/enable/RO=1/prio=1 ; M3B/delete/RO=0/prio=-1 ; M3C/enable/RO=0/prio=2] ✓ M2 attendu (case « principal » non cochée) : un seul RO actif après le changement d'organisme [réponse {"msg":"Opération effectuée avec succèss","success":true,"refId":"aef71b08-06f2- ; RO actifs 1 ; liens M2bA/enable/RO=1/prio=1 ; M2bB/enable/RO=0/prio=2] ✓ M3 attendu (case « principal » non cochée) : la complémentaire C est créée active avec une priorité ≥ 1 [réponse {"msg":"Opération effectuée avec succèss","success":true,"refId":"161758e1-f279- ; liens M3bA/enable/RO=1/prio=1 ; M3bC/enable/RO=0/prio=2 ; M3bB/delete/RO=0/prio=-1] ✓ M4 attendu : enregistrer la modification sans rien changer laisse l'assurance RO et le carnet non RO [réponse {"msg":"Opération effectuée avec succèss","success":true,"refId":"6b183754-82bc- ; liens avant M4A/enable/RO=1/prio=2 ; M4K/enable/RO=0/prio=1 ; M4D/delete/RO=0/prio=-1 ; après M4A/enable/RO=1/prio=2 ; M4K/enable/RO=0/prio=1 ; M4D/delete/RO=0/prio=-1] ✓ M4 attendu : le lien supprimé garde sa priorité -1 (il n'est pas reclassé avec les liens actifs) [M4A/enable/RO=1/prio=2 ; M4K/enable/RO=0/prio=1 ; M4D/delete/RO=0/prio=-1] ✓ P21-a attendu : RO changé de A en B par « Modifier infos client » : B RO en priorité 1, A reste actif (non RO) en priorité libre, aucune priorité en double [réponse {"data":{"strLASTNAME":"ZZAUDIT P21A","lgTIERSPAYANTID":"ZZAUDIT-TP-P21aB","full ; liens avant P21aA/enable/RO=1/prio=1 ; P21aC/enable/RO=0/prio=2 ; après P21aA/enable/RO=0/prio=3 ; P21aB/enable/RO=1/prio=1 ; P21aC/enable/RO=0/prio=2 ; doublons priorité / organisme - / -] ✓ P21-b attendu : un complémentaire ajouté avec une priorité déjà occupée prend la priorité libre suivante [réponse {"data":{"strLASTNAME":"ZZAUDIT P21B","lgTIERSPAYANTID":"ZZAUDIT-TP-P21bA","full ; liens avant P21bA/enable/RO=1/prio=1 ; P21bC/enable/RO=0/prio=2 ; après P21bA/enable/RO=1/prio=1 ; P21bD/enable/RO=0/prio=3 ; P21bC/enable/RO=0/prio=2 ; doublons priorité / organisme - / -] ✓ P21-c attendu : RO changé vers un organisme déjà rattaché : son lien est repris (pas de second lien), RO en priorité 1 ; A reste actif en priorité libre [réponse {"data":{"strLASTNAME":"ZZAUDIT P21C","lgTIERSPAYANTID":"ZZAUDIT-TP-P21cC","full ; liens avant P21cA/enable/RO=1/prio=1 ; P21cC/enable/RO=0/prio=2 ; après P21cA/enable/RO=0/prio=3 ; P21cC/enable/RO=1/prio=1 ; doublons priorité / organisme - / -] ✓ P21-d attendu (non-régression) : enregistrer la fiche sans changement garde A RO en priorité 1 et C en priorité 2 [réponse {"data":{"strLASTNAME":"ZZAUDIT P21D","lgTIERSPAYANTID":"ZZAUDIT-TP-P21dA","full ; liens avant P21dA/enable/RO=1/prio=1 ; P21dC/enable/RO=0/prio=2 ; après P21dA/enable/RO=1/prio=1 ; P21dC/enable/RO=0/prio=2] ✓ P21-e attendu : le lien créé par la modification de vente ne reprend pas une priorité déjà occupée [réponse {"msg":"Opération effectuée avec succèss","success":true,"refId":"b6756a67-fcba- ; liens avant P21eA/enable/RO=1/prio=1 ; P21eC/enable/RO=0/prio=2 ; après P21eA/enable/RO=1/prio=1 ; P21eD/enable/RO=0/prio=3 ; P21eC/enable/RO=0/prio=2 ; doublons priorité / organisme - / -] ✓ Aucune erreur JavaScript [] ✓ Jeu d'essai retiré (ventes, clients, tiers payants, factures), stocks et paramètres remis [ventes restantes 0] | E5: OK | L5: =IF(I5="","",IF(I5=E5,"Oui","Non"))
A6: 11 | B6: audits/repro-carnet.js | C6: REPRODUCTION — MODULE CARNET DEPOT ET RETOURS CARNET (constats CA-06, CA-07, CA-08/CA-15, CA-12). Carnet depot d'essai (copie d'un carnet existant, solde 5 000 F), retours par les routes de l'ecran « Retour carnet ». FAIL = defaut reproduit (mesure entre crochets). Lancement seul : node src/test/e2e/audits/repro-carnet.js | D6: 10 / 10 conformes ✓ CA-06 précondition : solde du carnet dépôt d'essai = 5 000 [5000] ✓ CA-06 attendu : un règlement de carnet dépôt de −1 000 F est refusé, solde inchangé [réponse {"msg":"Le montant du règlement doit être supérieur à zéro (montant négatif ou nul refusé).","success":false,"http":200} ; solde 5000 → 5000] ✓ CA-07 précondition : retour carnet de 2 boîtes créé (stock 100) [{"data":{"id":7526},"success":true,"http":200}] ✓ CA-12 attendu : le détail du retour (une entrée en stock) note stock final = stock initial + 2 [stock initial 100 ; stock final noté 102 ; quantité 2] ✓ CA-07 attendu : clôturer deux fois le même retour ne recompte ni le stock ni le solde [clôtures true/true ; stock 100 → 102 → 102 ; solde 5000 → 3290 → 3290] ✓ CA-12 attendu : l'historique de stock du retour enchaîne (début + quantité = fin) et n'est écrit qu'une fois [mouvements : 100+2=102] ✓ CA-08 attendu : un retour de −3 boîtes est refusé [réponse {"msg":"La quantité retournée doit être supérieure à zéro.","success":false,"http":200} ; stock 102 → 102] ✓ CA-15 attendu : un retour sans motif est refusé avec un message (pas une erreur 500) [HTTP 200 ; {"msg":"Choisissez le motif du retour.","success":false,"http":200}] ✓ Aucune erreur JavaScript [] ✓ Jeu d'essai retiré (ventes, clients, tiers payants, factures), stocks et paramètres remis [ventes restantes 0] | E6: OK | L6: =IF(I6="","",IF(I6=E6,"Oui","Non"))
A7: 12 | B7: audits/repro-differes.js | C7: REPRODUCTION — MODULE DIFFERES (constats DIF-01, DIF-02, DIF-03, D2/DIF-05, D3/DIF-06, D4/DIF-04, D5, DIF-07, DIF-08, DIF-09). Ventes comptant reglees en differe (mode 4) pour des clients d'essai, reglements par la route de l'ecran « Faire un reglement ». Invariant de reference : caisse nette de la vente + dette restante = prix de la vente. FAIL = defaut reproduit (mesure entre crochets). Lancement seul : node src/test/e2e/audits/repro-differes.js | D7: 13 / 13 conformes ✓ DIF-01 attendu : un règlement fait pendant la modification est refusé, ou déduit de la dette de la copie (caisse + dette = prix) [règlement pendant modification {"s":false,"m":"Une des ventes choisies a été annulée ou modifiée : rechargez la liste."} ; clôture copie false ; dette restante 5510 + réglé 0 = 5510 (prix 5510)] ✓ DIF-02 précondition : vente différée de 5510 avec 2755 d'acompte ; caisse + dette = prix [caisse 2755 ; dette 2755] ✓ DIF-02 attendu : après modification sans changement (copie en différé, 0 reçu), caisse + dette = prix [clôture copie true ; caisse nette 0 + dette 5510 = 5510 (prix 5510)] ✓ DIF-03 attendu : vente déjà réglée de 2755 puis passée à un autre client : refus, ou règlement reporté (dettes + réglé = prix) [clôture copie false ; dette client 1 2755 ; dette client 2 0 ; réglé par le client 1 2755 ; total 5510 (prix 5510)] ✓ D2 attendu : annuler une vente différée déjà réglée en partie est refusé (ou un avoir est créé) [annulation {"s":false,"m":"Ce différé a déjà reçu un règlement (partiel ou total) : il ne peut plus être annulé ; dette 2755 ; réglé resté en caisse 2755] ✓ D3 attendu : la liste des règlements de différés du jour montre les règlements de tous les clients (dont celui dont la vente a été annulée) [lignes renvoyées 3 (règlements du jour faits par le test : 2 clients)] ✓ D4 attendu : le solde du relevé = reste dû (prix 5510 − acompte 2755 = 2755) [solde du relevé 2755 ; reste dû 2755] ✓ D5 attendu : une vente portant deux lignes de dette (doublon, données réelles) est annulée sans laisser de dette [annulation true ; lignes de dette encore actives 0 ; dette du client 0] ✓ DIF-07 attendu : un règlement partiel qui déclare 1 F reçu pour 2755 F payés est refusé [règlement {"s":false,"m":"Le montant reçu (1 F) est inférieur au montant réglé (2755 F)."} ; dette 5510] ✓ DIF-08 attendu : la date de la ligne de dette reste celle de la vente (il y a 30 jours) après un règlement [date de la vente | date de la ligne de dette après règlement : 2026-09-30 | 2026-09-30 (la liste « Différés » affiche, trie et filtre sur cette date : ReglementServiceImpl.java:213-215, :242)] ✓ DIF-09 attendu : un règlement partiel solde d'abord la vente la plus ancienne [reste de l'ancienne 0 ; reste de la récente 2755] ✓ Aucune erreur JavaScript [] ✓ Jeu d'essai retiré (ventes, clients, tiers payants, factures), stocks et paramètres remis [ventes restantes 0] | E7: OK | L7: =IF(I7="","",IF(I7=E7,"Oui","Non"))
A8: 13 | B8: audits/repro-facturation.js | C8: REPRODUCTION — MODULE FACTURATION DES TIERS PAYANTS (constats F1, F2, F3, F4, F5, F6). Factures definitives par le chemin des ecrans (« Edition des factures » : groupe-tierspayant/facturation-bons et facturation-groupe, ancien controleur GroupeTierspayantController), provisoires par facturation/summary/generer, reglement par reglement-facture/do-reglement. Tiers payants, clients, groupe et factures d'essai retires a la fin ; compteur des numeros de facture remis a sa valeur. FAIL = defaut reproduit (mesure entre crochets). Lancement seul : node src/test/e2e/audits/repro-facturation.js | D8: 10 / 10 conformes ✓ F2 précondition : facture définitive générée, bon marqué « charged » [{"status":1,"http":200} ; statut charged ; factures 6221] ✓ F2 attendu (définitive, écran resté ouvert) : un bon déjà facturé n'est pas facturé une seconde fois [seconde génération {"status":0,"http":200} ; factures définitives portant le bon : 6221] ✓ F2 attendu (provisoire) : un bon déjà facturé n'entre pas dans une facture provisoire [génération provisoire {"success":true,"http":200} ; provisoires portant le bon : ] ✓ F1 attendu : supprimer une facture définitive par DELETE facturation/{id} est refusé (ou ses bons redeviennent facturables) [HTTP 200 ; facture encore en base ? 1 ; statut du bon charged ; factures définitives restantes portant le bon : 6221] ✓ F3 attendu : 5 paires de générations simultanées produisent toujours deux numéros différents [0 paire(s) sur 5 avec le même numéro : 6222,6223 ; 6224,6225 ; 6226,6227 ; 6228,6229 ; 6230,6231] ✓ F4 (chemin de l'écran) attendu : montants du groupe = somme des factures membres (4584), brut des membres = net (sans remise) [rattachement 2 ; génération {"status":1,"http":200} ; membres code/brut/net/père : 6233/2292.000/2292.000/16103010341224623616,6234/2292.000/2292.000/16103010341234472478 ; t_groupe_factures code/montant : 6232/2292,6232/2292 ; facture de groupe agrégée dans t_facture : 6233/2292.000/2292.000,6234/2292.000/2292.000] ✓ F5 attendu : facturer un seul des deux bons laisse l'encours de l'autre (2292) [encours organisme 4584 → 2292 ; encours client 4584 → 2292] ✓ F6 attendu : un règlement de facture de −5 000 F est refusé, facture inchangée [réponse {"success":"Echec de reglement ","str_ref":"16103010342919634968","lg_DOSSIER_REGLEMENT_ID":"","errors":"0","http":200} ; facture payé|restant|statut 0.000|2292.000|enable → 0.000|2292.000|enable] ✓ Aucune erreur JavaScript [] ✓ Jeu d'essai retiré (ventes, clients, tiers payants, factures), stocks et paramètres remis [ventes restantes 0] | E8: OK | L8: =IF(I8="","",IF(I8=E8,"Oui","Non"))
A9: 14 | B9: audits/repro-remise-caisse.js | C9: REPRODUCTION — REMISES DE LA VENTE COMPTANT ET MOUVEMENTS DE CAISSE (constats VC-05, VC-06, VC-07, VC-16). Remise d'essai de 10 % (t_remise, t_grille_remise, t_workflow_remise_article marques ZZAUDIT) appliquee a un produit TVA 18 % compte dans le chiffre d'affaires ; code remise du produit remis a la fin. FAIL = defaut reproduit (mesure entre crochets). Lancement seul : node src/test/e2e/audits/repro-remise-caisse.js | D9: 8 / 8 conformes ✓ VC-05/07 précondition : remise de 10 % posée et appliquée (prix 3270 F, TVA 18 %) [pose {"msg":"Opération effectuée avec success","success":true,"http":200} ; net {"montantAccount":0,"margeUg":0,"montant":3270,"remise":325,"restructuring":false,"cmuAmount":0,"montantTva":499,"montantNet":2945,"marge":198,"montantTtcUg":0,"montantTp":0,"montantTvaUg":0,"tiersPay] ✓ VC-05 attendu : TVA de la vente = somme des TVA des lignes [clôture true ; TVA en-tête 499 ; somme des lignes 499 ; TVA du mouvement de caisse 499] ✓ VC-07 attendu : la remise enregistrée est celle affichée et encaissée (prix − remise = net payé) [remise affichée 325 ; net affiché 2945 ; remise enregistrée (vente) 325 ; prix − remise enregistrée 2945 ; transaction remise|net|payé 325|2945|2945] ✓ VC-06 attendu : une vente encaissée au net sans remise n'enregistre pas de remise (remise de la vente = 0) [net demandé sans remiseId 3270 (plein tarif 3270) ; clôture true ; remise enregistrée sur la vente 0 ; transaction montant|remise|payé 3270|0|3270] ✓ VC-16 attendu : un mouvement de caisse saisi à la date d'hier porte la même date dans le mouvement, le règlement et la transaction [{"msg":"Opération effectuée .","mvtId":"782d5c43-677f-4c31-afd4-3a45e7f995cc","success":true,"http": ; mouvement 2026-10-29 | règlement 2026-10-29 | transaction 2026-10-29] ✓ VC-16 attendu : un mouvement de caisse daté de demain est refusé [{"msg":"La date du mouvement ne peut pas être dans le futur.","success":false,"http":200}] ✓ Aucune erreur JavaScript [] ✓ Jeu d'essai retiré (ventes, clients, tiers payants, factures), stocks et paramètres remis [ventes restantes 0] | E9: OK | L9: =IF(I9="","",IF(I9=E9,"Oui","Non"))
A10: 15 | B10: audits/repro-vente-assurance.js | C10: REPRODUCTION — MODULE VENTE ASSURANCE (constats CR-01, CR-02, CR-03, CR-04, CR-05/N3, CR-06, CR-07, CR-09, CR-10, CA-03, CA-09/N5). Tiers payants d'essai (copies d'un organisme existant, compteurs a zero) et clients d'essai crees par l'ecran client ; chaque cas a ses propres tiers payants, pour que les compteurs ne se melangent pas. FAIL = defaut reproduit (mesure entre crochets). Lancement seul : node src/test/e2e/audits/repro-vente-assurance.js | D10: 17 / 17 conformes ✓ CR-01 précondition : vente assurance encaissée, encours organisme et client = part tiers payant (564) [encours organisme|client 564|564 ; net 140] ✓ CR-01 attendu : après annulation, l'encours revient à 0 [annulation true ; encours organisme 564 → 0 ; encours client 564 → 0] ✓ CR-02 précondition : modification ouverte [0e2bd896-7a29-4c28-8f1f-ffd4a3b4f314] ✓ CR-02 attendu : modification sans changement → encours = une seule part (564) [clôture copie {"s":true,"m":"Opération effectuée avec success"} ; encours organisme 564 ; encours client 564] ✓ CR-03 attendu : clôture refusée (bon déjà utilisé) → aucun encours modifié, aucune ligne tiers payant close [clôture {"s":false,"m":"Le numéro de ZZAUDIT-DOUBLON est déjà utilisé par l'assureur :: ZZAUDIT-TP-CR03B"} ; encours A 353 → 353 ; encours B 212 → 212 ; vente is_Process ; lignes ZZAUDIT-TP-CR03A/50/353/is_Process/unpaid ; ZZAUDIT-TP-CR03B/30/212/is_Process/unpaid] ✓ CR-03 attendu : un second essai identique ne recompte rien [second essai false ; encours A 353 → 353] ✓ CR-04 attendu : 3 paires de clôtures simultanées sur le même organisme → encours = somme des parts [clôtures réussies 6/6 ; somme des parts 3384 ; encours organisme 3384 ; encours client 3384] ✓ CR-07 attendu : une part de 1 F et un taux de 1 % renvoyés par le poste (calcul serveur : 80 %) sont refusés, ou ignorés au profit du calcul serveur [clôture true ; part calculée [] ; ligne enregistrée ZZAUDIT-TP-CR07/80/564/is_Closed/unpaid ; encours organisme 564] ✓ CR-09 attendu : ajouter un tiers payant à 250 % est refusé [réponse {"msg":"Le taux du tiers payant doit être compris entre 0 et 100 %.","success":false,"http":200} ; lignes ZZAUDIT-TP-CR09A/70/0/is_Process/unpaid] ✓ CR-10 attendu : retirer le tiers payant d'une vente assurance encaissée est refusé, la ligne reste facturable [réponse {"msg":"Cette vente (N° 261030_00169) a été clôturée le 30/10/2026 10:04 : elle ne peut plus être mo ; lignes avant ZZAUDIT-TP-CR10/80/564/is_Closed/unpaid ; après ZZAUDIT-TP-CR10/80/564/is_Closed/unpaid] ✓ CA-03 précondition : la vente du tiers payant exclu a sa ligne vente_exclu ✓ CA-03 attendu : aucune des 8 ventes ordinaires suivantes n'a de ligne « vente exclue » [0 vente(s) ordinaire(s) enregistrée(s) comme exclues, au nom de -] ✓ CA-03 remise en état : une vente ordinaire après une vente « dépôt » n'est plus enregistrée comme exclue ✓ CA-09 attendu : la part passe de l'organisme A à l'organisme B (encours A 564 → 0, B 0 → 564) [réponse {"msg":"Opération effectuée avec succèss","success":true,"refId":"b41274a0-a8c2-4303-8bfa-52303a5984 ; encours A 0 ; encours B 564 ; lignes ZZAUDIT-TP-CA09B/80/564/is_Closed/unpaid] ✓ N5 attendu : changer le tiers payant d'une vente déjà facturée (ligne « charged ») est refusé, la ligne facturée reste [réponse {"msg":"Cette vente a déjà été facturée à l'organisme : son client ou ses tiers payants ne se modifi ; ligne facturée encore présente ? 1 ; lignes de la vente ZZAUDIT-TP-CA09A/80/564/is_Closed/charged] ✓ Aucune erreur JavaScript [] ✓ Jeu d'essai retiré (ventes, clients, tiers payants, factures), stocks et paramètres remis [ventes restantes 0] | E10: OK | L10: =IF(I10="","",IF(I10=E10,"Oui","Non"))
A11: 16 | B11: audits/repro-vente-comptant.js | C11: REPRODUCTION — MODULE VENTE COMPTANT (constats VC-01, VC-02, VC-04, VC-08, VC-09, VC-11, VC-12, VC-14, N1, N2). Chaque cas joue le parcours de l'ecran de vente par son API (session du compte de test) et affirme le comportement ATTENDU : FAIL = defaut reproduit, avec la mesure entre crochets. Jeu d'essai retire a la fin. | D11: 17 / 17 conformes ✓ VC-01 précondition : vente comptant de 2 boîtes encaissée [8d09a52f-8793-423d-8a3a-776661739806] ✓ VC-01 attendu : modifier la quantité d'une ligne d'une vente encaissée est refusé, ligne inchangée (2 boîtes) [réponse {"msg":"Cette vente (N° 261030_00185) a été clôturée le 30/10/2026 10:05 : elle ne peut plus être modifiée ici. Pour retirer un produit, passez par « Ventes ter ; ligne après = qté|montant 2|6950 ; vente {"statut":"is_Closed","annulee":false,"prix":6950,"remise":0,"partClient":0,"tva":0,"client":"NULL"} ; stock 98] ✓ VC-02 attendu : « Terminer la prévente » sur une vente encaissée est refusé, statut is_Closed conservé [réponse {"msg":"Cette vente (N° 261030_00186) a été clôturée le 30/10/2026 10:05 : elle ne peut plus être modifiée ici. Pour ret ; statut après is_Closed ; transactions de caisse 1] ✓ VC-04 précondition : modification ouverte (copie en cours) [{"msg":"Opération effectuée avec success","data":{"lgPREENREGISTREMENTID":"bd0c40ad-22a6-4fb3-a526-ae8c8f93d17a","intPRICE":3475,"intPRICEREMISE":0,"strREF":"26] ✓ VC-04 attendu : annuler la vente pendant sa modification est refusé, ou la clôture de la copie ne la réannule pas (une seule annulation ; stock = stock de départ − 1 car la copie est vendue) [annulation {"msg":"Cette vente est en cours de modification : terminez ou abandonnez la mod ; clôture copie {"s":true,"m":"Opération effectuée avec success"} ; annulations de l'origine 1 ; stock départ 97 → fin 96 ; somme caisse origine+copie+annulations 3475 (attendu 3475)] ✓ VC-08 précondition : vente encaissée rattachée au client d'essai [{"statut":"is_Closed","annulee":false,"prix":3475,"remise":0,"partClient":0,"tva":0,"client":"ZZAUDIT-CL-VC08"}] ✓ VC-08 attendu : changer le client d'une vente encaissée (identifiant inconnu) est refusé, client conservé [réponse {"msg":"Cette vente (N° 261030_00189) a été clôturée le 30/10/2026 10:05 : elle ne peut plus être modifiée ici. Pour ret ; client après ZZAUDIT-CL-VC08] ✓ VC-09 précondition : deux ventes en cours de 1 boîte chacune, stock 1, FORCER_STOCK_VENTE = 0 [128320bc-eb22-4d99-93aa-ef7bc838cdc5 / fb72b796-9118-4a70-bf0c-ce8f5b7e357e] ✓ VC-09 attendu : la seconde validation est refusée, le stock ne passe pas sous zéro [clôture 1 true ; clôture 2 {"s":false,"m":"Impossible de valider la vente : stock insuffisant pour A CIN 500MG CPR PELL B/3 (une autre vente l'a peut-être pris entre-temps). Veuillez modifier la vente."} ; stock final 0] ✓ VC-11 précondition : lot A (péremption proche) épuisé, lot B à 5 ; la vente de 2 boîtes sort du lot B [ZZAUDIT-LOT-A=0,ZZAUDIT-LOT-B=3] ✓ VC-11 attendu : l'annulation rend les 2 boîtes au lot B d'où elles sont sorties (A=0, B=5) [annulation true ; lots après annulation ZZAUDIT-LOT-A=0,ZZAUDIT-LOT-B=5] ✓ VC-12 attendu : toutes les écritures de la modification d'une vente d'hier portent la même date [clôture copie true ; transaction de la copie 2026-10-29 ; contre-passation 2026-10-29,2026-10-29 ; recette de la copie 2026-10-29 ; mouvement de stock de la copie 2026-10-29 ; mouvement de stock de l'annulation 2026-10-29,2026-10-29 ; aujourd'hui 2026-10-30] ✓ VC-14 attendu : une clôture qui déclare 1 F payé pour une vente de 6950 F est refusée [clôture {"s":false,"m":"Le montant réglé (1 F) est inférieur au net de la vente (6950 F) : vérifiez les montants saisis, ou choisissez le règlement en différé."} ; transaction montant|net|payé|réglé ; recette aucune] ✓ N1 attendu : une annulation qui échoue (produit sans ligne de stock dans l'emplacement) ne laisse aucune écriture [réponse {"msg":"Annulation impossible : le produit A CIN 500MG CPR PELL B/3 n'a pas de ligne de stock dans l'emplacement de la v ; vente annulée ? false ; copies d'annulation 0 ; contre-passations 0] ✓ N2 attendu : ouvrir la modification d'une vente annulée est refusé [réponse {"msg":"Seule une vente terminée et non annulée peut être modifiée : actualisez la liste des ventes.","success":false,"http":200} ; vente renvoyée comme « copie » : statut|copy|prix|annule -] ✓ Aucune erreur JavaScript [] ✓ Jeu d'essai retiré (ventes, clients, tiers payants, factures), stocks et paramètres remis [ventes restantes 0] | E11: OK | L11: =IF(I11="","",IF(I11=E11,"Oui","Non"))
A12: 17 | B12: audits/repro-vo-remise.js | C12: REPRODUCTION — REMISE SUR LA VENTE ASSURANCE (constats CR-05, N3, CR-06). Remise d'essai de 10 % (grille VO), tiers payant d'essai a 80 % puis a 95 %, client pose en base. FAIL = defaut reproduit (mesure entre crochets). Lancement seul : node src/test/e2e/audits/repro-vo-remise.js | D12: 9 / 9 conformes ✓ CR-05 précondition : remise appliquée sur la vente assurance [{"statut":"is_Closed","annulee":false,"prix":2010,"remise":40,"partClient":362,"tva":0,"client":"ZZAUDIT-CL-VR80"} ; net affiché 360] ✓ CR-05 attendu : en espèces, le montant réglé de la transaction = montant payé par le client (net arrondi de la part client 362) [prix 2010 ; remise 40 ; parts TP 1608 ; part client 362 ; transaction payé|réglé|remise 360|360|40] ✓ N3 attendu : en différé sans acompte, la dette du client = part client (362) [part client 362 ; remise 40 ; dette prix|reste 362|362] ✓ CR-06 attendu : avec une remise (10 %) supérieure à la part client (5 %), parts TP + part client = prix − remise [prix 2010 ; remise 10 ; parts TP 1909 ; part client 91 ; total 2000 (attendu 2000)] ✓ Règle 1 attendu : produit remisable seul à 80 % : remise = part client (402) × 10 % = 40, part client = 362 [prix 2010 ; parts TP 1608 ; remise 40 (ligne 40) ; part client 362] ✓ Règle 2 attendu : remisable + non remisable : remise sur la seule part client du remisable (402 → 40), 0 sur l'autre, part client = total des parts client − remise [clôture true ; prix 2010 + 2755 ; parts TP 3812 ; remises lignes 40 / 0 ; remise vente 40 ; part client 913 (attendu 913)] ✓ Règle 3 attendu : plafond par vente de 1 000 : part de l'organisme = 1 000, répartie au prorata ; remise sur la part client augmentée du remisable (1588 → 158) [clôture true ; prix 2010 + 2755 ; parts TP 1000 ; remises lignes 158 / 0 ; remise vente 158 ; part client 3607 (attendu 3607)] ✓ Aucune erreur JavaScript [] ✓ Jeu d'essai retiré (ventes, clients, tiers payants, factures), stocks et paramètres remis [ventes restantes 0] | E12: OK | L12: =IF(I12="","",IF(I12=E12,"Oui","Non"))
A13: 18 | B13: audits/test-ecran-assurances-client-depot.js | C13: VENTE EN DEPOT > FICHE DU CLIENT ASSURE : grille des complementaires modifiable, avec les memes controles que celle de l'ecran de vente de l'officine (decision du 29/10 au cahier de recette). La fiche du depot est une copie de celle de l'officine : la grille y etait restee en lecture seule, et « Associer une assurance » acceptait 0 % et une priorite deja prise. Preparation (hors parcours teste) : client d'essai, assurance principale A (80 %, priorite 1) et complementaires C (10 %, priorite 2) et F (10 %, priorite 3). Parcours de l'utilisateur, a la souris et au clavier : - GESTION DES TIERS-PAYANTS > « Gestion depots extensions », onglet « Saisir vente dépôt », type « Assurance », client cherche au clavier ; bouton de modification du client ; - grille : taux et matricule de C modifies d'un clic dans la cellule, « Enregistrer » : enregistres ; - grille : priorite de l'autre assurance et taux de 150 refuses, avec un message ; - « Associer une assurance » : taux 0 puis priorite prise refuses, la fenetre reste ouverte. Jeu d'essai retire a la fin. Lancement seul : node src/test/e2e/audits/test-ecran-assurances-client-depot.js | D13: 8 / 8 conformes ✓ Grille du dépôt : taux et matricule de C modifiés à l'écran puis enregistrés [15/ZZAUDIT-MATD {"data":{"strLASTNAME":"ZZAUDIT DEPOTG","lgTIERSPAYANTID":"ZZAUDIT-TP-GA","fullName":"ESSAI ZZAUDIT DEPOTG","preenregistrementstp":[],"lgCLIENTID":"ZZ] ✓ Grille du dépôt : priorité déjà portée refusée, avec un message [saisi 3, C garde 2, message « Priorité 3 déjà portée par ZZAUDIT-TP-GF »] ✓ Grille du dépôt : taux de 150 % refusé, avec un message [C garde 15 %, message « Taux de 1 à 100 % seulement »] ✓ « Associer une assurance » du dépôt : taux de 0 % refusé, la fenêtre reste ouverte, le champ marqué [fenêtre ouverte] ✓ « Associer une assurance » du dépôt : priorité déjà prise refusée, la fenêtre reste ouverte [] ✓ Après « Enregistrer » : aucune priorité en double, E non rattachée [ZZAUDIT-TP-GA/1/1 ; ZZAUDIT-TP-GC/2/0 ; ZZAUDIT-TP-GF/3/0] ✓ Aucune erreur JavaScript, aucun message d'erreur [] ✓ Jeu d'essai retiré (ventes, clients, tiers payants, factures), stocks et paramètres remis [ventes restantes 0] | E13: OK | L13: =IF(I13="","",IF(I13=E13,"Oui","Non"))
