Workbook

Sheet Mode d'emploi
A1: CAHIER DE RECETTE PRESTIGE
A2: Version testée : branche integration/recette-2026-10-29 (21ddcd3d), déployée sur le poste local (port 8080), copie de l'officine restaurée le 30/10
A4: À quoi sert ce cahier
A5: Chaque ligne est un cas de test. Sa description (existant, étapes, résultats attendus) est tirée uniquement du test automatique correspondant : rien n'y est ajouté. Le nom du fichier du test est rappelé en colonne « Test automatique ».
A7: Comment le remplir
A8: 1. Ouvrir la feuille du module (onglets en bas). La feuille « Synthèse » donne l'avancement par module.
A9: 2. Pour chaque ligne : vérifier l'« Existant » (données et profil nécessaires), suivre les « Étapes » dans l'ordre, comparer avec les « Résultats attendus ».
A10: 3. Les étapes et résultats marqués « (Contrôle technique) » ou « (technique) » sont vérifiés par le test automatique dans la base ou par un appel au serveur : ils ne se voient pas à l'écran. Le testeur peut les laisser à Claude.
A11: 4. Remplir les colonnes jaunes : « Résultat testeur » (OK, KO, Bloqué, Non testé), « Commentaire », « Testeur », « Date ».
A12: 5. Colonne « Résultat Claude » : résultat du test automatique lors de sa dernière exécution par Claude (date et détail à côté). Indiquer dans « Résultat Claude confirmé ? » Oui ou Non après votre propre essai.
A14: Précautions
A15: Toujours tester sur une copie de travail, jamais sur la base de production de l'officine.
... A17: Ne recopier aucune donnée de patient dans les commentaires.

Sheet Synthèse
A1: SYNTHÈSE DE LA RECETTE
A2: Version testée : branche integration/recette-2026-10-29 (21ddcd3d), déployée sur le poste local (port 8080), copie de l'officine restaurée le 30/10
A4: Module | B4: Cas | C4: Claude OK | D4: Claude échec | E4: Claude non joué | F4: Testeur : joués | G4: Testeur OK | H4: Testeur KO | I4: Testeur bloqués | J4: Résultat Claude confirmé | K4: Résultat Claude contesté | L4: % OK testeur
A5: Connexion et sécurité | B5: 16 | C5: 16 | D5: 0 | E5: 0 | F5: =COUNTIF('Connexion et sécurité'!L5:L20,"OK")+COUNTIF('Connexion et sécurité'!L5:L20,"KO")+COUNTIF('Connexion et sécurité'!L5:L20,"Bloqué") | G5: =COUNTIF('Connexion et sécurité'!L5:L20,"OK") | H5: =COUNTIF('Connexion et sécurité'!L5:L20,"KO") | I5: =COUNTIF('Connexion et sécurité'!L5:L20,"Bloqué") | J5: =COUNTIF('Connexion et sécurité'!P5:P20,"Oui") | K5: =COUNTIF('Connexion et sécurité'!P5:P20,"Non") | L5: =IF(F5=0,"",G5/F5)
A6: Ventes | B6: 47 | C6: 46 | D6: 1 | E6: 0 | F6: =COUNTIF('Ventes'!L5:L51,"OK")+COUNTIF('Ventes'!L5:L51,"KO")+COUNTIF('Ventes'!L5:L51,"Bloqué") | G6: =COUNTIF('Ventes'!L5:L51,"OK") | H6: =COUNTIF('Ventes'!L5:L51,"KO") | I6: =COUNTIF('Ventes'!L5:L51,"Bloqué") | J6: =COUNTIF('Ventes'!P5:P51,"Oui") | K6: =COUNTIF('Ventes'!P5:P51,"Non") | L6: =IF(F6=0,"",G6/F6)
A7: Vente en dépôt | B7: 11 | C7: 11 | D7: 0 | E7: 0 | F7: =COUNTIF('Vente en dépôt'!L5:L15,"OK")+COUNTIF('Vente en dépôt'!L5:L15,"KO")+COUNTIF('Vente en dépôt'!L5:L15,"Bloqué") | G7: =COUNTIF('Vente en dépôt'!L5:L15,"OK") | H7: =COUNTIF('Vente en dépôt'!L5:L15,"KO") | I7: =COUNTIF('Vente en dépôt'!L5:L15,"Bloqué") | J7: =COUNTIF('Vente en dépôt'!P5:P15,"Oui") | K7: =COUNTIF('Vente en dépôt'!P5:P15,"Non") | L7: =IF(F7=0,"",G7/F7)
A8: Ordonnances | B8: 21 | C8: 18 | D8: 3 | E8: 0 | F8: =COUNTIF('Ordonnances'!L5:L25,"OK")+COUNTIF('Ordonnances'!L5:L25,"KO")+COUNTIF('Ordonnances'!L5:L25,"Bloqué") | G8: =COUNTIF('Ordonnances'!L5:L25,"OK") | H8: =COUNTIF('Ordonnances'!L5:L25,"KO") | I8: =COUNTIF('Ordonnances'!L5:L25,"Bloqué") | J8: =COUNTIF('Ordonnances'!P5:P25,"Oui") | K8: =COUNTIF('Ordonnances'!P5:P25,"Non") | L8: =IF(F8=0,"",G8/F8)
A9: Clients | B9: 12 | C9: 12 | D9: 0 | E9: 0 | F9: =COUNTIF('Clients'!L5:L16,"OK")+COUNTIF('Clients'!L5:L16,"KO")+COUNTIF('Clients'!L5:L16,"Bloqué") | G9: =COUNTIF('Clients'!L5:L16,"OK") | H9: =COUNTIF('Clients'!L5:L16,"KO") | I9: =COUNTIF('Clients'!L5:L16,"Bloqué") | J9: =COUNTIF('Clients'!P5:P16,"Oui") | K9: =COUNTIF('Clients'!P5:P16,"Non") | L9: =IF(F9=0,"",G9/F9)
A10: Caisse | B10: 14 | C10: 13 | D10: 1 | E10: 0 | F10: =COUNTIF('Caisse'!L5:L18,"OK")+COUNTIF('Caisse'!L5:L18,"KO")+COUNTIF('Caisse'!L5:L18,"Bloqué") | G10: =COUNTIF('Caisse'!L5:L18,"OK") | H10: =COUNTIF('Caisse'!L5:L18,"KO") | I10: =COUNTIF('Caisse'!L5:L18,"Bloqué") | J10: =COUNTIF('Caisse'!P5:P18,"Oui") | K10: =COUNTIF('Caisse'!P5:P18,"Non") | L10: =IF(F10=0,"",G10/F10)
A11: Tiers payants et facturation | B11: 22 | C11: 22 | D11: 0 | E11: 0 | F11: =COUNTIF('Tiers payants et facturation'!L5:L26,"OK")+COUNTIF('Tiers payants et facturation'!L5:L26,"KO")+COUNTIF('Tiers payants et facturation'!L5:L26,"Bloqué") | G11: =COUNTIF('Tiers payants et facturation'!L5:L26,"OK") | H11: =COUNTIF('Tiers payants et facturation'!L5:L26,"KO") | I11: =COUNTIF('Tiers payants et facturation'!L5:L26,"Bloqué") | J11: =COUNTIF('Tiers payants et facturation'!P5:P26,"Oui") | K11: =COUNTIF('Tiers payants et facturation'!P5:P26,"Non") | L11: =IF(F11=0,"",G11/F11)
A12: Commandes et PharmaML | B12: 37 | C12: 36 | D12: 1 | E12: 0 | F12: =COUNTIF('Commandes et PharmaML'!L5:L41,"OK")+COUNTIF('Commandes et PharmaML'!L5:L41,"KO")+COUNTIF('Commandes et PharmaML'!L5:L41,"Bloqué") | G12: =COUNTIF('Commandes et PharmaML'!L5:L41,"OK") | H12: =COUNTIF('Commandes et PharmaML'!L5:L41,"KO") | I12: =COUNTIF('Commandes et PharmaML'!L5:L41,"Bloqué") | J12: =COUNTIF('Commandes et PharmaML'!P5:P41,"Oui") | K12: =COUNTIF('Commandes et PharmaML'!P5:P41,"Non") | L12: =IF(F12=0,"",G12/F12)
A13: Réception et bons de livraison | B13: 21 | C13: 20 | D13: 1 | E13: 0 | F13: =COUNTIF('Réception et bons de livraison'!L5:L25,"OK")+COUNTIF('Réception et bons de livraison'!L5:L25,"KO")+COUNTIF('Réception et bons de livraison'!L5:L25,"Bloqué") | G13: =COUNTIF('Réception et bons de livraison'!L5:L25,"OK") | H13: =COUNTIF('Réception et bons de livraison'!L5:L25,"KO") | I13: =COUNTIF('Réception et bons de livraison'!L5:L25,"Bloqué") | J13: =COUNTIF('Réception et bons de livraison'!P5:P25,"Oui") | K13: =COUNTIF('Réception et bons de livraison'!P5:P25,"Non") | L13: =IF(F13=0,"",G13/F13)
A14: Stock et inventaire | B14: 25 | C14: 23 | D14: 2 | E14: 0 | F14: =COUNTIF('Stock et inventaire'!L5:L29,"OK")+COUNTIF('Stock et inventaire'!L5:L29,"KO")+COUNTIF('Stock et inventaire'!L5:L29,"Bloqué") | G14: =COUNTIF('Stock et inventaire'!L5:L29,"OK") | H14: =COUNTIF('Stock et inventaire'!L5:L29,"KO") | I14: =COUNTIF('Stock et inventaire'!L5:L29,"Bloqué") | J14: =COUNTIF('Stock et inventaire'!P5:P29,"Oui") | K14: =COUNTIF('Stock et inventaire'!P5:P29,"Non") | L14: =IF(F14=0,"",G14/F14)
A15: Fiche article | B15: 16 | C15: 15 | D15: 1 | E15: 0 | F15: =COUNTIF('Fiche article'!L5:L20,"OK")+COUNTIF('Fiche article'!L5:L20,"KO")+COUNTIF('Fiche article'!L5:L20,"Bloqué") | G15: =COUNTIF('Fiche article'!L5:L20,"OK") | H15: =COUNTIF('Fiche article'!L5:L20,"KO") | I15: =COUNTIF('Fiche article'!L5:L20,"Bloqué") | J15: =COUNTIF('Fiche article'!P5:P20,"Oui") | K15: =COUNTIF('Fiche article'!P5:P20,"Non") | L15: =IF(F15=0,"",G15/F15)
A16: Étiquettes | B16: 11 | C16: 11 | D16: 0 | E16: 0 | F16: =COUNTIF('Étiquettes'!L5:L15,"OK")+COUNTIF('Étiquettes'!L5:L15,"KO")+COUNTIF('Étiquettes'!L5:L15,"Bloqué") | G16: =COUNTIF('Étiquettes'!L5:L15,"OK") | H16: =COUNTIF('Étiquettes'!L5:L15,"KO") | I16: =COUNTIF('Étiquettes'!L5:L15,"Bloqué") | J16: =COUNTIF('Étiquettes'!P5:P15,"Oui") | K16: =COUNTIF('Étiquettes'!P5:P15,"Non") | L16: =IF(F16=0,"",G16/F16)
A17: Analyses et statistiques | B17: 27 | C17: 26 | D17: 1 | E17: 0 | F17: =COUNTIF('Analyses et statistiques'!L5:L31,"OK")+COUNTIF('Analyses et statistiques'!L5:L31,"KO")+COUNTIF('Analyses et statistiques'!L5:L31,"Bloqué") | G17: =COUNTIF('Analyses et statistiques'!L5:L31,"OK") | H17: =COUNTIF('Analyses et statistiques'!L5:L31,"KO") | I17: =COUNTIF('Analyses et statistiques'!L5:L31,"Bloqué") | J17: =COUNTIF('Analyses et statistiques'!P5:P31,"Oui") | K17: =COUNTIF('Analyses et statistiques'!P5:P31,"Non") | L17: =IF(F17=0,"",G17/F17)
A18: Pilotage et tableau de bord | B18: 22 | C18: 22 | D18: 0 | E18: 0 | F18: =COUNTIF('Pilotage et tableau de bord'!L5:L26,"OK")+COUNTIF('Pilotage et tableau de bord'!L5:L26,"KO")+COUNTIF('Pilotage et tableau de bord'!L5:L26,"Bloqué") | G18: =COUNTIF('Pilotage et tableau de bord'!L5:L26,"OK") | H18: =COUNTIF('Pilotage et tableau de bord'!L5:L26,"KO") | I18: =COUNTIF('Pilotage et tableau de bord'!L5:L26,"Bloqué") | J18: =COUNTIF('Pilotage et tableau de bord'!P5:P26,"Oui") | K18: =COUNTIF('Pilotage et tableau de bord'!P5:P26,"Non") | L18: =IF(F18=0,"",G18/F18)
A19: Fidélité | B19: 6 | C19: 6 | D19: 0 | E19: 0 | F19: =COUNTIF('Fidélité'!L5:L10,"OK")+COUNTIF('Fidélité'!L5:L10,"KO")+COUNTIF('Fidélité'!L5:L10,"Bloqué") | G19: =COUNTIF('Fidélité'!L5:L10,"OK") | H19: =COUNTIF('Fidélité'!L5:L10,"KO") | I19: =COUNTIF('Fidélité'!L5:L10,"Bloqué") | J19: =COUNTIF('Fidélité'!P5:P10,"Oui") | K19: =COUNTIF('Fidélité'!P5:P10,"Non") | L19: =IF(F19=0,"",G19/F19)
A20: Campagnes et WhatsApp | B20: 15 | C20: 12 | D20: 3 | E20: 0 | F20: =COUNTIF('Campagnes et WhatsApp'!L5:L19,"OK")+COUNTIF('Campagnes et WhatsApp'!L5:L19,"KO")+COUNTIF('Campagnes et WhatsApp'!L5:L19,"Bloqué") | G20: =COUNTIF('Campagnes et WhatsApp'!L5:L19,"OK") | H20: =COUNTIF('Campagnes et WhatsApp'!L5:L19,"KO") | I20: =COUNTIF('Campagnes et WhatsApp'!L5:L19,"Bloqué") | J20: =COUNTIF('Campagnes et WhatsApp'!P5:P19,"Oui") | K20: =COUNTIF('Campagnes et WhatsApp'!P5:P19,"Non") | L20: =IF(F20=0,"",G20/F20)
A21: Ressources humaines et pointage | B21: 14 | C21: 14 | D21: 0 | E21: 0 | F21: =COUNTIF('Ressources humaines et pointage'!L5:L18,"OK")+COUNTIF('Ressources humaines et pointage'!L5:L18,"KO")+COUNTIF('Ressources humaines et pointage'!L5:L18,"Bloqué") | G21: =COUNTIF('Ressources humaines et pointage'!L5:L18,"OK") | H21: =COUNTIF('Ressources humaines et pointage'!L5:L18,"KO") | I21: =COUNTIF('Ressources humaines et pointage'!L5:L18,"Bloqué") | J21: =COUNTIF('Ressources humaines et pointage'!P5:P18,"Oui") | K21: =COUNTIF('Ressources humaines et pointage'!P5:P18,"Non") | L21: =IF(F21=0,"",G21/F21)
A22: Application mobile | B22: 23 | C22: 20 | D22: 3 | E22: 0 | F22: =COUNTIF('Application mobile'!L5:L27,"OK")+COUNTIF('Application mobile'!L5:L27,"KO")+COUNTIF('Application mobile'!L5:L27,"Bloqué") | G22: =COUNTIF('Application mobile'!L5:L27,"OK") | H22: =COUNTIF('Application mobile'!L5:L27,"KO") | I22: =COUNTIF('Application mobile'!L5:L27,"Bloqué") | J22: =COUNTIF('Application mobile'!P5:P27,"Oui") | K22: =COUNTIF('Application mobile'!P5:P27,"Non") | L22: =IF(F22=0,"",G22/F22)
A23: Centre de support et administration | B23: 21 | C23: 17 | D23: 2 | E23: 2 | F23: =COUNTIF('Centre de support et administra'!L5:L25,"OK")+COUNTIF('Centre de support et administra'!L5:L25,"KO")+COUNTIF('Centre de support et administra'!L5:L25,"Bloqué") | G23: =COUNTIF('Centre de support et administra'!L5:L25,"OK") | H23: =COUNTIF('Centre de support et administra'!L5:L25,"KO") | I23: =COUNTIF('Centre de support et administra'!L5:L25,"Bloqué") | J23: =COUNTIF('Centre de support et administra'!P5:P25,"Oui") | K23: =COUNTIF('Centre de support et administra'!P5:P25,"Non") | L23: =IF(F23=0,"",G23/F23)
A24: Ergonomie générale | B24: 32 | C24: 30 | D24: 2 | E24: 0 | F24: =COUNTIF('Ergonomie générale'!L5:L36,"OK")+COUNTIF('Ergonomie générale'!L5:L36,"KO")+COUNTIF('Ergonomie générale'!L5:L36,"Bloqué") | G24: =COUNTIF('Ergonomie générale'!L5:L36,"OK") | H24: =COUNTIF('Ergonomie générale'!L5:L36,"KO") | I24: =COUNTIF('Ergonomie générale'!L5:L36,"Bloqué") | J24: =COUNTIF('Ergonomie générale'!P5:P36,"Oui") | K24: =COUNTIF('Ergonomie générale'!P5:P36,"Non") | L24: =IF(F24=0,"",G24/F24)
A25: Performances | B25: 16 | C25: 14 | D25: 2 | E25: 0 | F25: =COUNTIF('Performances'!L5:L20,"OK")+COUNTIF('Performances'!L5:L20,"KO")+COUNTIF('Performances'!L5:L20,"Bloqué") | G25: =COUNTIF('Performances'!L5:L20,"OK") | H25: =COUNTIF('Performances'!L5:L20,"KO") | I25: =COUNTIF('Performances'!L5:L20,"Bloqué") | J25: =COUNTIF('Performances'!P5:P20,"Oui") | K25: =COUNTIF('Performances'!P5:P20,"Non") | L25: =IF(F25=0,"",G25/F25)
A26: TOTAL | B26: =SUM(B5:B25) | C26: =SUM(C5:C25) | D26: =SUM(D5:D25) | E26: =SUM(E5:E25) | F26: =SUM(F5:F25) | G26: =SUM(G5:G25) | H26: =SUM(H5:H25) | I26: =SUM(I5:I25) | ... K26: =SUM(K5:K25) | L26: =IF(F26=0,"",G26/F26)

Sheet Connexion et sécurité
A1: CAHIER DE RECETTE — CONNEXION ET SÉCURITÉ
A2: Version testée : branche integration/recette-2026-10-29 (21ddcd3d), déployée sur le poste local (port 8080), copie de l'officine restaurée le 30/10
A3: 16 cas — Claude : 16 OK, 0 en échec, 0 non joués
A4: N° | B4: Cas de test | C4: Écran (menu) | D4: Objectif | E4: Existant (avant de commencer) | F4: Étapes | G4: Résultats attendus | H4: Nettoyage / prudence | I4: Test automatique | J4: Résultat Claude | K4: Détail Claude | L4: Résultat testeur | M4: Commentaire testeur | N4: Testeur | O4: Date | P4: Résultat Claude confirmé ?
A5: SEC-01 | B5: Super administrateur : Centre de support réservé, invisible et protégé pour l'admin | C5: Centre de support (sous-menus lus dans l'arbre du menu) ; autres écrans (non précisé dans le test) : contrôles faits par les routes du serveur | D5: Retours du 25/10 (points 5 et 7) : l'administrateur ne voit dans le Centre de support que « Me contacter » et se voit refuser l'audit, la stabilité du serveur et la maintenance ; il ne voit pas le super administrateur (profils, utilisateurs), ne peut ni en créer un ni changer son mot de passe, ni accorder les droits du Centre de support ; le super administrateur a tout. | E5: Comptes d'essai du poste local (outils/poste-local/compte-essai.sql) : le compte de test de profil Administrateur et le compte de support de profil Super Administrateur ; un profil « Caissiere ». Aucune donnée créée (ce qui serait créé par erreur est retiré). | F5: 1. Se connecter en administrateur et ouvrir le Centre de support. 2. (Contrôle technique, fait par le test automatique) : demander l'audit, l'état du serveur et la maintenance. 3. (Contrôle technique, fait par le test automatique) : lire la liste des profils (route REST et ancien écran) et la liste des utilisateurs. 4. (Contrôle technique, fait par le test automatique) : tenter de créer un utilisateur de profil Super Administrateur. 5. (Contrôle technique, fait par le test automatique) : tenter de changer le mot de passe du super administrateur (route REST et ancienne page JSP). 6. (Contrôle technique, fait par le test automatique) : lire le catalogue des droits « CENTRE DE SUPPORT » du profil Caissiere, puis tenter d'accorder le droit des tickets. 7. Se connecter en super administrateur et ouvrir le Centre de support. 8. (Contrôle technique, fait par le test automatique) : demander l'audit, la liste des profils et le catalogue des droits du Centre de support. | G5: 1. (technique) Précondition : compte de test Administrateur et compte de support Super Administrateur présents. 2. Administrateur : Centre de support réduit à « Me contacter ». 3. (technique) Administrateur : audit refusé par le serveur. 4. (technique) Administrateur : stabilité du serveur refusée. 5. (technique) Administrateur : maintenance refusée. 6. (technique) Administrateur : profil Super Administrateur absent des listes de profils (REST et écran historique). 7. (technique) Administrateur : comptes super administrateur absents de la liste des utilisateurs. 8. (technique) Administrateur : création d'un super administrateur refusée, rien de créé. 9. (technique) Administrateur : mot de passe d'un super administrateur non modifiable. 10. (technique) Administrateur : ancienne page (JSP), mot de passe d'un super administrateur non modifiable, sans erreur. 11. (technique) Administrateur : seuls « Centre de support » et « Me contacter » au catalogue des droits du Centre de support. 12. (technique) Administrateur : attribution directe d'un droit du Centre de support refusée. 13. Super administrateur : tout le Centre de support, audit compris. 14. (technique) Super administrateur : audit accessible. 15. (technique) Super administrateur : profil Super Administrateur dans la liste des profils. 16. (technique) Super administrateur : tous les droits du Centre de support au catalogue (au moins 8). 17. (technique) Essais retirés. | H5: Le test supprime l'utilisateur d'essai s'il avait été créé par erreur, retire le droit des tickets s'il avait été accordé, et remet le mot de passe d'essai du compte de support. | I5: securite/test-droits-super-admin.js | J5: OK | K5: Joué le 30/10 15:33 — 17 / 17 conformes
A6: SEC-02 | B6: Gestion de profils : les fenêtres Créer, Modifier et Privilèges sont modales | C6: GESTION DES UTILISATEURS > Gestion de profils | D6: Retours du 25/10, point 3 : dans la gestion de profils, les fenêtres « Créer », « Modifier » et « Attribution des privilèges » voilent l'écran derrière elles (plus de clic possible dessous) et se ferment par leur bouton sans rien enregistrer. | E6: Connexion avec le compte d'essai (administrateur). Au moins un profil existant. Rien n'est créé. | F6: 1. Se connecter avec le compte d'essai. 2. Ouvrir GESTION DES UTILISATEURS > Gestion de profils. 3. Cliquer sur « Créer », regarder l'écran derrière, puis cliquer sur « Annuler ». 4. Cliquer sur l'icône « Modifier » de la première ligne, regarder l'écran derrière, puis cliquer sur « Annuler ». 5. Cliquer sur l'icône « Attribution des privilèges » de la première ligne, regarder l'écran derrière, puis cliquer sur « Fermer ». | G6: 1. « Créer » : fenêtre modale, l'écran derrière est voilé. 2. « Créer » se ferme par « Annuler ». 3. « Modifier » : fenêtre modale, l'écran derrière est voilé. 4. « Modifier » se ferme par « Annuler ». 5. « Attribution des privilèges » : fenêtre modale, l'écran derrière est voilé. 6. « Attribution des privilèges » se ferme par « Fermer ». 7. (technique) Aucun profil ni privilège modifié. 8. Aucune erreur JavaScript, aucune fenêtre du navigateur. | H6: Rien à retirer (lecture seule). | I6: retours/test-profils-fenetres-modales.js | J6: OK | K6: Joué le 30/10 15:33 — 8 / 8 conformes
A7: SEC-03 | B7: Liste des utilisateurs : l'empreinte du mot de passe n'est plus envoyée au navigateur | C7: GESTION DES UTILISATEURS > Utilisateurs | D7: Constat du 17/10 : la liste des utilisateurs renvoyait l'empreinte du mot de passe de chaque compte. Ni la route lue par l'écran, ni l'ancienne route encore lue par deux écrans, ni les trois anciennes routes de privilèges ne doivent la renvoyer ; la grille et la fenêtre « Modifier » fonctionnent toujours. | E7: Connexion avec le compte administrateur de test. Lecture seule : le test ne crée ni ne modifie rien. | F7: 1. Ouvrir GESTION DES UTILISATEURS > Utilisateurs et attendre la liste. 2. (Contrôle technique, fait par le test automatique) : lire les réponses de la liste reçues par le navigateur. 3. (Contrôle technique, fait par le test automatique) : lire l'ancienne route de la liste et les trois anciennes routes de privilèges. 4. Sur la première ligne, cliquer sur l'icône « Modifier » et lire le login ; fermer la fenêtre. | G7: 1. La grille affiche les comptes. 2. (technique) Réponse de la liste lue par l'écran : sans le champ du mot de passe. 3. (technique) Ancienne route ws_data.jsp : sans le champ du mot de passe, toujours des comptes. 4. (technique) Anciennes routes ws_privilege.jsp (3) : sans le champ du mot de passe. 5. « Modifier » : la fenêtre s'ouvre avec le login du compte. 6. (technique) Aucune erreur JavaScript. | H7: Rien à retirer (lecture seule). | I7: securite/test-liste-utilisateurs-sans-mot-de-passe.js | J7: OK | K7: Joué le 30/10 15:33 — 6 / 6 conformes
A8: SEC-04 | B8: Fichier journal : nom du poste, ventes non journalisées, colonnes, alertes, export | C8: MENU PHARMACIEN > Fichier Journal ; SERVICE CLIENT > Vente terminées (menu lu dans la configuration des menus de l'application ; écran décrit par le test : Fichier Journal (menu non précisé dans le test) ; Ventes terminées) | D8: Retours du 10/10 (Q10) : chaque poste porte un nom saisi une fois dans le journal ; les ventes ne sont pas journalisées mais gardent leur poste et leur adresse IP (filtre et détail dans « Ventes terminées ») ; ajustements et suppressions de facture sont journalisés avec poste, adresse IP et application ; alertes d'annulations en série et d'opérations hors horaires ; export Excel enrichi. | E8: Connexion avec le compte de test habituel (administrateur). Un article vendable (prix de 200 à 400) en stock. Le test automatique crée lui-même : une caisse ouverte si l'utilisateur n'en a pas, le stock de l'article porté à 100, quatre lignes de journal datées du 10/06/2025 au poste « E2E-POSTE-ALERTE » (trois annulations à 10:00, 10:05 et 10:12, un ajustement à 05:30), une vente, une prévente, un ajustement de +2 et une facture provisoire « E2E-JRN-FACT » de 12 345 qu'il supprime. Pour un test manuel, préparer ces mêmes éléments. | F8: 1. Se connecter. 2. Ouvrir le Fichier Journal et regarder la liste des types de journal. 3. Dans « Ce poste », saisir « E2E POSTE 7 » et cliquer sur le bouton d'enregistrement du nom. 4. Faire une vente au comptant d'un article et la clôturer. 5. Faire une prévente et la terminer. 6. Ouvrir Ventes terminées ; ouvrir la liste des postes ; filtrer par « E2E POSTE 7 » (Entrée), puis par « E2E-POSTE-INCONNU », puis de nouveau par « E2E POSTE 7 ». 7. Cliquer sur « Voir détail » de la vente et lire le champ « Poste ». 8. Faire un ajustement de stock de +2 sur l'article et le valider. 9. Supprimer la facture provisoire d'essai depuis la liste des factures. 10. Rouvrir le Fichier Journal, chercher sur la date du jour et regarder les colonnes de la ligne d'ajustement. 11. Choisir le poste « E2E-POSTE-ALERTE » et chercher le 10/06/2025. 12. Cliquer sur le bouton des alertes. 13. Lancer l'export Excel du 10/06/2025 pour ce poste. | G8: 1. Le journal ne propose plus de type « Vente » ni « Prévente » (les ventes ne sont pas journalisées). 2. Le nom « E2E POSTE 7 » est mémorisé sur le poste. 3. (technique) La vente clôturée garde le poste de saisie, le poste et l'adresse IP d'encaissement. 4. (technique) La vente clôturée n'ajoute aucune ligne au journal. 5. (technique) La prévente garde son poste de saisie et n'ajoute aucune ligne au journal. 6. Ventes terminées : « E2E POSTE 7 » figure dans la liste des postes. 7. Le filtre par ce poste montre la vente. 8. Le filtre par un autre poste ne la montre pas. 9. Le détail de la vente affiche « Poste » avec l'adresse IP entre parenthèses (le poste de saisie, identique, est masqué). 10. (technique) L'ajustement est journalisé avec « Stock : avant X → après X+2 » et le poste. 11. (technique) La facture est supprimée et la suppression est journalisée avec « Suppression de la facture N° E2E-JRN-FACT, montant 12345 » et le poste. 12. La liste du journal a les colonnes Poste, Adresse IP et Application, renseignées pour l'ajustement (application de type navigateur Chrome). 13. Le filtre par poste montre les 4 lignes de ce poste seulement. 14. Les alertes signalent la série « 3 annulations du 10/06/2025 10:00 au 10/06/2025 10:12 ». 15. Les alertes signalent l'ajustement de 05:30 le 10/06/2025 comme hors horaires. 16. L'export Excel a les colonnes Poste, Adresse IP, Application, Avant / après, et les 4 lignes du poste filtré. 17. Aucune erreur JavaScript. 18. (technique) Ventes et lignes de journal de l'essai retirées. | H8: Le test retire ventes, prévente, règlements, mouvements, ajustement, lignes de journal et facture d'essai, la caisse ouverte par lui, remet le stock d'origine et efface le nom du poste mémorisé. | I8: retours/test-journal-complet.js | J8: OK | K8: Joué le 30/10 15:33 — 18 / 18 conformes
A9: SEC-05 | B9: Page de connexion : informations de l'officine, message d'erreur, blocage après 10 échecs | C9: Page de connexion | D9: Page de connexion du 13/10 : l'ancienne adresse renvoie vers la nouvelle page ; nom de l'application, version et nom de la pharmacie s'affichent ; un mauvais mot de passe donne un message dans la page ; 10 échecs sur un identifiant imposent une attente (écran et téléphone) ; après l'attente, une faute de frappe ne rebloque pas ; la session change à la connexion. | E9: Le compte de test habituel (administrateur) et un identifiant d'essai inexistant (« e2e_inconnu_… »). Aucune donnée écrite : le blocage est gardé en mémoire et expire seul au bout de 30 s. | F9: 1. Ouvrir l'ancienne adresse de la page de connexion (security/index.jsp). 2. Lire le titre, le nom de l'application, la version et le nom de la pharmacie. 3. Saisir le compte de test avec un mauvais mot de passe et cliquer sur « Connexion ». 4. (Contrôle technique, fait par le test automatique) : envoyer 11 tentatives de connexion avec l'identifiant inexistant, puis une tentative par la connexion du téléphone. 5. Saisir l'identifiant inexistant dans la page et cliquer sur « Connexion ». 6. (Contrôle technique, fait par le test automatique) : envoyer 10 mauvais mots de passe pour le compte de test, attendre 31 s, puis envoyer encore un mauvais mot de passe. 7. Se connecter avec le compte de test et son bon mot de passe. 8. Dans un nouvel onglet, rouvrir la page de connexion. | G9: 1. L'ancienne adresse security/index.jsp arrive sur la nouvelle page HTML. 2. (technique) La page est servie sans code JSP. 3. Le nom de l'application, la version et le titre sont affichés. 4. Le nom de la pharmacie est affiché. 5. Mauvais mot de passe : message « incorrect » dans la page. 6. Aucune fenêtre (alerte du navigateur). 7. (technique) Les 9 premiers échecs donnent le message habituel. 8. (technique) Au 10e échec, une attente de 30 s est annoncée (« Trop d'essais »). 9. (technique) Pendant l'attente : refus immédiat avec le temps restant (« Réessayez dans … »). 10. (technique) Le téléphone subit le même blocage. 11. À l'écran, le message de blocage « Trop d'essais » s'affiche. 12. (technique) Un compte réel est bloqué au 10e échec. 13. (technique) L'attente écoulée, une faute de frappe ne rebloque pas : simple message « incorrect ». 14. (technique) Aucune session n'est créée sur la page de connexion avant la connexion. 15. La connexion se fait normalement (arrivée sur l'accueil). 16. (technique) L'identifiant de session est renouvelé à la connexion (un identifiant imposé avant n'est pas repris). 17. Déjà connecté : la page de connexion renvoie directement à l'accueil. 18. Aucune fenêtre pendant tout le parcours. | H9: PRUDENCE : Le test bloque le compte de test pendant 30 s : ne pas lancer d'autre test pendant ce temps. Rien à retirer : l'identifiant d'essai n'existe pas et le blocage expire seul. | I9: securite/test-connexion.js | J9: OK | K9: Joué le 30/10 15:33 — 18 / 18 conformes
A10: SEC-06 | B10: Sessions : pas de session pour les accès anonymes, expiration et retour à la connexion | C10: Page de connexion | D10: Sécurité (13/10) : les routes publiques et pages d'entrée ne créent plus de session ; une connexion ratée non plus ; les sessions expirent après la durée réglée sans requête (720 minutes par défaut) ; un écran dont la session a expiré revient à la connexion avec un message dans la page, sans fenêtre. | E10: Compte d'essai des tests automatiques (administrateur). Le réglage de durée de session (720 minutes par défaut) est ramené à 1 minute pendant le test puis remis à sa valeur d'origine. | F10: 1. (Contrôle technique, fait par le test automatique) : vérifier la présence du réglage de durée de session. 2. (Contrôle technique, fait par le test automatique) : appeler les routes publiques et les pages d'entrée sans être connecté, tenter une connexion ratée, puis une connexion réussie. 3. (Contrôle technique, fait par le test automatique) : ramener la durée de session à 1 minute et attendre une minute. 4. Se connecter avec le compte d'essai. 5. (Contrôle technique, fait par le test automatique) : demander des données, puis provoquer un refus (401) sur une route du téléphone. 6. Ne plus rien faire pendant un peu plus d'une minute. 7. Se reconnecter ; la session est fermée côté serveur ; faire une action à l'écran. 8. (Contrôle technique, fait par le test automatique) : se déconnecter sans session, puis remettre le réglage. | G10: 1. (technique) Le réglage de durée est présent (720 min par défaut). 2. (technique) Routes publiques et pages d'entrée : aucune session créée. 3. (technique) Connexion ratée : aucune session créée. 4. (technique) Connexion réussie : session créée. 5. (technique) Session active : les données répondent. 6. Refus (401) alors que le poste est connecté : l'écran reste ouvert. 7. (technique) Après 1 minute sans requête : la session est expirée (401). 8. Session fermée : l'écran revient à la page de connexion. 9. Le message « session expirée » est affiché dans la page. 10. Aucune fenêtre n'est affichée. 11. (technique) Déconnexion sans session : aucune session créée. 12. (technique) Le réglage est remis à sa valeur d'origine. | H10: PRUDENCE : Pendant le test, la durée de session est d'une minute pour tous les postes : ne pas le lancer pendant que d'autres utilisateurs travaillent. Le test remet le réglage de durée de session à sa valeur d'origine (et attend la minute de cache). | I10: securite/test-sessions.js | J10: OK | K10: Joué le 30/10 15:33 — 12 / 12 conformes
A11: SEC-07 | B11: Connexion par badge (QR) : connexion, refus, journal, limite d'essais | C11: Page de connexion (bouton « Se connecter avec mon badge ») | D11: Demande du 16/10 : se connecter en présentant son badge à la douchette. Le badge doit être actif, non expiré, d'un employé actif rattaché à l'utilisateur ; tout autre cas est refusé sans session ; le secret n'apparaît nulle part ; après 10 échecs le badge est bloqué un moment ; la connexion par mot de passe reste possible. | E11: Compte de test habituel (administrateur). Le test automatique crée lui-même : un employé d'essai « ESSAI Badge connexion » rattaché à cet utilisateur (en détachant le temps du test l'employé déjà rattaché) et un badge actif avec un secret aléatoire. Pour un test manuel, préparer un badge d'essai imprimé pour un employé d'essai rattaché à un utilisateur d'essai. | F11: 1. Ouvrir la page de connexion et cliquer sur « Se connecter avec mon badge ». 2. Présenter le badge à la douchette (lecture puis Entrée). 3. Sur une nouvelle page de connexion, cliquer dans le champ « Identifiant » et présenter le badge directement. 4. Présenter successivement des badges invalides : secret faux, login d'un autre utilisateur, contenu illisible, badge désactivé, badge expiré, employé inactif, connexion par badge coupée (paramètre KEY_CONNEXION_BADGE = 0). 5. Rétablir le badge et le présenter de nouveau. 6. (Contrôle technique, fait par le test automatique) : lire le journal de connexion et les traces du serveur. 7. Se connecter avec l'identifiant et le mot de passe. 8. Présenter 10 fois le badge avec un mauvais secret, puis avec le bon. | G11: 1. Le bouton affiche la zone « Présentez votre badge ». 2. La lecture à la douchette connecte et ouvre l'accueil, avec la session de l'utilisateur du badge. 3. La lecture directe dans « Identifiant » connecte aussi, et le secret lu ne reste pas affiché dans le champ. 4. Refus — secret faux : message « Badge non reconnu », aucune session. 5. Refus — login d'un autre utilisateur : message « Badge non reconnu », aucune session. 6. Refus — contenu illisible : message « Badge non reconnu », aucune session. 7. Refus — badge désactivé : message « Badge non reconnu », aucune session. 8. Refus — badge expiré : message « Badge non reconnu », aucune session. 9. Refus — employé inactif : message « Badge non reconnu », aucune session. 10. Refus — connexion par badge coupée (paramètre KEY_CONNEXION_BADGE = 0) : message « Badge non reconnu », aucune session. 11. Badge rétabli : connexion acceptée. 12. (technique) Le journal de connexion indique « par badge », sans le secret. 13. (technique) Le secret ne figure pas dans les traces du serveur. 14. La connexion par mot de passe fonctionne toujours. 15. Après 10 échecs, le badge est refusé avec un délai d'attente, même avec le bon secret. 16. (technique) Badge et employé d'essai retirés. | H11: PRUDENCE : Le test modifie temporairement le paramètre KEY_CONNEXION_BADGE (connexion par badge coupée) et lit les traces du serveur : à jouer sur un serveur d'essai. Le test retire le badge et l'employé d'essai, rattache de nouveau l'employé d'origine à l'utilisateur et remet le paramètre KEY_CONNEXION_BADGE dans son état. | I11: retours/test-connexion-badge.js | J11: OK | K11: Joué le 30/10 15:33 — 16 / 16 conformes
A12: SEC-08 | B12: Accès sans connexion : routes de gestion et anciennes pages fermées, public conservé | C12: Page de connexion ; le reste sans écran (contrôle technique) | D12: Audit du 12/10 : de faux en-têtes ne valent plus connexion ; les routes de gestion et les anciennes pages JSP ne répondent plus sans session ; ce qui doit rester public (connexion, nom de l'officine, espace produit, avis) le reste ; connecté, les écrans reçoivent toujours leurs données. | E12: Connexion avec le compte de test (administrateur), utilisée seulement pour la partie « connecté ». Le test automatique crée ou modifie lui-même le paramètre « KEY_ENTETES_X_USER_INFO » le temps d'un essai. | F12: 1. (Contrôle technique, fait par le test automatique) : appeler, sans connexion et avec de faux en-têtes d'administrateur, les routes de l'application de vente. 2. (Contrôle technique, fait par le test automatique) : appeler sans connexion, puis avec de faux en-têtes, 18 routes de gestion (CA, TVA, factures, crédits, valorisation, licence…). 3. (Contrôle technique, fait par le test automatique) : appeler sans connexion 9 anciennes pages JSP et servlets. 4. (Contrôle technique, fait par le test automatique) : appeler sans connexion le nom de l'officine, l'espace produit, ses DCI et les avis publics. 5. Ouvrir la page de connexion et regarder le nom de la pharmacie. 6. Se connecter à Prestige. 7. (Contrôle technique, fait par le test automatique) : connecté, appeler une ancienne JSP et les routes lues par les écrans. 8. (Contrôle technique, fait par le test automatique) : mettre le paramètre à 1, attendre une minute et rappeler avec de faux en-têtes ; puis remettre le paramètre et attendre une minute. | G12: 1. (technique) Faux en-têtes d'administrateur refusés. 2. (technique) Catalogue (prix d'achat) refusé avec de faux en-têtes. 3. (technique) Aucune route de gestion lisible sans connexion (18 routes). 4. (technique) Aucune route de gestion lisible avec de faux en-têtes. 5. (technique) Anciennes JSP et servlets refusées sans connexion (9). 6. (technique) Public : nom de l'officine. 7. (technique) Public : espace produit. 8. (technique) Public : DCI de l'espace produit. 9. (technique) Public : avis (jeton faux refusé par le service, pas par le filtre de connexion). 10. Page de connexion : le nom de la pharmacie est affiché. 11. (technique) Connecté : une ancienne JSP répond toujours. 12. (technique) Connecté : les routes des écrans sont toujours servies. 13. (technique) Paramètre à 1 : l'ancien comportement revient (compatibilité). 14. (technique) Paramètre remis : faux en-têtes de nouveau refusés. | H12: PRUDENCE : Pendant environ une minute, le paramètre rouvre l'accès par faux en-têtes : à jouer uniquement sur une base d'essai. Le test remet le paramètre « KEY_ENTETES_X_USER_INFO » à sa valeur d'avant (ou le supprime s'il n'existait pas) et attend une minute pour que l'ancien comportement ne reste pas actif. | I12: securite/test-acces-sans-connexion.js | J12: OK | K12: Joué le 30/10 15:33 — 14 / 14 conformes
A13: SEC-09 | B13: Connexion par badge : lecture déformée par la douchette signalée ou corrigée | C13: Page de connexion, bouton badge et champ « Identifiant » | D13: Retours des 23 et 24/10 : « Badge non reconnu » après le scan d'un badge. La douchette peut déformer la lecture (clavier AZERTY, verrouillage majuscules, douchette restée en QWERTY). L'écran doit le dire clairement sans montrer le secret, et une douchette en QWERTY (avec ou sans majuscules) doit quand même connecter. | E13: Le compte de test (administrateur). Le test automatique crée lui-même : un employé d'essai « ESSAI Badge lecture » relié au compte de test et un badge actif avec son secret (l'éventuel employé déjà relié au compte est détaché le temps du test). Pour un test manuel, préparer : un badge imprimé depuis Ressources humaines (onglet Badges) pour un compte d'essai, et une douchette réglable (AZERTY / QWERTY, majuscules). | F13: 1. Ouvrir la page de connexion. 2. Cliquer sur le bouton badge et scanner un badge dont les séparateurs « | » sont lus comme « µ ». 3. Sur une nouvelle page de connexion, scanner le badge avec le verrouillage majuscules actif (casse inversée). 4. Sur une nouvelle page, scanner un ancien exemplaire du badge (secret qui n'est plus valable). 5. (Contrôle technique, fait par le test automatique) : lire la fin du journal du serveur. 6. Sur une nouvelle page, scanner le bon badge, lu correctement. 7. Sur une nouvelle page, scanner le badge avec une douchette restée en QWERTY sur un poste AZERTY, par le bouton badge. 8. Sur une nouvelle page, faire la même lecture QWERTY dans le champ « Identifiant » puis Entrée. 9. Sur une nouvelle page, scanner avec la douchette en QWERTY et verrouillage majuscules actif, par le bouton badge. 10. Sur une nouvelle page, faire la même lecture QWERTY + majuscules dans le champ « Identifiant » puis Entrée. | G13: 1. « | » remplacé : titre « Lecture du badge déformée », consigne sur la douchette (clavier / AZERTY), aucune session ouverte. 2. Ce qui a été lu est montré (« PRESTIGE-BADGEµ1µ… »), sans le secret du badge. 3. Casse inversée : un message parle des majuscules, aucune session ouverte, le secret n'apparaît pas. 4. Ancien exemplaire lu correctement : « Badge non reconnu » avec la mention qu'il a été réimprimé, aucune session. 5. (technique) Le journal du serveur note la raison du refus (secret), sans le secret. 6. La bonne lecture connecte toujours (arrivée dans l'application). 7. Douchette QWERTY sur poste AZERTY : connexion par le bouton badge. 8. Même lecture dans « Identifiant » : connexion aussi. 9. QWERTY et verrouillage majuscules : connexion par le bouton badge. 10. Même lecture dans « Identifiant » : connexion aussi. 11. (technique) Badge et employé d'essai retirés. | H13: Le test supprime le badge et l'employé d'essai et rattache de nouveau au compte de test l'employé qui l'était avant. | I13: retours/test-connexion-badge-lecture.js | J13: OK | K13: Joué le 30/10 15:33 — 11 / 11 conformes
A14: SEC-10 | B14: Badge sans compte utilisateur ou lecture déformée : messages clairs à la connexion | C14: RESSOURCES HUMAINES > Employés, planning de la semaine, congés et absences, pointages, connexions, pointage mobile (menu lu dans la configuration des menus de l'application ; écran décrit par le test : (menu non précisé dans le test) > Ressources humaines, onglet Badges ; page de connexion) | D14: Un refus « FORMAT » apparaissait dans les traces du serveur. Il faut distinguer un badge imprimé pour un employé sans compte utilisateur (il ne peut pas connecter) d'une lecture déformée (douchette réglée sur un autre clavier), à l'écran comme dans les traces, sans jamais montrer le secret du badge. | E14: Connexion avec le compte administrateur. Le test automatique crée lui-même : un employé d'essai (matricule E2E-BSC-M1) sans compte utilisateur et son badge actif ; pour un test manuel, préparer : un employé sans compte utilisateur avec un badge actif. | F14: 1. Ouvrir l'écran « Ressources humaines » (menu : voir colonne « Écran ») puis l'onglet des badges. 2. Sélectionner la ligne du badge de l'employé d'essai et lire son texte. 3. Cliquer sur le bouton d'impression des badges (libellé non précisé dans le test) et lire le message affiché. 4. Sur une nouvelle page de connexion, scanner le QR du badge sans compte (login vide). 5. Sur une nouvelle page de connexion, scanner le même badge avec une douchette réglée en QWERTY sur un poste AZERTY. 6. (Contrôle technique, fait par le test automatique) : envoyer au serveur la lecture du badge sans login et lire les traces du serveur. | G14: 1. Onglet Badges : la ligne du badge indique « sans compte utilisateur ». 2. L'impression en QR depuis l'écran avertit que le badge est sans compte utilisateur et ne permettra pas de se connecter. 3. Badge sans login : la page de connexion affiche « Badge sans compte utilisateur » et la marche à suivre (réimprimer), sans appel au serveur et sans afficher le secret. 4. Lecture déformée : la page affiche « Lecture du badge déformée » avec ce qui a été lu (ex. « PRESTIGE)BQDGE »), sans le secret. 5. (technique) Les traces du serveur indiquent le refus FORMAT avec « login vide », sans le secret. 6. (technique) Badge et employé d'essai retirés. | H14: PRUDENCE : Le test lit le journal du serveur (traces) : à jouer sur un poste d'essai. Le test supprime le badge et l'employé d'essai. | I14: retours/test-badge-sans-compte.js | J14: OK | K14: Joué le 30/10 15:33 — 6 / 6 conformes
A15: SEC-11 | B15: Une vente ne peut pas être terminée au nom d'un profil « prévente » (deux onglets) | C15: SERVICE CLIENT > Ventes > « Nouvelle vente » | D15: Cas d'officine du 17/10 : une connexion d'un profil « prévente » dans un autre onglet remplaçait l'utilisateur de la session, et la vente commencée par la caissière était terminée au nom de ce profil. Le serveur doit refuser toute clôture (écran, application mobile, dépôt) à un profil prévente, et l'onglet de la caissière doit annoncer le changement de compte. | E15: Connexion avec le compte d'essai (administrateur), caisse ouverte (le test en ouvre une si besoin). Le rôle « Vendeur » existe sans le droit de clôture ; un article en stock (plus de 5 boîtes) avec un CIP de 7 chiffres. Le test automatique crée lui-même : un utilisateur d'essai « e2e-stagiaire » (E2E STAGIAIRE) au rôle « Vendeur », avec une caisse ouverte ; pour un test manuel, préparer : un compte d'essai au rôle « Vendeur » avec une caisse ouverte. | F15: 1. Dans le navigateur, ouvrir un second onglet sur la page de connexion, sans se connecter. 2. Dans le premier onglet, se connecter avec le compte d'essai, ouvrir SERVICE CLIENT > Ventes et cliquer sur « Nouvelle vente ». 3. Saisir le CIP de l'article puis Entrée. 4. Dans le second onglet, se connecter avec le compte « e2e-stagiaire » et regarder le menu. 5. Revenir au premier onglet, saisir le montant reçu et cliquer sur « Terminer la vente » ; lire l'annonce. 6. (Contrôle technique, fait par le test automatique) : rejouer la demande de clôture depuis la session du profil prévente. 7. (Contrôle technique, fait par le test automatique) : depuis cette session, tenter les clôtures de l'application mobile (paiement mobile money avec clôture, ventes en dépôt v1 et v2, dépôt agréé, comptant v2). 8. Dans un nouveau navigateur, se connecter avec le compte d'essai seul, ouvrir SERVICE CLIENT > Ventes, « Nouvelle vente », saisir l'article, le montant reçu et cliquer sur « Terminer la vente ». | G15: 1. (technique) Jeu d'essai : rôle « Vendeur » sans le droit de clôture, article en stock. 2. Onglet administrateur : vente commencée (un article). 3. Onglet 2 : le profil prévente est connecté, sans le menu Ventes. 4. Onglet administrateur : « Changement de compte » est annoncé dans la page (la page se recharge au nom du compte connecté). 5. (technique) La vente n'est pas terminée au nom du profil prévente. 6. (technique) Clôture rejouée depuis la session du profil prévente : refusée (403), vente non terminée. 7. (technique) Application mobile, profil prévente — paiement mobile money avec clôture : refusé (403), vente non terminée. 8. (technique) Application mobile, profil prévente — clôture de vente en dépôt (v1) : refusée (403). 9. (technique) Application mobile, profil prévente — clôture de vente en dépôt agréé (v1) : refusée (403). 10. (technique) Application mobile, profil prévente — clôture de vente en dépôt (v2) : refusée (403). 11. (technique) Application mobile, profil prévente — clôture comptant (v2) : refusée (403). 12. Non-régression : l'administrateur seul termine sa vente normalement (caissier = administrateur). 13. (technique) Données d'essai retirées, stock remis. | H15: Le test supprime les ventes d'essai (règlements, mouvements, recettes), l'utilisateur « e2e-stagiaire », son rôle, ses journaux et les caisses ouvertes pour l'essai, et remet le stock de l'article. | I15: securite/test-cloture-vente-profil-prevente.js | J15: OK | K15: Joué le 30/10 23:29 — 13/13 OK
A16: SEC-12 | B16: Saisies absurdes dans les recherches et filtres : jamais d'erreur interne du serveur | C16: Sans écran (contrôle technique) | D16: Demande du 07/10 : toutes les lectures du serveur sont appelées avec des valeurs absurdes (vide, lettres, négatif, nombre énorme, date impossible, apostrophe, balise, texte très long, caractères spéciaux). Le serveur doit refuser proprement, sans erreur interne, sans dépasser 30 s et sans rien écrire. | E16: Connexion avec le compte d'essai. Le test relève lui-même les lectures dans le code du serveur et écarte celles qui agissent (envoi, synchronisation, exports, etc.). Rien n'est écrit en base. | F16: 1. (Contrôle technique, fait par le test automatique) : relever toutes les lectures de l'API dans le code. 2. Se connecter avec le compte d'essai. 3. (Contrôle technique, fait par le test automatique) : appeler chaque lecture retenue avec chaque jeu de valeurs absurdes, deux appels à la fois. 4. (Contrôle technique, fait par le test automatique) : vérifier la session, les erreurs, les durées, les tables et le Centre de support. | G16: 1. (technique) Le relevé trouve les lectures de l'API (plus de 500). 2. (technique) La session est toujours ouverte après tous les appels. 3. (technique) Aucune erreur interne (HTTP 500), quelle que soit la saisie. 4. (technique) Aucune lecture ne dépasse 30 s. 5. (technique) Aucune table modifiée par les lectures. 6. (technique) Aucune nouvelle erreur au Centre de support. | H16: PRUDENCE : Envoie un très grand nombre d'appels au serveur pendant plusieurs minutes : à jouer sur un poste d'essai, en dehors des heures d'ouverture. Rien à retirer (lecture seule). | I16: retours/test-saisie-api.js | J16: OK | K16: Joué le 30/10 18:38 — 6/6 OK
... A20: SEC-16 | B20: Rappel « date et heure fausses » : serveur, date reculée et horloge du poste | C20: Écran d'accueil après la connexion (rappel affiché en bas de l'écran) | D20: Retours du 25/10, point 2 : quand l'heure du serveur est fausse, quand la date a reculé ou quand l'horloge du poste est fausse, un rappel discret s'affiche en bas de l'écran, avec « Mettre à jour » et « Masquer », sans fenêtre surgissante. | E20: Connexion avec le compte de test (administrateur), une caisse, l'heure d'Internet joignable depuis le serveur. Le test automatique crée lui-même : un réglage d'essai « KEY_HORLOGE_ESSAI_DECALAGE » (serveur en avance d'une heure) et une opération de caisse d'essai datée de dans 2 jours ; il avance l'horloge du navigateur de 3 h pour un second poste. La synchronisation est interceptée : Windows n'est pas touché. | F20: 1. Se connecter à Prestige avec une horloge juste et attendre la vérification. 2. (Contrôle technique, fait par le test automatique) : simuler un serveur en avance d'une heure et relancer la vérification. 3. Cliquer sur « Mettre à jour » dans le rappel, puis sur « Masquer ». 4. (Contrôle technique, fait par le test automatique) : poser une opération de caisse datée de dans 2 jours, puis ouvrir un nouvel onglet de Prestige. 5. Se connecter depuis un poste dont l'horloge est en avance de 3 h. 6. Cliquer sur « Mettre à jour » dans le rappel. 7. (Contrôle technique, fait par le test automatique) : afficher un rappel WhatsApp en bas à droite et relancer la vérification. | G20: 1. (technique) Précondition : horloge du serveur juste, fuseau attendu, heure d'Internet joignable. 2. Horloge juste : aucun rappel. 3. Serveur en avance d'une heure : rappel « la date ou l'heure n'est pas bonne… en avance de 1 h », avec « Mettre à jour » et « Masquer ». 4. « Mettre à jour » : synchronisation demandée au serveur, compte rendu « synchronisée » dans le rappel, bouton « Mis à jour ». 5. « Masquer » retire le rappel. 6. Date reculée (opération datée de dans 2 jours) : signalée (« a reculé »). 7. Horloge du poste en avance de 3 h : « l'horloge de ce poste est en avance de 3 h ». 8. Poste seul en faute : « Mettre à jour » explique comment synchroniser ce poste (« Synchroniser maintenant »), sans appel au serveur. 9. Le rappel s'affiche au-dessus du rappel WhatsApp, sans le recouvrir. 10. Aucune fenêtre surgissante. 11. (technique) Essais retirés. | H20: PRUDENCE : En test manuel, ne pas changer l'heure du serveur ni de Windows : le test automatique simule les écarts et intercepte la synchronisation. Le test supprime le réglage d'essai et l'opération de caisse « E2E-HORLOGE ». | I20: securite/test-horloge.js | J20: OK | K20: Joué le 30/10 15:33 — 11 / 11 conformes

Sheet Ventes
A1: CAHIER DE RECETTE — VENTES
A2: Version testée : branche integration/recette-2026-10-29 (21ddcd3d), déployée sur le poste local (port 8080), copie de l'officine restaurée le 30/10
A3: 47 cas — Claude : 46 OK, 1 en échec, 0 non joués
A4: N° | B4: Cas de test | C4: Écran (menu) | D4: Objectif | E4: Existant (avant de commencer) | F4: Étapes | G4: Résultats attendus | H4: Nettoyage / prudence | I4: Test automatique | J4: Résultat Claude | K4: Détail Claude | L4: Résultat testeur | M4: Commentaire testeur | N4: Testeur | O4: Date | P4: Résultat Claude confirmé ?
A5: VEN-01 | B5: Vente assurance : encours des organismes justes après annulation, modification, refus | C5: (menu non précisé dans le test) > Vente assurance | D5: Reproduire les constats d'audit sur la vente assurance (CR-01 à CR-10, CA-03, CA-09/N5) : l'encours des organismes et des clients doit rester juste après annulation, modification, clôture refusée ou simultanée ; les parts et taux falsifiés, un taux de 250 % ou le retrait d'un tiers payant encaissé doivent être refusés ; une vente ordinaire ne doit pas être enregistrée comme « exclue » ; un changement d'organisme doit déplacer la part, sauf si la vente est déjà facturée. | E5: Connexion avec le compte de test administrateur ; caisse ouverte pour ce compte (créée par le test si besoin) ; au moins un produit à TVA 0 avec du stock. Le test automatique crée lui-même des tiers payants d'essai (copies d'un organisme, compteurs à zéro, certains « exclus » ou « dépôt ») et des clients assurés « ZZAUDIT » ; pour un test manuel, préparer : des organismes d'essai et des clients assurés à 80 % (ou 50 % + 30 %, 70 % + 20 %). | F5: 1. CR-01 : encaisser une vente assurance à 80 %, noter l'encours de l'organisme et du client, puis annuler la vente. 2. CR-02 : encaisser une vente assurance, ouvrir sa modification et la valider sans rien changer. 3. CR-03 : client à deux organismes (50 % et 30 %) ; vendre avec un numéro de bon, puis faire une seconde vente réutilisant le même numéro de bon sur le second organisme et tenter de la clôturer, deux fois. 4. CR-04 : (Contrôle technique, fait par le test automatique) : préparer 6 ventes assurance du même client et les clôturer deux par deux au même instant. 5. CR-07 : (Contrôle technique, fait par le test automatique) : clôturer une vente à 80 % en envoyant une part de 1 F et un taux de 1 %. 6. CR-09 : sur une vente en cours, ajouter un second tiers payant avec un taux de 250 %. 7. CR-10 : sur une vente assurance encaissée, retirer le tiers payant. 8. CA-03 : encaisser une vente sur un organisme « exclu », puis 8 ventes ordinaires ; ensuite 3 ventes sur un carnet dépôt, puis une vente ordinaire. 9. CA-09 : sur une vente encaissée sur l'organisme A, remplacer l'organisme par B. 10. N5 : sur une vente déjà facturée, remplacer l'organisme par un autre. | G5: 1. CR-01 (précondition) : après la vente, l'encours de l'organisme et du client = part du tiers payant. 2. CR-01 : après annulation, l'encours de l'organisme et du client revient à 0. 3. CR-02 (précondition) : la modification s'ouvre. 4. CR-02 : après une modification sans changement, l'encours = une seule part. 5. CR-03 : la clôture est refusée (bon déjà utilisé), aucun encours n'est modifié et aucune ligne tiers payant n'est close. 6. CR-03 : un second essai identique ne recompte rien. 7. CR-04 : (technique) après 3 paires de clôtures simultanées, l'encours = somme des parts des ventes clôturées. 8. CR-07 : (technique) la part de 1 F et le taux de 1 % sont refusés, ou ignorés au profit du calcul du serveur (taux 80 %). 9. CR-09 : l'ajout d'un tiers payant à 250 % est refusé. 10. CR-10 : le retrait du tiers payant d'une vente encaissée est refusé, la ligne reste facturable. 11. CA-03 (précondition) : la vente de l'organisme exclu est enregistrée comme exclue. 12. CA-03 : aucune des 8 ventes ordinaires suivantes n'est enregistrée comme « vente exclue ». 13. CA-03 : une vente ordinaire après des ventes « dépôt » n'est pas enregistrée comme exclue. 14. CA-09 : la part passe de l'organisme A à l'organisme B (encours A → 0, B → part). 15. N5 : changer l'organisme d'une vente déjà facturée est refusé, la ligne facturée reste. 16. Chaque cas se déroule sans exception, et aucune erreur JavaScript n'apparaît. | H5: PRUDENCE : Test de reproduction : une ligne « FAIL » signifie que le défaut est reproduit. Le test retire les tiers payants, clients, ventes et lignes d'essai, et ferme la caisse d'essai s'il l'a créée. | I5: audits/repro-vente-assurance.js | J5: OK | K5: Joué le 30/10 15:33 — 17 / 17 conformes
A6: VEN-02 | B6: Vente comptant : modifications, annulations et clôtures interdites ou cohérentes | C6: (menu non précisé dans le test) > Vente comptant | D6: Reproduire les constats d'audit sur la vente comptant (VC-01 à VC-14, N1, N2) : une vente encaissée ne doit pas changer de quantité, de statut ni de client ; une annulation pendant une modification, la vente du dernier stock deux fois, un paiement insuffisant ou la modification d'une vente annulée doivent être refusés ; l'annulation rend les boîtes au bon lot ; la modification d'une vente d'hier garde une seule date ; une annulation qui échoue n'écrit rien. | E6: Connexion avec le compte de test administrateur ; caisse ouverte pour ce compte (créée par le test si besoin) ; au moins un produit avec du stock ; un autre vendeur actif. Le test automatique crée lui-même : un client « ZZAUDIT VC08 », deux lots d'essai (A épuisé à péremption proche, B à 5 boîtes) sur un produit sans lot, et règle le paramètre FORCER_STOCK_VENTE à 0 ; pour un test manuel, préparer l'équivalent. | F6: 1. VC-01 : encaisser une vente comptant de 2 boîtes, puis tenter de passer la ligne à 5 boîtes. 2. VC-02 : encaisser une vente, puis lancer « Terminer la prévente » dessus. 3. VC-04 : encaisser une vente d'une boîte, ouvrir sa modification, annuler la vente d'origine, puis valider la modification avec un autre vendeur. 4. VC-08 : encaisser une vente pour le client d'essai, puis tenter de la rattacher à un client inconnu. 5. VC-09 : stock du produit à 1, FORCER_STOCK_VENTE à 0 ; préparer deux ventes d'une boîte chacune et les valider l'une après l'autre. 6. VC-11 : vendre 2 boîtes du produit à lots, puis annuler la vente. 7. VC-12 : encaisser une vente, la dater de la veille (préparation faite par le test), puis la modifier et valider la modification avec un autre vendeur. 8. VC-14 : préparer une vente de 2 boîtes et la clôturer en déclarant 1 F reçu et payé. 9. N1 : (Contrôle technique, fait par le test automatique) : retirer la ligne de stock du produit dans l'emplacement, puis annuler la vente. 10. N2 : encaisser une vente, l'annuler, puis tenter d'ouvrir sa modification. | G6: 1. VC-01 (précondition) : la vente de 2 boîtes est encaissée. 2. VC-01 : la modification de quantité est refusée, la ligne reste à 2 boîtes. 3. VC-02 : « Terminer la prévente » est refusé, la vente reste encaissée. 4. VC-04 (précondition) : la modification s'ouvre (copie en cours). 5. VC-04 : l'annulation pendant la modification est refusée, ou la validation de la copie ne réannule pas : une seule annulation, stock = stock de départ − 1, caisse cohérente. 6. VC-08 (précondition) : la vente est rattachée au client d'essai. 7. VC-08 : le changement de client vers un identifiant inconnu est refusé, le client est conservé. 8. VC-09 (précondition) : deux ventes en cours d'une boîte chacune, stock 1. 9. VC-09 : la seconde validation est refusée, le stock ne passe pas sous zéro. 10. VC-11 (précondition) : la vente de 2 boîtes sort du lot B (lot B à 3). 11. VC-11 : l'annulation rend les 2 boîtes au lot B (A = 0, B = 5). 12. VC-12 : toutes les écritures de la modification d'une vente d'hier portent la même date. 13. VC-14 : la clôture qui déclare 1 F payé pour une vente de 2 boîtes est refusée. 14. N1 : (technique) l'annulation qui échoue ne laisse aucune écriture (vente non annulée, aucune copie, aucune contre-passation). 15. N2 : l'ouverture de la modification d'une vente annulée est refusée. 16. Chaque cas se déroule sans exception, et aucune erreur JavaScript n'apparaît. | H6: PRUDENCE : Test de reproduction : une ligne « FAIL » signifie que le défaut est reproduit. Modifie temporairement le paramètre FORCER_STOCK_VENTE (remis à la fin). Le test retire les ventes, le client, les lots d'essai, remet le stock et le paramètre FORCER_STOCK_VENTE à leur valeur, et ferme la caisse d'essai s'il l'a créée. | I6: audits/repro-vente-comptant.js | J6: OK | K6: Joué le 30/10 15:33 — 17 / 17 conformes
