Workbook

Sheet Synthèse
A1: PRESTIGE — Cahier de recette — Synthèse
A2: Une feuille par module (onglets en bas). Les chiffres ci-dessous se calculent depuis la colonne Statut de chaque feuille.
A4: Module | B4: Feuille | C4: Cas | D4: OK | E4: KO | F4: Bloqué | G4: N/A | H4: Non testé | I4: Avancement | J4: Réussite | K4: KO priorité Haute | L4: Auto : OK | M4: Auto : OK partiel | N4: Auto : KO | O4: Auto : non exécuté
A5: Transversal | B5: Transversal | C5: =Transversal!$C$5 -> 17 | D5: =Transversal!$C$7 -> 0 | E5: =Transversal!$C$8 -> 0 | F5: =Transversal!$C$9 -> 0 | G5: =Transversal!$C$10 -> 0 | H5: =Transversal!$C$6 -> 17 | I5: =Transversal!$G$5 -> 0 | J5: =Transversal!$G$6 -> 0 | K5: =Transversal!$G$7 -> 0 | L5: =COUNTIF(Transversal!$N$13:$N$29,"OK") -> 11 | M5: =COUNTIF(Transversal!$N$13:$N$29,"OK PARTIEL") -> 6 | N5: =COUNTIF(Transversal!$N$13:$N$29,"KO") -> 0 | O5: =COUNTIF(Transversal!$N$13:$N$29,"NON EXÉCUTÉ") -> 0
A6: SERVICE CLIENT | B6: Service client | C6: ='Service client'!$C$5 -> 44 | D6: ='Service client'!$C$7 -> 0 | E6: ='Service client'!$C$8 -> 0 | F6: ='Service client'!$C$9 -> 0 | G6: ='Service client'!$C$10 -> 0 | H6: ='Service client'!$C$6 -> 44 | I6: ='Service client'!$G$5 -> 0 | J6: ='Service client'!$G$6 -> 0 | K6: ='Service client'!$G$7 -> 0 | L6: =COUNTIF('Service client'!$N$13:$N$56,"OK") -> 34 | M6: =COUNTIF('Service client'!$N$13:$N$56,"OK PARTIEL") -> 3 | N6: =COUNTIF('Service client'!$N$13:$N$56,"KO") -> 0 | O6: =COUNTIF('Service client'!$N$13:$N$56,"NON EXÉCUTÉ") -> 7
A7: GESTION COURANTE | B7: Gestion courante | C7: ='Gestion courante'!$C$5 -> 19 | D7: ='Gestion courante'!$C$7 -> 0 | E7: ='Gestion courante'!$C$8 -> 0 | F7: ='Gestion courante'!$C$9 -> 0 | G7: ='Gestion courante'!$C$10 -> 0 | H7: ='Gestion courante'!$C$6 -> 19 | I7: ='Gestion courante'!$G$5 -> 0 | J7: ='Gestion courante'!$G$6 -> 0 | K7: ='Gestion courante'!$G$7 -> 0 | L7: =COUNTIF('Gestion courante'!$N$13:$N$31,"OK") -> 16 | M7: =COUNTIF('Gestion courante'!$N$13:$N$31,"OK PARTIEL") -> 0 | N7: =COUNTIF('Gestion courante'!$N$13:$N$31,"KO") -> 0 | O7: =COUNTIF('Gestion courante'!$N$13:$N$31,"NON EXÉCUTÉ") -> 3
A8: FACTURATION | B8: Facturation | C8: =Facturation!$C$5 -> 13 | D8: =Facturation!$C$7 -> 0 | E8: =Facturation!$C$8 -> 0 | F8: =Facturation!$C$9 -> 0 | G8: =Facturation!$C$10 -> 0 | H8: =Facturation!$C$6 -> 13 | I8: =Facturation!$G$5 -> 0 | J8: =Facturation!$G$6 -> 0 | K8: =Facturation!$G$7 -> 0 | L8: =COUNTIF(Facturation!$N$13:$N$25,"OK") -> 11 | M8: =COUNTIF(Facturation!$N$13:$N$25,"OK PARTIEL") -> 2 | N8: =COUNTIF(Facturation!$N$13:$N$25,"KO") -> 0 | O8: =COUNTIF(Facturation!$N$13:$N$25,"NON EXÉCUTÉ") -> 0
A9: GESTION DES PROMOTIONS | B9: Gestion des promotions | C9: ='Gestion des promotions'!$C$5 -> 2 | D9: ='Gestion des promotions'!$C$7 -> 0 | E9: ='Gestion des promotions'!$C$8 -> 0 | F9: ='Gestion des promotions'!$C$9 -> 0 | G9: ='Gestion des promotions'!$C$10 -> 0 | H9: ='Gestion des promotions'!$C$6 -> 2 | I9: ='Gestion des promotions'!$G$5 -> 0 | J9: ='Gestion des promotions'!$G$6 -> 0 | K9: ='Gestion des promotions'!$G$7 -> 0 | L9: =COUNTIF('Gestion des promotions'!$N$13:$N$14,"OK") -> 2 | M9: =COUNTIF('Gestion des promotions'!$N$13:$N$14,"OK PARTIEL") -> 0 | N9: =COUNTIF('Gestion des promotions'!$N$13:$N$14,"KO") -> 0 | O9: =COUNTIF('Gestion des promotions'!$N$13:$N$14,"NON EXÉCUTÉ") -> 0
A10: GESTION DES TIERS-PAYANTS | B10: Gestion des tiers-payants | C10: ='Gestion des tiers-payants'!$C$5 -> 30 | D10: ='Gestion des tiers-payants'!$C$7 -> 0 | E10: ='Gestion des tiers-payants'!$C$8 -> 0 | F10: ='Gestion des tiers-payants'!$C$9 -> 0 | G10: ='Gestion des tiers-payants'!$C$10 -> 0 | H10: ='Gestion des tiers-payants'!$C$6 -> 30 | I10: ='Gestion des tiers-payants'!$G$5 -> 0 | J10: ='Gestion des tiers-payants'!$G$6 -> 0 | K10: ='Gestion des tiers-payants'!$G$7 -> 0 | L10: =COUNTIF('Gestion des tiers-payants'!$N$13:$N$42,"OK") -> 27 | M10: =COUNTIF('Gestion des tiers-payants'!$N$13:$N$42,"OK PARTIEL") -> 1 | N10: =COUNTIF('Gestion des tiers-payants'!$N$13:$N$42,"KO") -> 0 | O10: =COUNTIF('Gestion des tiers-payants'!$N$13:$N$42,"NON EXÉCUTÉ") -> 2
A11: MENU PHARMACIEN | B11: Menu pharmacien | C11: ='Menu pharmacien'!$C$5 -> 4 | D11: ='Menu pharmacien'!$C$7 -> 0 | E11: ='Menu pharmacien'!$C$8 -> 0 | F11: ='Menu pharmacien'!$C$9 -> 0 | G11: ='Menu pharmacien'!$C$10 -> 0 | H11: ='Menu pharmacien'!$C$6 -> 4 | I11: ='Menu pharmacien'!$G$5 -> 0 | J11: ='Menu pharmacien'!$G$6 -> 0 | K11: ='Menu pharmacien'!$G$7 -> 0 | L11: =COUNTIF('Menu pharmacien'!$N$13:$N$16,"OK") -> 4 | M11: =COUNTIF('Menu pharmacien'!$N$13:$N$16,"OK PARTIEL") -> 0 | N11: =COUNTIF('Menu pharmacien'!$N$13:$N$16,"KO") -> 0 | O11: =COUNTIF('Menu pharmacien'!$N$13:$N$16,"NON EXÉCUTÉ") -> 0
A12: GESTION DES COMMANDES | B12: Gestion des commandes | C12: ='Gestion des commandes'!$C$5 -> 30 | D12: ='Gestion des commandes'!$C$7 -> 0 | E12: ='Gestion des commandes'!$C$8 -> 0 | F12: ='Gestion des commandes'!$C$9 -> 0 | G12: ='Gestion des commandes'!$C$10 -> 0 | H12: ='Gestion des commandes'!$C$6 -> 30 | I12: ='Gestion des commandes'!$G$5 -> 0 | J12: ='Gestion des commandes'!$G$6 -> 0 | K12: ='Gestion des commandes'!$G$7 -> 0 | L12: =COUNTIF('Gestion des commandes'!$N$13:$N$42,"OK") -> 24 | M12: =COUNTIF('Gestion des commandes'!$N$13:$N$42,"OK PARTIEL") -> 1 | N12: =COUNTIF('Gestion des commandes'!$N$13:$N$42,"KO") -> 0 | O12: =COUNTIF('Gestion des commandes'!$N$13:$N$42,"NON EXÉCUTÉ") -> 5
A13: GESTION DU STOCK | B13: Gestion du stock | C13: ='Gestion du stock'!$C$5 -> 46 | D13: ='Gestion du stock'!$C$7 -> 0 | E13: ='Gestion du stock'!$C$8 -> 0 | F13: ='Gestion du stock'!$C$9 -> 0 | G13: ='Gestion du stock'!$C$10 -> 0 | H13: ='Gestion du stock'!$C$6 -> 46 | I13: ='Gestion du stock'!$G$5 -> 0 | J13: ='Gestion du stock'!$G$6 -> 0 | K13: ='Gestion du stock'!$G$7 -> 0 | L13: =COUNTIF('Gestion du stock'!$N$13:$N$58,"OK") -> 39 | M13: =COUNTIF('Gestion du stock'!$N$13:$N$58,"OK PARTIEL") -> 3 | N13: =COUNTIF('Gestion du stock'!$N$13:$N$58,"KO") -> 0 | O13: =COUNTIF('Gestion du stock'!$N$13:$N$58,"NON EXÉCUTÉ") -> 4
A14: PARAMETRAGES | B14: Parametrages | C14: =Parametrages!$C$5 -> 35 | D14: =Parametrages!$C$7 -> 0 | E14: =Parametrages!$C$8 -> 0 | F14: =Parametrages!$C$9 -> 0 | G14: =Parametrages!$C$10 -> 0 | H14: =Parametrages!$C$6 -> 35 | I14: =Parametrages!$G$5 -> 0 | J14: =Parametrages!$G$6 -> 0 | K14: =Parametrages!$G$7 -> 0 | L14: =COUNTIF(Parametrages!$N$13:$N$47,"OK") -> 31 | M14: =COUNTIF(Parametrages!$N$13:$N$47,"OK PARTIEL") -> 2 | N14: =COUNTIF(Parametrages!$N$13:$N$47,"KO") -> 0 | O14: =COUNTIF(Parametrages!$N$13:$N$47,"NON EXÉCUTÉ") -> 2
A15: RETROCESSION | B15: Retrocession | C15: =Retrocession!$C$5 -> 2 | D15: =Retrocession!$C$7 -> 0 | E15: =Retrocession!$C$8 -> 0 | F15: =Retrocession!$C$9 -> 0 | G15: =Retrocession!$C$10 -> 0 | H15: =Retrocession!$C$6 -> 2 | I15: =Retrocession!$G$5 -> 0 | J15: =Retrocession!$G$6 -> 0 | K15: =Retrocession!$G$7 -> 0 | L15: =COUNTIF(Retrocession!$N$13:$N$14,"OK") -> 2 | M15: =COUNTIF(Retrocession!$N$13:$N$14,"OK PARTIEL") -> 0 | N15: =COUNTIF(Retrocession!$N$13:$N$14,"KO") -> 0 | O15: =COUNTIF(Retrocession!$N$13:$N$14,"NON EXÉCUTÉ") -> 0
A16: ANALYSE DE GESTION | B16: Analyse de gestion | C16: ='Analyse de gestion'!$C$5 -> 48 | D16: ='Analyse de gestion'!$C$7 -> 0 | E16: ='Analyse de gestion'!$C$8 -> 0 | F16: ='Analyse de gestion'!$C$9 -> 0 | G16: ='Analyse de gestion'!$C$10 -> 0 | H16: ='Analyse de gestion'!$C$6 -> 48 | I16: ='Analyse de gestion'!$G$5 -> 0 | J16: ='Analyse de gestion'!$G$6 -> 0 | K16: ='Analyse de gestion'!$G$7 -> 0 | L16: =COUNTIF('Analyse de gestion'!$N$13:$N$60,"OK") -> 40 | M16: =COUNTIF('Analyse de gestion'!$N$13:$N$60,"OK PARTIEL") -> 1 | N16: =COUNTIF('Analyse de gestion'!$N$13:$N$60,"KO") -> 0 | O16: =COUNTIF('Analyse de gestion'!$N$13:$N$60,"NON EXÉCUTÉ") -> 7
A17: NOTIFICATIONS | B17: Notifications | C17: =Notifications!$C$5 -> 6 | D17: =Notifications!$C$7 -> 0 | E17: =Notifications!$C$8 -> 0 | F17: =Notifications!$C$9 -> 0 | G17: =Notifications!$C$10 -> 0 | H17: =Notifications!$C$6 -> 6 | I17: =Notifications!$G$5 -> 0 | J17: =Notifications!$G$6 -> 0 | K17: =Notifications!$G$7 -> 0 | L17: =COUNTIF(Notifications!$N$13:$N$18,"OK") -> 5 | M17: =COUNTIF(Notifications!$N$13:$N$18,"OK PARTIEL") -> 0 | N17: =COUNTIF(Notifications!$N$13:$N$18,"KO") -> 0 | O17: =COUNTIF(Notifications!$N$13:$N$18,"NON EXÉCUTÉ") -> 1
A18: GESTION DES UTILISATEURS | B18: Gestion des utilisateurs | C18: ='Gestion des utilisateurs'!$C$5 -> 6 | D18: ='Gestion des utilisateurs'!$C$7 -> 0 | E18: ='Gestion des utilisateurs'!$C$8 -> 0 | F18: ='Gestion des utilisateurs'!$C$9 -> 0 | G18: ='Gestion des utilisateurs'!$C$10 -> 0 | H18: ='Gestion des utilisateurs'!$C$6 -> 6 | I18: ='Gestion des utilisateurs'!$G$5 -> 0 | J18: ='Gestion des utilisateurs'!$G$6 -> 0 | K18: ='Gestion des utilisateurs'!$G$7 -> 0 | L18: =COUNTIF('Gestion des utilisateurs'!$N$13:$N$18,"OK") -> 5 | M18: =COUNTIF('Gestion des utilisateurs'!$N$13:$N$18,"OK PARTIEL") -> 0 | N18: =COUNTIF('Gestion des utilisateurs'!$N$13:$N$18,"KO") -> 0 | O18: =COUNTIF('Gestion des utilisateurs'!$N$13:$N$18,"NON EXÉCUTÉ") -> 1
A19: CONFIGURATION | B19: Configuration | C19: =Configuration!$C$5 -> 10 | D19: =Configuration!$C$7 -> 0 | E19: =Configuration!$C$8 -> 0 | F19: =Configuration!$C$9 -> 0 | G19: =Configuration!$C$10 -> 0 | H19: =Configuration!$C$6 -> 10 | I19: =Configuration!$G$5 -> 0 | J19: =Configuration!$G$6 -> 0 | K19: =Configuration!$G$7 -> 0 | L19: =COUNTIF(Configuration!$N$13:$N$22,"OK") -> 3 | M19: =COUNTIF(Configuration!$N$13:$N$22,"OK PARTIEL") -> 0 | N19: =COUNTIF(Configuration!$N$13:$N$22,"KO") -> 0 | O19: =COUNTIF(Configuration!$N$13:$N$22,"NON EXÉCUTÉ") -> 7
A20: Campagnes SMS / WhatsApp | B20: Campagnes SMS - WhatsApp | C20: ='Campagnes SMS - WhatsApp'!$C$5 -> 3 | D20: ='Campagnes SMS - WhatsApp'!$C$7 -> 0 | E20: ='Campagnes SMS - WhatsApp'!$C$8 -> 0 | F20: ='Campagnes SMS - WhatsApp'!$C$9 -> 0 | G20: ='Campagnes SMS - WhatsApp'!$C$10 -> 0 | H20: ='Campagnes SMS - WhatsApp'!$C$6 -> 3 | I20: ='Campagnes SMS - WhatsApp'!$G$5 -> 0 | J20: ='Campagnes SMS - WhatsApp'!$G$6 -> 0 | K20: ='Campagnes SMS - WhatsApp'!$G$7 -> 0 | L20: =COUNTIF('Campagnes SMS - WhatsApp'!$N$13:$N$15,"OK") -> 3 | M20: =COUNTIF('Campagnes SMS - WhatsApp'!$N$13:$N$15,"OK PARTIEL") -> 0 | N20: =COUNTIF('Campagnes SMS - WhatsApp'!$N$13:$N$15,"KO") -> 0 | O20: =COUNTIF('Campagnes SMS - WhatsApp'!$N$13:$N$15,"NON EXÉCUTÉ") -> 0
A21: RESSOURCES HUMAINES | B21: Ressources humaines | C21: ='Ressources humaines'!$C$5 -> 8 | D21: ='Ressources humaines'!$C$7 -> 0 | E21: ='Ressources humaines'!$C$8 -> 0 | F21: ='Ressources humaines'!$C$9 -> 0 | G21: ='Ressources humaines'!$C$10 -> 0 | H21: ='Ressources humaines'!$C$6 -> 8 | I21: ='Ressources humaines'!$G$5 -> 0 | J21: ='Ressources humaines'!$G$6 -> 0 | K21: ='Ressources humaines'!$G$7 -> 0 | L21: =COUNTIF('Ressources humaines'!$N$13:$N$20,"OK") -> 7 | M21: =COUNTIF('Ressources humaines'!$N$13:$N$20,"OK PARTIEL") -> 1 | N21: =COUNTIF('Ressources humaines'!$N$13:$N$20,"KO") -> 0 | O21: =COUNTIF('Ressources humaines'!$N$13:$N$20,"NON EXÉCUTÉ") -> 0
A22: Avis clients | B22: Avis clients | C22: ='Avis clients'!$C$5 -> 1 | D22: ='Avis clients'!$C$7 -> 0 | E22: ='Avis clients'!$C$8 -> 0 | F22: ='Avis clients'!$C$9 -> 0 | G22: ='Avis clients'!$C$10 -> 0 | H22: ='Avis clients'!$C$6 -> 1 | I22: ='Avis clients'!$G$5 -> 0 | J22: ='Avis clients'!$G$6 -> 0 | K22: ='Avis clients'!$G$7 -> 0 | L22: =COUNTIF('Avis clients'!$N$13:$N$13,"OK") -> 1 | M22: =COUNTIF('Avis clients'!$N$13:$N$13,"OK PARTIEL") -> 0 | N22: =COUNTIF('Avis clients'!$N$13:$N$13,"KO") -> 0 | O22: =COUNTIF('Avis clients'!$N$13:$N$13,"NON EXÉCUTÉ") -> 0
A23: GESTION CLIENT | B23: Gestion client | C23: ='Gestion client'!$C$5 -> 2 | D23: ='Gestion client'!$C$7 -> 0 | E23: ='Gestion client'!$C$8 -> 0 | F23: ='Gestion client'!$C$9 -> 0 | G23: ='Gestion client'!$C$10 -> 0 | H23: ='Gestion client'!$C$6 -> 2 | I23: ='Gestion client'!$G$5 -> 0 | J23: ='Gestion client'!$G$6 -> 0 | K23: ='Gestion client'!$G$7 -> 0 | L23: =COUNTIF('Gestion client'!$N$13:$N$14,"OK") -> 1 | M23: =COUNTIF('Gestion client'!$N$13:$N$14,"OK PARTIEL") -> 1 | N23: =COUNTIF('Gestion client'!$N$13:$N$14,"KO") -> 0 | O23: =COUNTIF('Gestion client'!$N$13:$N$14,"NON EXÉCUTÉ") -> 0
A24: CENTRE DE SUPPORT | B24: Centre de support | C24: ='Centre de support'!$C$5 -> 12 | D24: ='Centre de support'!$C$7 -> 0 | E24: ='Centre de support'!$C$8 -> 0 | F24: ='Centre de support'!$C$9 -> 0 | G24: ='Centre de support'!$C$10 -> 0 | H24: ='Centre de support'!$C$6 -> 12 | I24: ='Centre de support'!$G$5 -> 0 | J24: ='Centre de support'!$G$6 -> 0 | K24: ='Centre de support'!$G$7 -> 0 | L24: =COUNTIF('Centre de support'!$N$13:$N$24,"OK") -> 10 | M24: =COUNTIF('Centre de support'!$N$13:$N$24,"OK PARTIEL") -> 1 | N24: =COUNTIF('Centre de support'!$N$13:$N$24,"KO") -> 0 | O24: =COUNTIF('Centre de support'!$N$13:$N$24,"NON EXÉCUTÉ") -> 1
A25: TOTAL | C25: =SUM(C5:C24) -> 338 | D25: =SUM(D5:D24) -> 0 | E25: =SUM(E5:E24) -> 0 | F25: =SUM(F5:F24) -> 0 | G25: =SUM(G5:G24) -> 0 | H25: =SUM(H5:H24) -> 338 | I25: =IF((C25-G25)=0,0,(D25+E25+F25)/(C25-G25)) -> 0 | J25: =IF((D25+E25+F25)=0,0,D25/(D25+E25+F25)) -> 0 | K25: =SUM(K5:K24) -> 0 | L25: =SUM(L5:L24) -> 276 | M25: =SUM(M5:M24) -> 22 | N25: =SUM(N5:N24) -> 0 | O25: =SUM(O5:O24) -> 40

Sheet Transversal
A1: PRESTIGE — Cahier de recette — Transversal
A2: Version testée : | E2: Base de test (jamais la production) :
A4: Synthèse du module | I4: Mode d'emploi
A5: Total des cas | C5: =COUNTA($A$13:$A$29) -> 17 | E5: Avancement (testés hors N/A) | G5: =IF(($C$5-$C$10)=0,0,($C$7+$C$8+$C$9)/($C$5-$C$10)) -> 0 | I5: Remplir uniquement les cellules jaunes : Testeur, Date (jj/mm/aaaa), Statut (liste), Résultat obtenu, N° ticket.
A6: Non testé | C6: =C5-COUNTIF($K$13:$K$29,"OK")-COUNTIF($K$13:$K$29,"KO")-COUNTIF($K$13:$K$29,"Bloqué")-COUNTIF($K$13:$K$29,"N/A") -> 17 | D6: =IF($C$5=0,0,C6/$C$5) -> 1 | E6: Taux de réussite (OK / testés) | G6: =IF(($C$7+$C$8+$C$9)=0,0,$C$7/($C$7+$C$8+$C$9)) -> 0 | I6: Statut : Non testé (vide) · OK · KO (décrire et ouvrir un ticket) · Bloqué · N/A (sans objet).
A7: OK | C7: =COUNTIF($K$13:$K$29,"OK") -> 0 | D7: =IF($C$5=0,0,C7/$C$5) -> 0 | E7: KO en priorité Haute | G7: =COUNTIFS($K$13:$K$29,"KO",$H$13:$H$29,"Haute") -> 0 | I7: Exemple : Testeur « A. KONÉ » · Date 24/10/2026 · Statut KO · Résultat « Ticket sans le nom du vendeur » · Ticket « SUP-0042 ».
A8: KO | C8: =COUNTIF($K$13:$K$29,"KO") -> 0 | D8: =IF($C$5=0,0,C8/$C$5) -> 0 | E8: Exécution automatique : OK / OK partiel / KO / non exécuté | G8: =COUNTIF(N13:N29,"OK")&" / "&COUNTIF(N13:N29,"OK PARTIEL")&" / "&COUNTIF(N13:N29,"KO")&" / "&COUNTIF(N13:N29,"NON EXÉCUTÉ") -> 11 / 6 / 0 / 0 | I8: Tests sur la copie de travail uniquement, jamais la base de production ; sauvegarder la base avant chaque série.
A9: Bloqué | C9: =COUNTIF($K$13:$K$29,"Bloqué") -> 0 | D9: =IF($C$5=0,0,C9/$C$5) -> 0 | I9: Ajouter un cas : insérer une ligne dans le tableau. Colonnes grises : résultat de l'exécution automatique sur le banc (ne pas modifier).
A10: N/A | C10: =COUNTIF($K$13:$K$29,"N/A") -> 0 | D10: =IF($C$5=0,0,C10/$C$5) -> 0
A12: N° | B12: Écran | C12: Type de test | D12: Cas de test | E12: Prérequis | F12: Étapes | G12: Résultat attendu | H12: Priorité | I12: Testeur | J12: Date | K12: Statut | L12: Résultat obtenu / anomalie | M12: N° ticket | N12: Résultat (exécution automatique) | O12: Détail / preuve de l'exécution automatique
A13: 1 | B13: Page de connexion | C13: Fonctionnel | D13: Connexion par identifiant et mot de passe | E13: Compte utilisateur actif | F13: 1. Ouvrir http://<serveur>:8080/prestige 2. Saisir identifiant et mot de passe 3. Entrée | G13: L'accueil s'ouvre avec les menus du profil ; la connexion est notée au journal | H13: Haute | N13: OK | O13: securite/test-connexion.js : 16/16 OK
A14: 2 | B14: Page de connexion | C14: Sécurité | D14: Mot de passe faux | E14: Compte actif | F14: 1. Saisir un mauvais mot de passe 3 fois | G14: Refus à chaque essai, message générique (sans dire si l'identifiant existe) ; après plusieurs échecs, délai d'attente imposé | H14: Haute | N14: OK | O14: securite/test-connexion.js : 16/16 OK securite/test-sessions.js : 12/12 OK
A15: 3 | B15: Page de connexion | C15: Fonctionnel | D15: Connexion par badge QR | E15: Employé rattaché à un utilisateur, badge actif imprimé en QR | F15: 1. Cliquer « Se connecter avec mon badge » 2. Passer le QR devant la douchette | G15: Session ouverte au nom de l'employé, journal « par badge » | H15: Haute | N15: OK | O15: retours/test-connexion-badge.js : 16/16 OK
A16: 4 | B16: Page de connexion | C16: Fonctionnel | D16: Badge scanné dans le champ Identifiant | E16: Badge QR valide | F16: 1. Cliquer dans « Identifiant » 2. Scanner le badge | G16: La lecture est reprise par la connexion par badge ; le contenu ne reste pas affiché ; session ouverte | H16: Moyenne | N16: OK | O16: retours/test-connexion-badge.js : 16/16 OK
A17: 5 | B17: Page de connexion | C17: Fonctionnel | D17: Douchette en clavier QWERTY sur poste AZERTY | E17: Douchette réglée en anglais | F17: 1. Scanner le badge en mode badge | G17: Connexion acceptée (lecture remise en ordre automatiquement) | H17: Moyenne | N17: OK PARTIEL | O17: retours/test-connexion-badge-lecture.js : 9/9 OK Non couvert : frappe simulee : la vraie douchette Sunmi a ete essayee par l'officine le 23/10
A18: 6 | B18: Page de connexion | C18: Ergonomie | D18: Lecture de badge déformée | E18: Douchette mal réglée ou Verr. Maj. actif | F18: 1. Scanner le badge | G18: Message « Lecture du badge déformée » avec ce qui a été lu, secret masqué ; consigne Verr. Maj. si casse inversée | H18: Moyenne | N18: OK | O18: retours/test-connexion-badge-lecture.js : 9/9 OK
A19: 7 | B19: Page de connexion | C19: Sécurité | D19: Badge réimprimé après régénération | E19: QR régénéré dans RH | F19: 1. Scanner l'ancien exemplaire 2. Scanner le nouveau | G19: Ancien : « Badge non reconnu », aucune session ; nouveau : connexion | H19: Haute | N19: OK | O19: retours/test-rh-badge-qr.js : 15/15 OK
A20: 8 | B20: Page de connexion | C20: Sécurité | D20: Badge désactivé / expiré / employé inactif | E20: Badge dans l'un de ces états | F20: 1. Scanner le badge | G20: « Badge non reconnu », aucune session ; raison notée dans server.log sans le secret | H20: Haute | N20: OK | O20: retours/test-connexion-badge.js : 16/16 OK
A21: 9 | B21: Page de connexion | C21: Sécurité | D21: Badge d'un employé sans compte utilisateur | E21: Employé non rattaché, badge imprimé en QR | F21: 1. Scanner le badge | G21: « Badge sans compte utilisateur » avec la marche à suivre, aucune session | H21: Moyenne | N21: OK | O21: retours/test-badge-sans-compte.js : 6/6 OK
A22: 10 | B22: Session | C22: Sécurité | D22: Déconnexion | E22: Session ouverte | F22: 1. GESTION DES UTILISATEURS > Deconnexion | G22: Retour à la page de connexion ; un appel à une page protégée redemande la connexion | H22: Haute | N22: OK PARTIEL | O22: securite/test-sessions.js : 12/12 OK Non couvert : clic sur l'entree « Deconnexion » du menu non joue
A23: 11 | B23: Droits | C23: Sécurité | D23: Menus selon le profil | E23: Deux profils différents (caissier, admin) | F23: 1. Se connecter avec chaque profil | G23: Chaque profil ne voit que les menus de ses droits ; une action interdite est refusée par le serveur | H23: Haute | N23: OK PARTIEL | O23: securite/test-droits-serveur.js : 26/26 OK Non couvert : refus du serveur verifie ; affichage des menus par profil non compare
A24: 12 | B24: Journaux | C24: Sécurité | D24: Aucun secret dans les journaux | E24: Après une série de tests | F24: 1. Ouvrir server.log et le Centre de support | G24: Aucun mot de passe, jeton, secret de badge ni texte de message patient dans les traces | H24: Haute | N24: OK PARTIEL | O24: retours/test-connexion-badge.js : 16/16 OK support/test-sms-configuration-sans-secret.js : 6/6 OK Non couvert : secret du badge et identifiants SMS verifies ; pas une revue complete des journaux
... A29: 17 | B29: Performance | C29: Performance | D29: Temps d'ouverture des écrans principaux | E29: Base de taille réelle | F29: 1. Ouvrir Ventes, Pilotage, Gestion des entrées, Fiche article | G29: Chaque écran utilisable en moins de 3 s ; mesures reportées dans RAPPORT_LENTEUR_CONNEXION.md | H29: Moyenne | N29: OK PARTIEL | O29: perf/test-perf-pilotage.js : 26/26 budgets respectes perf/test-lignes-bl-mobile.js : 5/5 OK Non couvert : temps d'ouverture de chaque ecran : voir les lignes Non-regression

Sheet Service client
A1: PRESTIGE — Cahier de recette — SERVICE CLIENT
A2: Version testée : | E2: Base de test (jamais la production) :
A4: Synthèse du module | I4: Mode d'emploi
A5: Total des cas | C5: =COUNTA($A$13:$A$56) -> 44 | E5: Avancement (testés hors N/A) | G5: =IF(($C$5-$C$10)=0,0,($C$7+$C$8+$C$9)/($C$5-$C$10)) -> 0 | I5: Remplir uniquement les cellules jaunes : Testeur, Date (jj/mm/aaaa), Statut (liste), Résultat obtenu, N° ticket.
A6: Non testé | C6: =C5-COUNTIF($K$13:$K$56,"OK")-COUNTIF($K$13:$K$56,"KO")-COUNTIF($K$13:$K$56,"Bloqué")-COUNTIF($K$13:$K$56,"N/A") -> 44 | D6: =IF($C$5=0,0,C6/$C$5) -> 1 | E6: Taux de réussite (OK / testés) | G6: =IF(($C$7+$C$8+$C$9)=0,0,$C$7/($C$7+$C$8+$C$9)) -> 0 | I6: Statut : Non testé (vide) · OK · KO (décrire et ouvrir un ticket) · Bloqué · N/A (sans objet).
A7: OK | C7: =COUNTIF($K$13:$K$56,"OK") -> 0 | D7: =IF($C$5=0,0,C7/$C$5) -> 0 | E7: KO en priorité Haute | G7: =COUNTIFS($K$13:$K$56,"KO",$H$13:$H$56,"Haute") -> 0 | I7: Exemple : Testeur « A. KONÉ » · Date 24/10/2026 · Statut KO · Résultat « Ticket sans le nom du vendeur » · Ticket « SUP-0042 ».
A8: KO | C8: =COUNTIF($K$13:$K$56,"KO") -> 0 | D8: =IF($C$5=0,0,C8/$C$5) -> 0 | E8: Exécution automatique : OK / OK partiel / KO / non exécuté | G8: =COUNTIF(N13:N56,"OK")&" / "&COUNTIF(N13:N56,"OK PARTIEL")&" / "&COUNTIF(N13:N56,"KO")&" / "&COUNTIF(N13:N56,"NON EXÉCUTÉ") -> 34 / 3 / 0 / 7 | I8: Tests sur la copie de travail uniquement, jamais la base de production ; sauvegarder la base avant chaque série.
A9: Bloqué | C9: =COUNTIF($K$13:$K$56,"Bloqué") -> 0 | D9: =IF($C$5=0,0,C9/$C$5) -> 0 | I9: Ajouter un cas : insérer une ligne dans le tableau. Colonnes grises : résultat de l'exécution automatique sur le banc (ne pas modifier).
A10: N/A | C10: =COUNTIF($K$13:$K$56,"N/A") -> 0 | D10: =IF($C$5=0,0,C10/$C$5) -> 0
A12: N° | B12: Écran | C12: Type de test | D12: Cas de test | E12: Prérequis | F12: Étapes | G12: Résultat attendu | H12: Priorité | I12: Testeur | J12: Date | K12: Statut | L12: Résultat obtenu / anomalie | M12: N° ticket | N12: Résultat (exécution automatique) | O12: Détail / preuve de l'exécution automatique
A13: 1 | B13: Ouverture de Caisse | C13: Fonctionnel | D13: Ouvrir la caisse | E13: Fonds de caisse attribué | F13: 1. Ouvrir la caisse avec le fonds | G13: Caisse ouverte ; les ventes deviennent possibles | H13: Haute | N13: NON EXÉCUTÉ | O13: Pas de test automatique (ouverture de caisse avec fonds) : a faire a la main
A14: 2 | B14: Ventes | C14: Fonctionnel | D14: Vente au comptant | E14: Caisse ouverte, article en stock | F14: 1. Nouvelle vente 2. Scanner ou taper le CIP, Entrée 3. Quantité 4. Clôturer, régler en espèces | G14: Ticket imprimé, stock diminué, montant en caisse | H14: Haute | N14: OK PARTIEL | O14: vente/test-historique-deconditionnement.js : 15/15 OK Non couvert : vente cloturee et stock verifies ; impression du ticket (imprimante) non verifiable ici
A15: 3 | B15: Ventes | C15: Fonctionnel | D15: Vente assurance (tiers-payant) | E15: Client assuré avec tiers-payant et taux | F15: 1. Type de vente Assurance 2. Choisir l'assuré 3. Ajouter les articles 4. Clôturer | G15: Part assurance et part client calculées au taux ; bon enregistré | H15: Haute | N15: OK PARTIEL | O15: vente/test-deuxieme-assurance.js : 14/14 PASS retours/test-vente-client-standard.js : 25/25 OK Non couvert : assure choisi et parts d'assurance modifiees ; vente assurance complete jusqu'a la cloture non jouee
A16: 4 | B16: Ventes | C16: Fonctionnel | D16: Vente carnet | E16: Client carnet | F16: 1. Type Carnet, choisir le client, vendre, clôturer | G16: Montant porté au compte du carnet | H16: Haute | N16: NON EXÉCUTÉ | O16: Pas de test automatique de vente carnet complete : a faire a la main
A17: 5 | B17: Ventes | C17: Fonctionnel | D17: Changement de tiers-payant sur la vente | E17: Vente assurance en cours | F17: 1. Changer le tiers-payant 2. Valider sans choix puis avec choix | G17: Sans choix : champ signalé ; avec choix : vente mise à jour | H17: Moyenne | N17: OK | O17: journal/test-vente-changer-tiers-payant.js : 7/7 OK
A18: 6 | B18: Ventes | C18: Ergonomie | D18: Vendeur tapé non reconnu | E18: Nouvelle vente | F18: 1. Taper un nom inconnu dans « Vendeur », Tab | G18: Signal immédiat (bordure rouge, infobulle, alerte sans fenêtre) : la vente sera au nom de l'utilisateur connecté | H18: Moyenne | N18: OK | O18: journal/test-vente-vendeur-inconnu.js : 5/5 OK
A19: 7 | B19: Ventes | C19: Fonctionnel | D19: Vendeur tapé exact | E19: Nouvelle vente | F19: 1. Taper le nom complet d'un vendeur, Tab | G19: Vendeur reconnu et retenu, pas de signal | H19: Basse | N19: OK | O19: journal/test-vente-vendeur-inconnu.js : 5/5 OK
A20: 8 | B20: Ventes | C20: Fonctionnel | D20: Quantité décimale dans la grille | E20: Vente avec une ligne | F20: 1. Taper 1.5 dans la colonne quantité, Entrée | G20: Quantité enregistrée en entier, sans erreur serveur | H20: Moyenne | N20: OK | O20: journal/test-vente-quantite-decimale.js : 5/5 OK
A21: 9 | B21: Ventes | C21: Fonctionnel | D21: QR code publicitaire scanné | E21: Nouvelle vente | F21: 1. Scanner un QR de site internet dans « Produit » | G21: Message « QR code publicitaire » sans fenêtre, champ vidé, aucune recherche lancée | H21: Basse | N21: OK | O21: journal/test-scan-qr-publicitaire.js : 13/13 OK
A22: 10 | B22: Ventes | C22: Fonctionnel | D22: Étiquette 2D (GS1) scannée | E22: Paramètre de lecture GS1 actif | F22: 1. Scanner un DataMatrix produit | G22: Produit trouvé ; lot comparé, lot périmé refusé | H22: Moyenne | N22: OK | O22: retours/test-etiquettes-gs1.js : 17/17 OK retours/test-gs1-controle-lot.js : 25/25 OK
A23: 11 | B23: Ventes | C23: Fonctionnel | D23: Règlement en points fidélité | E23: Client avec points, fidélité paramétrée | F23: 1. Vente, mode de règlement « Points fidélité » | G23: Points déduits ; montant restant réglé autrement | H23: Moyenne | N23: OK | O23: retours/test-paiement-points.js : 25/25 OK
A24: 12 | B24: Ventes | C24: Fonctionnel | D24: Déconditionnement automatique | E24: Article déconditionnable, stock détail insuffisant | F24: 1. Vendre au détail | G24: Boîte déconditionnée automatiquement ; historique cohérent | H24: Moyenne | N24: OK | O24: vente/test-historique-deconditionnement.js : 15/15 OK
... A56: 44 | B56: Retraits et abandons | C56: Non-régression | D56: Ouverture et affichage de l'écran | E56: Profil ayant le droit du menu | F56: 1. Ouvrir SERVICE CLIENT > Retraits et abandons 2. Utiliser la recherche / les filtres de l'écran 3. Imprimer ou exporter si l'écran le propose | G56: L'écran s'ouvre sans message d'erreur ; la liste se charge ; filtres et impression/export fonctionnent ; aucune erreur au Centre de support | H56: Moyenne | N56: OK | O56: recette/recette-ecrans.js : ouvert par le menu, chargé en 1.7 s — exécuté le 24/10/2026 sur le banc

Sheet Gestion courante
A1: PRESTIGE — Cahier de recette — GESTION COURANTE
A2: Version testée : | E2: Base de test (jamais la production) :
A4: Synthèse du module | I4: Mode d'emploi
A5: Total des cas | C5: =COUNTA($A$13:$A$31) -> 19 | E5: Avancement (testés hors N/A) | G5: =IF(($C$5-$C$10)=0,0,($C$7+$C$8+$C$9)/($C$5-$C$10)) -> 0 | I5: Remplir uniquement les cellules jaunes : Testeur, Date (jj/mm/aaaa), Statut (liste), Résultat obtenu, N° ticket.
A6: Non testé | C6: =C5-COUNTIF($K$13:$K$31,"OK")-COUNTIF($K$13:$K$31,"KO")-COUNTIF($K$13:$K$31,"Bloqué")-COUNTIF($K$13:$K$31,"N/A") -> 19 | D6: =IF($C$5=0,0,C6/$C$5) -> 1 | E6: Taux de réussite (OK / testés) | G6: =IF(($C$7+$C$8+$C$9)=0,0,$C$7/($C$7+$C$8+$C$9)) -> 0 | I6: Statut : Non testé (vide) · OK · KO (décrire et ouvrir un ticket) · Bloqué · N/A (sans objet).
A7: OK | C7: =COUNTIF($K$13:$K$31,"OK") -> 0 | D7: =IF($C$5=0,0,C7/$C$5) -> 0 | E7: KO en priorité Haute | G7: =COUNTIFS($K$13:$K$31,"KO",$H$13:$H$31,"Haute") -> 0 | I7: Exemple : Testeur « A. KONÉ » · Date 24/10/2026 · Statut KO · Résultat « Ticket sans le nom du vendeur » · Ticket « SUP-0042 ».
A8: KO | C8: =COUNTIF($K$13:$K$31,"KO") -> 0 | D8: =IF($C$5=0,0,C8/$C$5) -> 0 | E8: Exécution automatique : OK / OK partiel / KO / non exécuté | G8: =COUNTIF(N13:N31,"OK")&" / "&COUNTIF(N13:N31,"OK PARTIEL")&" / "&COUNTIF(N13:N31,"KO")&" / "&COUNTIF(N13:N31,"NON EXÉCUTÉ") -> 16 / 0 / 0 / 3 | I8: Tests sur la copie de travail uniquement, jamais la base de production ; sauvegarder la base avant chaque série.
A9: Bloqué | C9: =COUNTIF($K$13:$K$31,"Bloqué") -> 0 | D9: =IF($C$5=0,0,C9/$C$5) -> 0 | I9: Ajouter un cas : insérer une ligne dans le tableau. Colonnes grises : résultat de l'exécution automatique sur le banc (ne pas modifier).
A10: N/A | C10: =COUNTIF($K$13:$K$31,"N/A") -> 0 | D10: =IF($C$5=0,0,C10/$C$5) -> 0
A12: N° | B12: Écran | C12: Type de test | D12: Cas de test | E12: Prérequis | F12: Étapes | G12: Résultat attendu | H12: Priorité | I12: Testeur | J12: Date | K12: Statut | L12: Résultat obtenu / anomalie | M12: N° ticket | N12: Résultat (exécution automatique) | O12: Détail / preuve de l'exécution automatique
A13: 1 | B13: Ticket Z | C13: Fonctionnel | D13: Ticket Z du jour | E13: Ventes du jour | F13: 1. Éditer le ticket Z | G13: Totaux par mode de règlement égaux à la caisse | H13: Haute | N13: NON EXÉCUTÉ | O13: Pas de test automatique du ticket Z : a faire a la main
A14: 2 | B14: Balance Vente/Caisse | C14: Fonctionnel | D14: Balance sur une période | E14: Ventes sur la période | F14: 1. Choisir la période | G14: Totaux cohérents avec les ventes terminées de la période | H14: Haute | N14: NON EXÉCUTÉ | O14: Pas de test automatique des totaux de la balance (ouverture : voir la ligne Non-regression) : a faire a la main
A15: 3 | B15: Mouvements de Caisse | C15: Fonctionnel | D15: Entrée / sortie de caisse | E15: Caisse ouverte | F15: 1. Saisir un mouvement | G15: Mouvement visible et pris dans la clôture | H15: Moyenne | N15: OK | O15: caisse/test-mvt-caisse.js : 11/11 PASS
A16: 4 | B16: Ticket Z | C16: Non-régression | D16: Ouverture et affichage de l'écran | E16: Profil ayant le droit du menu | F16: 1. Ouvrir GESTION COURANTE > Ticket Z 2. Utiliser la recherche / les filtres de l'écran 3. Imprimer ou exporter si l'écran le propose | G16: L'écran s'ouvre sans message d'erreur ; la liste se charge ; filtres et impression/export fonctionnent ; aucune erreur au Centre de support | H16: Moyenne | N16: OK | O16: recette/recette-ecrans.js : ouvert par le menu, chargé en 1.6 s, 1 écriture(s) interceptée(s) — exécuté le 24/10/2026 sur le banc
A17: 5 | B17: Bons par organisme | C17: Non-régression | D17: Ouverture et affichage de l'écran | E17: Profil ayant le droit du menu | F17: 1. Ouvrir GESTION COURANTE > Bons par organisme 2. Utiliser la recherche / les filtres de l'écran 3. Imprimer ou exporter si l'écran le propose | G17: L'écran s'ouvre sans message d'erreur ; la liste se charge ; filtres et impression/export fonctionnent ; aucune erreur au Centre de support | H17: Moyenne | N17: OK | O17: recette/recette-ecrans.js : ouvert par le menu, chargé en 1.7 s — exécuté le 24/10/2026 sur le banc
A18: 6 | B18: Mouvements de Caisse | C18: Non-régression | D18: Ouverture et affichage de l'écran | E18: Profil ayant le droit du menu | F18: 1. Ouvrir GESTION COURANTE > Mouvements de Caisse 2. Utiliser la recherche / les filtres de l'écran 3. Imprimer ou exporter si l'écran le propose | G18: L'écran s'ouvre sans message d'erreur ; la liste se charge ; filtres et impression/export fonctionnent ; aucune erreur au Centre de support | H18: Moyenne | N18: OK | O18: recette/recette-ecrans.js : ouvert par le menu, chargé en 1.7 s — exécuté le 24/10/2026 sur le banc
A19: 7 | B19: Visualiser la caisse | C19: Non-régression | D19: Ouverture et affichage de l'écran | E19: Profil ayant le droit du menu | F19: 1. Ouvrir GESTION COURANTE > Visualiser la caisse 2. Utiliser la recherche / les filtres de l'écran 3. Imprimer ou exporter si l'écran le propose | G19: L'écran s'ouvre sans message d'erreur ; la liste se charge ; filtres et impression/export fonctionnent ; aucune erreur au Centre de support | H19: Moyenne | N19: OK | O19: recette/recette-ecrans.js : ouvert par le menu, chargé en 1.8 s — exécuté le 24/10/2026 sur le banc
A20: 8 | B20: Gestion Caisse | C20: Non-régression | D20: Ouverture et affichage de l'écran | E20: Profil ayant le droit du menu | F20: 1. Ouvrir GESTION COURANTE > Gestion Caisse 2. Utiliser la recherche / les filtres de l'écran 3. Imprimer ou exporter si l'écran le propose | G20: L'écran s'ouvre sans message d'erreur ; la liste se charge ; filtres et impression/export fonctionnent ; aucune erreur au Centre de support | H20: Moyenne | N20: OK | O20: recette/recette-ecrans.js : ouvert par le menu, chargé en 1.8 s — exécuté le 24/10/2026 sur le banc
A21: 9 | B21: Liste de Caisse | C21: Non-régression | D21: Ouverture et affichage de l'écran | E21: Profil ayant le droit du menu | F21: 1. Ouvrir GESTION COURANTE > Liste de Caisse 2. Utiliser la recherche / les filtres de l'écran 3. Imprimer ou exporter si l'écran le propose | G21: L'écran s'ouvre sans message d'erreur ; la liste se charge ; filtres et impression/export fonctionnent ; aucune erreur au Centre de support | H21: Moyenne | N21: OK | O21: recette/recette-ecrans.js : ouvert par le menu, chargé en 1.8 s — exécuté le 24/10/2026 sur le banc
A22: 10 | B22: Balance Vente/Caisse | C22: Non-régression | D22: Ouverture et affichage de l'écran | E22: Profil ayant le droit du menu | F22: 1. Ouvrir GESTION COURANTE > Balance Vente/Caisse 2. Utiliser la recherche / les filtres de l'écran 3. Imprimer ou exporter si l'écran le propose | G22: L'écran s'ouvre sans message d'erreur ; la liste se charge ; filtres et impression/export fonctionnent ; aucune erreur au Centre de support | H22: Moyenne | N22: OK | O22: recette/recette-ecrans.js : ouvert par son composant (entrée introuvable sous ce libellé), chargé en 11.4 s, 1 écriture(s) interceptée(s) — exécuté le 24/10/2026 sur le banc
A23: 11 | B23: Balance Depot | C23: Non-régression | D23: Ouverture et affichage de l'écran | E23: Profil ayant le droit du menu | F23: 1. Ouvrir GESTION COURANTE > Balance Depot 2. Utiliser la recherche / les filtres de l'écran 3. Imprimer ou exporter si l'écran le propose | G23: L'écran s'ouvre sans message d'erreur ; la liste se charge ; filtres et impression/export fonctionnent ; aucune erreur au Centre de support | H23: Moyenne | N23: OK | O23: recette/recette-ecrans.js : ouvert par son composant (entrée introuvable sous ce libellé), chargé en 11.0 s — exécuté le 24/10/2026 sur le banc
A24: 12 | B24: Point Caisse Depot | C24: Non-régression | D24: Ouverture et affichage de l'écran | E24: Profil ayant le droit du menu | F24: 1. Ouvrir GESTION COURANTE > Point Caisse Depot 2. Utiliser la recherche / les filtres de l'écran 3. Imprimer ou exporter si l'écran le propose | G24: L'écran s'ouvre sans message d'erreur ; la liste se charge ; filtres et impression/export fonctionnent ; aucune erreur au Centre de support | H24: Moyenne | N24: OK | O24: recette/recette-ecrans.js : écran court, bien dessiné (160 px, vérifié sur capture) ; ouvert par son composant (entrée introuvable sous ce libellé), chargé en 11.6 s — exécuté le 24/10/2026 sur le banc
... A31: 19 | B31: Mouchard prix de vente | C31: Non-régression | D31: Ouverture et affichage de l'écran | E31: Profil ayant le droit du menu | F31: 1. Ouvrir GESTION COURANTE > Mouchard prix de vente 2. Utiliser la recherche / les filtres de l'écran 3. Imprimer ou exporter si l'écran le propose | G31: L'écran s'ouvre sans message d'erreur ; la liste se charge ; filtres et impression/export fonctionnent ; aucune erreur au Centre de support | H31: Moyenne | N31: OK | O31: recette/recette-ecrans.js : ouvert par le menu, chargé en 1.7 s — exécuté le 24/10/2026 sur le banc

Sheet Facturation
A1: PRESTIGE — Cahier de recette — FACTURATION
A2: Version testée : | E2: Base de test (jamais la production) :
A4: Synthèse du module | I4: Mode d'emploi
A5: Total des cas | C5: =COUNTA($A$13:$A$25) -> 13 | E5: Avancement (testés hors N/A) | G5: =IF(($C$5-$C$10)=0,0,($C$7+$C$8+$C$9)/($C$5-$C$10)) -> 0 | I5: Remplir uniquement les cellules jaunes : Testeur, Date (jj/mm/aaaa), Statut (liste), Résultat obtenu, N° ticket.
A6: Non testé | C6: =C5-COUNTIF($K$13:$K$25,"OK")-COUNTIF($K$13:$K$25,"KO")-COUNTIF($K$13:$K$25,"Bloqué")-COUNTIF($K$13:$K$25,"N/A") -> 13 | D6: =IF($C$5=0,0,C6/$C$5) -> 1 | E6: Taux de réussite (OK / testés) | G6: =IF(($C$7+$C$8+$C$9)=0,0,$C$7/($C$7+$C$8+$C$9)) -> 0 | I6: Statut : Non testé (vide) · OK · KO (décrire et ouvrir un ticket) · Bloqué · N/A (sans objet).
A7: OK | C7: =COUNTIF($K$13:$K$25,"OK") -> 0 | D7: =IF($C$5=0,0,C7/$C$5) -> 0 | E7: KO en priorité Haute | G7: =COUNTIFS($K$13:$K$25,"KO",$H$13:$H$25,"Haute") -> 0 | I7: Exemple : Testeur « A. KONÉ » · Date 24/10/2026 · Statut KO · Résultat « Ticket sans le nom du vendeur » · Ticket « SUP-0042 ».
A8: KO | C8: =COUNTIF($K$13:$K$25,"KO") -> 0 | D8: =IF($C$5=0,0,C8/$C$5) -> 0 | E8: Exécution automatique : OK / OK partiel / KO / non exécuté | G8: =COUNTIF(N13:N25,"OK")&" / "&COUNTIF(N13:N25,"OK PARTIEL")&" / "&COUNTIF(N13:N25,"KO")&" / "&COUNTIF(N13:N25,"NON EXÉCUTÉ") -> 11 / 2 / 0 / 0 | I8: Tests sur la copie de travail uniquement, jamais la base de production ; sauvegarder la base avant chaque série.
A9: Bloqué | C9: =COUNTIF($K$13:$K$25,"Bloqué") -> 0 | D9: =IF($C$5=0,0,C9/$C$5) -> 0 | I9: Ajouter un cas : insérer une ligne dans le tableau. Colonnes grises : résultat de l'exécution automatique sur le banc (ne pas modifier).
A10: N/A | C10: =COUNTIF($K$13:$K$25,"N/A") -> 0 | D10: =IF($C$5=0,0,C10/$C$5) -> 0
A12: N° | B12: Écran | C12: Type de test | D12: Cas de test | E12: Prérequis | F12: Étapes | G12: Résultat attendu | H12: Priorité | I12: Testeur | J12: Date | K12: Statut | L12: Résultat obtenu / anomalie | M12: N° ticket | N12: Résultat (exécution automatique) | O12: Détail / preuve de l'exécution automatique
A13: 1 | B13: Gestion des différés | C13: Fonctionnel | D13: Régler un différé | E13: Client avec ventes en différé | F13: 1. Choisir le client 2. Saisir un règlement partiel puis total | G13: Solde mis à jour ; règlement non compté deux fois ; ticket de règlement | H13: Haute | N13: OK | O13: retours/test-differes-reglement.js : 14/14 OK
A14: 2 | B14: Factures | C14: Fonctionnel | D14: Générer les factures tiers-payant | E14: Bons de la période | F14: 1. Générer pour un organisme | G14: Facture créée avec les bons ; impression et export | H14: Haute | N14: OK PARTIEL | O14: facturation/test-cachet-facture.js : 11/11 OK Non couvert : edition d'une facture existante verifiee ; generation des factures d'un organisme non jouee
A15: 3 | B15: Liste des Reglements | C15: Fonctionnel | D15: Régler une facture | E15: Facture émise | F15: 1. Saisir le règlement | G15: Facture soldée ou partiellement réglée ; balance âgée à jour | H15: Haute | N15: OK PARTIEL | O15: reglement/test-liste-reglements.js : 19/19 PASS Non couvert : liste et exports verifies ; saisie d'un reglement de facture non jouee
A16: 4 | B16: Gestion des différés | C16: Non-régression | D16: Ouverture et affichage de l'écran | E16: Profil ayant le droit du menu | F16: 1. Ouvrir FACTURATION > Gestion des différés 2. Utiliser la recherche / les filtres de l'écran 3. Imprimer ou exporter si l'écran le propose | G16: L'écran s'ouvre sans message d'erreur ; la liste se charge ; filtres et impression/export fonctionnent ; aucune erreur au Centre de support | H16: Moyenne | N16: OK | O16: recette/recette-ecrans.js : ouvert par son composant (entrée introuvable sous ce libellé), chargé en 11.6 s — exécuté le 24/10/2026 sur le banc
A17: 5 | B17: Liste des Reglements | C17: Non-régression | D17: Ouverture et affichage de l'écran | E17: Profil ayant le droit du menu | F17: 1. Ouvrir FACTURATION > Liste des Reglements 2. Utiliser la recherche / les filtres de l'écran 3. Imprimer ou exporter si l'écran le propose | G17: L'écran s'ouvre sans message d'erreur ; la liste se charge ; filtres et impression/export fonctionnent ; aucune erreur au Centre de support | H17: Moyenne | N17: OK | O17: recette/recette-ecrans.js : ouvert par le menu, chargé en 1.2 s — exécuté le 24/10/2026 sur le banc
A18: 6 | B18: Factures | C18: Non-régression | D18: Ouverture et affichage de l'écran | E18: Profil ayant le droit du menu | F18: 1. Ouvrir FACTURATION > Factures 2. Utiliser la recherche / les filtres de l'écran 3. Imprimer ou exporter si l'écran le propose | G18: L'écran s'ouvre sans message d'erreur ; la liste se charge ; filtres et impression/export fonctionnent ; aucune erreur au Centre de support | H18: Moyenne | N18: OK | O18: recette/recette-ecrans.js : ouvert par le menu, chargé en 1.8 s — exécuté le 24/10/2026 sur le banc
A19: 7 | B19: Dossiers à facturer | C19: Non-régression | D19: Ouverture et affichage de l'écran | E19: Profil ayant le droit du menu | F19: 1. Ouvrir FACTURATION > Dossiers à facturer 2. Utiliser la recherche / les filtres de l'écran 3. Imprimer ou exporter si l'écran le propose | G19: L'écran s'ouvre sans message d'erreur ; la liste se charge ; filtres et impression/export fonctionnent ; aucune erreur au Centre de support | H19: Moyenne | N19: OK | O19: recette/recette-ecrans.js : ouvert par le menu, chargé en 1.7 s — exécuté le 24/10/2026 sur le banc
A20: 8 | B20: Récap par organisme | C20: Non-régression | D20: Ouverture et affichage de l'écran | E20: Profil ayant le droit du menu | F20: 1. Ouvrir FACTURATION > Récap par organisme 2. Utiliser la recherche / les filtres de l'écran 3. Imprimer ou exporter si l'écran le propose | G20: L'écran s'ouvre sans message d'erreur ; la liste se charge ; filtres et impression/export fonctionnent ; aucune erreur au Centre de support | H20: Moyenne | N20: OK | O20: recette/recette-ecrans.js : ouvert par le menu, chargé en 2.6 s — exécuté le 24/10/2026 sur le banc
A21: 9 | B21: Factures Compagnies Ass | C21: Non-régression | D21: Ouverture et affichage de l'écran | E21: Profil ayant le droit du menu | F21: 1. Ouvrir FACTURATION > Factures Compagnies Ass 2. Utiliser la recherche / les filtres de l'écran 3. Imprimer ou exporter si l'écran le propose | G21: L'écran s'ouvre sans message d'erreur ; la liste se charge ; filtres et impression/export fonctionnent ; aucune erreur au Centre de support | H21: Moyenne | N21: OK | O21: recette/recette-ecrans.js : ouvert par son composant (entrée introuvable sous ce libellé), chargé en 11.5 s, 1 écriture(s) interceptée(s) — exécuté le 24/10/2026 sur le banc
A22: 10 | B22: Factures provisoires | C22: Non-régression | D22: Ouverture et affichage de l'écran | E22: Profil ayant le droit du menu | F22: 1. Ouvrir FACTURATION > Factures provisoires 2. Utiliser la recherche / les filtres de l'écran 3. Imprimer ou exporter si l'écran le propose | G22: L'écran s'ouvre sans message d'erreur ; la liste se charge ; filtres et impression/export fonctionnent ; aucune erreur au Centre de support | H22: Moyenne | N22: OK | O22: recette/recette-ecrans.js : ouvert par son composant (entrée introuvable sous ce libellé), chargé en 11.0 s — exécuté le 24/10/2026 sur le banc
A23: 11 | B23: Modèle de facture | C23: Non-régression | D23: Ouverture et affichage de l'écran | E23: Profil ayant le droit du menu | F23: 1. Ouvrir FACTURATION > Modèle de facture 2. Utiliser la recherche / les filtres de l'écran 3. Imprimer ou exporter si l'écran le propose | G23: L'écran s'ouvre sans message d'erreur ; la liste se charge ; filtres et impression/export fonctionnent ; aucune erreur au Centre de support | H23: Moyenne | N23: OK | O23: recette/recette-ecrans.js : ouvert par son composant (entrée introuvable sous ce libellé), chargé en 11.0 s — exécuté le 24/10/2026 sur le banc
A24: 12 | B24: Suivi des bons | C24: Non-régression | D24: Ouverture et affichage de l'écran | E24: Profil ayant le droit du menu | F24: 1. Ouvrir FACTURATION > Suivi des bons 2. Utiliser la recherche / les filtres de l'écran 3. Imprimer ou exporter si l'écran le propose | G24: L'écran s'ouvre sans message d'erreur ; la liste se charge ; filtres et impression/export fonctionnent ; aucune erreur au Centre de support | H24: Moyenne | N24: OK | O24: recette/recette-ecrans.js : ouvert par son composant (entrée introuvable sous ce libellé), chargé en 11.3 s — exécuté le 24/10/2026 sur le banc
A25: 13 | B25: Modèles de facture | C25: Non-régression | D25: Ouverture et affichage de l'écran | E25: Profil ayant le droit du menu | F25: 1. Ouvrir FACTURATION > Modèles de facture 2. Utiliser la recherche / les filtres de l'écran 3. Imprimer ou exporter si l'écran le propose | G25: L'écran s'ouvre sans message d'erreur ; la liste se charge ; filtres et impression/export fonctionnent ; aucune erreur au Centre de support | H25: Moyenne | N25: OK | O25: recette/recette-ecrans.js : ouvert par son composant (entrée introuvable sous ce libellé), chargé en 11.0 s — exécuté le 24/10/2026 sur le banc

Sheet Gestion des promotions
A1: PRESTIGE — Cahier de recette — GESTION DES PROMOTIONS
A2: Version testée : | E2: Base de test (jamais la production) :
A4: Synthèse du module | I4: Mode d'emploi
A5: Total des cas | C5: =COUNTA($A$13:$A$14) -> 2 | E5: Avancement (testés hors N/A) | G5: =IF(($C$5-$C$10)=0,0,($C$7+$C$8+$C$9)/($C$5-$C$10)) -> 0 | I5: Remplir uniquement les cellules jaunes : Testeur, Date (jj/mm/aaaa), Statut (liste), Résultat obtenu, N° ticket.
A6: Non testé | C6: =C5-COUNTIF($K$13:$K$14,"OK")-COUNTIF($K$13:$K$14,"KO")-COUNTIF($K$13:$K$14,"Bloqué")-COUNTIF($K$13:$K$14,"N/A") -> 2 | D6: =IF($C$5=0,0,C6/$C$5) -> 1 | E6: Taux de réussite (OK / testés) | G6: =IF(($C$7+$C$8+$C$9)=0,0,$C$7/($C$7+$C$8+$C$9)) -> 0 | I6: Statut : Non testé (vide) · OK · KO (décrire et ouvrir un ticket) · Bloqué · N/A (sans objet).
A7: OK | C7: =COUNTIF($K$13:$K$14,"OK") -> 0 | D7: =IF($C$5=0,0,C7/$C$5) -> 0 | E7: KO en priorité Haute | G7: =COUNTIFS($K$13:$K$14,"KO",$H$13:$H$14,"Haute") -> 0 | I7: Exemple : Testeur « A. KONÉ » · Date 24/10/2026 · Statut KO · Résultat « Ticket sans le nom du vendeur » · Ticket « SUP-0042 ».
A8: KO | C8: =COUNTIF($K$13:$K$14,"KO") -> 0 | D8: =IF($C$5=0,0,C8/$C$5) -> 0 | E8: Exécution automatique : OK / OK partiel / KO / non exécuté | G8: =COUNTIF(N13:N14,"OK")&" / "&COUNTIF(N13:N14,"OK PARTIEL")&" / "&COUNTIF(N13:N14,"KO")&" / "&COUNTIF(N13:N14,"NON EXÉCUTÉ") -> 2 / 0 / 0 / 0 | I8: Tests sur la copie de travail uniquement, jamais la base de production ; sauvegarder la base avant chaque série.
A9: Bloqué | C9: =COUNTIF($K$13:$K$14,"Bloqué") -> 0 | D9: =IF($C$5=0,0,C9/$C$5) -> 0 | I9: Ajouter un cas : insérer une ligne dans le tableau. Colonnes grises : résultat de l'exécution automatique sur le banc (ne pas modifier).
A10: N/A | C10: =COUNTIF($K$13:$K$14,"N/A") -> 0 | D10: =IF($C$5=0,0,C10/$C$5) -> 0
A12: N° | B12: Écran | C12: Type de test | D12: Cas de test | E12: Prérequis | F12: Étapes | G12: Résultat attendu | H12: Priorité | I12: Testeur | J12: Date | K12: Statut | L12: Résultat obtenu / anomalie | M12: N° ticket | N12: Résultat (exécution automatique) | O12: Détail / preuve de l'exécution automatique
A13: 1 | B13: Promotions | C13: Non-régression | D13: Ouverture et affichage de l'écran | E13: Profil ayant le droit du menu | F13: 1. Ouvrir GESTION DES PROMOTIONS > Promotions 2. Utiliser la recherche / les filtres de l'écran 3. Imprimer ou exporter si l'écran le propose | G13: L'écran s'ouvre sans message d'erreur ; la liste se charge ; filtres et impression/export fonctionnent ; aucune erreur au Centre de support | H13: Basse | N13: OK | O13: recette/recette-ecrans.js : ouvert par son composant (entrée introuvable sous ce libellé), chargé en 20.9 s, 1 écriture(s) interceptée(s) — exécuté le 24/10/2026 sur le banc
A14: 2 | B14: Historique des Promotions | C14: Non-régression | D14: Ouverture et affichage de l'écran | E14: Profil ayant le droit du menu | F14: 1. Ouvrir GESTION DES PROMOTIONS > Historique des Promotions 2. Utiliser la recherche / les filtres de l'écran 3. Imprimer ou exporter si l'écran le propose | G14: L'écran s'ouvre sans message d'erreur ; la liste se charge ; filtres et impression/export fonctionnent ; aucune erreur au Centre de support | H14: Basse | N14: OK | O14: recette/recette-ecrans.js : ouvert par son composant (entrée introuvable sous ce libellé), chargé en 20.9 s — exécuté le 24/10/2026 sur le banc

Sheet Gestion des tiers-payants
A1: PRESTIGE — Cahier de recette — GESTION DES TIERS-PAYANTS
A2: Version testée : | E2: Base de test (jamais la production) :
A4: Synthèse du module | I4: Mode d'emploi
A5: Total des cas | C5: =COUNTA($A$13:$A$42) -> 30 | E5: Avancement (testés hors N/A) | G5: =IF(($C$5-$C$10)=0,0,($C$7+$C$8+$C$9)/($C$5-$C$10)) -> 0 | I5: Remplir uniquement les cellules jaunes : Testeur, Date (jj/mm/aaaa), Statut (liste), Résultat obtenu, N° ticket.
A6: Non testé | C6: =C5-COUNTIF($K$13:$K$42,"OK")-COUNTIF($K$13:$K$42,"KO")-COUNTIF($K$13:$K$42,"Bloqué")-COUNTIF($K$13:$K$42,"N/A") -> 30 | D6: =IF($C$5=0,0,C6/$C$5) -> 1 | E6: Taux de réussite (OK / testés) | G6: =IF(($C$7+$C$8+$C$9)=0,0,$C$7/($C$7+$C$8+$C$9)) -> 0 | I6: Statut : Non testé (vide) · OK · KO (décrire et ouvrir un ticket) · Bloqué · N/A (sans objet).
A7: OK | C7: =COUNTIF($K$13:$K$42,"OK") -> 0 | D7: =IF($C$5=0,0,C7/$C$5) -> 0 | E7: KO en priorité Haute | G7: =COUNTIFS($K$13:$K$42,"KO",$H$13:$H$42,"Haute") -> 0 | I7: Exemple : Testeur « A. KONÉ » · Date 24/10/2026 · Statut KO · Résultat « Ticket sans le nom du vendeur » · Ticket « SUP-0042 ».
A8: KO | C8: =COUNTIF($K$13:$K$42,"KO") -> 0 | D8: =IF($C$5=0,0,C8/$C$5) -> 0 | E8: Exécution automatique : OK / OK partiel / KO / non exécuté | G8: =COUNTIF(N13:N42,"OK")&" / "&COUNTIF(N13:N42,"OK PARTIEL")&" / "&COUNTIF(N13:N42,"KO")&" / "&COUNTIF(N13:N42,"NON EXÉCUTÉ") -> 27 / 1 / 0 / 2 | I8: Tests sur la copie de travail uniquement, jamais la base de production ; sauvegarder la base avant chaque série.
A9: Bloqué | C9: =COUNTIF($K$13:$K$42,"Bloqué") -> 0 | D9: =IF($C$5=0,0,C9/$C$5) -> 0 | I9: Ajouter un cas : insérer une ligne dans le tableau. Colonnes grises : résultat de l'exécution automatique sur le banc (ne pas modifier).
A10: N/A | C10: =COUNTIF($K$13:$K$42,"N/A") -> 0 | D10: =IF($C$5=0,0,C10/$C$5) -> 0
A12: N° | B12: Écran | C12: Type de test | D12: Cas de test | E12: Prérequis | F12: Étapes | G12: Résultat attendu | H12: Priorité | I12: Testeur | J12: Date | K12: Statut | L12: Résultat obtenu / anomalie | M12: N° ticket | N12: Résultat (exécution automatique) | O12: Détail / preuve de l'exécution automatique
A13: 1 | B13: Tiers-payants | C13: Fonctionnel | D13: Créer / modifier un tiers-payant | E13: Droit | F13: 1. Créer, enregistrer, modifier le plafond | G13: Fiche enregistrée ; plafond pris en compte à la vente | H13: Moyenne | N13: OK PARTIEL | O13: etape2/test-tp-maj-selective.js : 31/31 assertions Non couvert : modification verifiee ; creation non jouee
A14: 2 | B14: Tiers payants désactivés | C14: Fonctionnel | D14: Lister et réactiver | E14: Tiers-payant désactivé | F14: 1. Ouvrir la liste 2. Rechercher par nom | G14: Seuls les désactivés apparaissent ; recherche OK | H14: Moyenne | N14: OK | O14: journal/test-tiers-payants-desactives.js : 5/5 OK
A15: 3 | B15: Clients | C15: Fonctionnel | D15: Créer un client assuré | E15: Tiers-payant | F15: 1. Créer le client avec matricule et taux | G15: Client utilisable en vente assurance | H15: Haute | N15: NON EXÉCUTÉ | O15: Pas de test automatique de creation de client assure : a faire a la main
A16: 4 | B16: Retour carnet dépôt | C16: Fonctionnel | D16: Retour avec code lu à la douchette | E16: Tiers-payant carnet | F16: 1. Nouveau retour, choisir le tiers-payant 2. Scanner le produit | G16: Produit trouvé ; code envoyé encodé (codes avec / ou # acceptés) | H16: Basse | N16: OK | O16: journal/test-retour-carnet-code-encode.js : 3/3 OK
A17: 5 | B17: Balance agée détaillée | C17: Fonctionnel | D17: Balance âgée | E17: Factures non réglées | F17: 1. Ouvrir, filtrer par organisme | G17: Montants par tranche d'âge cohérents avec les factures | H17: Moyenne | N17: NON EXÉCUTÉ | O17: Pas de test automatique des montants de la balance agee : a faire a la main
A18: 6 | B18: Balance agée détaillée | C18: Non-régression | D18: Ouverture et affichage de l'écran | E18: Profil ayant le droit du menu | F18: 1. Ouvrir GESTION DES TIERS-PAYANTS > Balance agée détaillée 2. Utiliser la recherche / les filtres de l'écran 3. Imprimer ou exporter si l'écran le propose | G18: L'écran s'ouvre sans message d'erreur ; la liste se charge ; filtres et impression/export fonctionnent ; aucune erreur au Centre de support | H18: Basse | N18: OK | O18: recette/recette-ecrans.js : ouvert par le menu, chargé en 3.0 s — exécuté le 24/10/2026 sur le banc
A19: 7 | B19: Groupe et Compagnie d'Ass | C19: Non-régression | D19: Ouverture et affichage de l'écran | E19: Profil ayant le droit du menu | F19: 1. Ouvrir GESTION DES TIERS-PAYANTS > Groupe et Compagnie d'Ass 2. Utiliser la recherche / les filtres de l'écran 3. Imprimer ou exporter si l'écran le propose | G19: L'écran s'ouvre sans message d'erreur ; la liste se charge ; filtres et impression/export fonctionnent ; aucune erreur au Centre de support | H19: Basse | N19: OK | O19: recette/recette-ecrans.js : ouvert par son composant (entrée introuvable sous ce libellé), chargé en 11.6 s — exécuté le 24/10/2026 sur le banc
A20: 8 | B20: Emplacements/Depot | C20: Non-régression | D20: Ouverture et affichage de l'écran | E20: Profil ayant le droit du menu | F20: 1. Ouvrir GESTION DES TIERS-PAYANTS > Emplacements/Depot 2. Utiliser la recherche / les filtres de l'écran 3. Imprimer ou exporter si l'écran le propose | G20: L'écran s'ouvre sans message d'erreur ; la liste se charge ; filtres et impression/export fonctionnent ; aucune erreur au Centre de support | H20: Basse | N20: OK | O20: recette/recette-ecrans.js : ouvert par le menu, chargé en 1.2 s — exécuté le 24/10/2026 sur le banc
A21: 9 | B21: Gestion des litiges | C21: Non-régression | D21: Ouverture et affichage de l'écran | E21: Profil ayant le droit du menu | F21: 1. Ouvrir GESTION DES TIERS-PAYANTS > Gestion des litiges 2. Utiliser la recherche / les filtres de l'écran 3. Imprimer ou exporter si l'écran le propose | G21: L'écran s'ouvre sans message d'erreur ; la liste se charge ; filtres et impression/export fonctionnent ; aucune erreur au Centre de support | H21: Basse | N21: OK | O21: recette/recette-ecrans.js : ouvert par son composant (entrée introuvable sous ce libellé), chargé en 11.4 s — exécuté le 24/10/2026 sur le banc
A22: 10 | B22: Tiers payants désactivés | C22: Non-régression | D22: Ouverture et affichage de l'écran | E22: Profil ayant le droit du menu | F22: 1. Ouvrir GESTION DES TIERS-PAYANTS > Tiers payants désactivés 2. Utiliser la recherche / les filtres de l'écran 3. Imprimer ou exporter si l'écran le propose | G22: L'écran s'ouvre sans message d'erreur ; la liste se charge ; filtres et impression/export fonctionnent ; aucune erreur au Centre de support | H22: Basse | N22: OK | O22: recette/recette-ecrans.js : ouvert par le menu, chargé en 1.3 s, 1 écriture(s) interceptée(s) — exécuté le 24/10/2026 sur le banc
A23: 11 | B23: Balance âgée récap | C23: Non-régression | D23: Ouverture et affichage de l'écran | E23: Profil ayant le droit du menu | F23: 1. Ouvrir GESTION DES TIERS-PAYANTS > Balance âgée récap 2. Utiliser la recherche / les filtres de l'écran 3. Imprimer ou exporter si l'écran le propose | G23: L'écran s'ouvre sans message d'erreur ; la liste se charge ; filtres et impression/export fonctionnent ; aucune erreur au Centre de support | H23: Basse | N23: OK | O23: recette/recette-ecrans.js : ouvert par le menu, chargé en 2.0 s — exécuté le 24/10/2026 sur le banc
A24: 12 | B24: Clients désactivés | C24: Non-régression | D24: Ouverture et affichage de l'écran | E24: Profil ayant le droit du menu | F24: 1. Ouvrir GESTION DES TIERS-PAYANTS > Clients désactivés 2. Utiliser la recherche / les filtres de l'écran 3. Imprimer ou exporter si l'écran le propose | G24: L'écran s'ouvre sans message d'erreur ; la liste se charge ; filtres et impression/export fonctionnent ; aucune erreur au Centre de support | H24: Basse | N24: OK | O24: recette/recette-ecrans.js : ouvert par le menu, chargé en 1.7 s — exécuté le 24/10/2026 sur le banc
... A42: 30 | B42: Catégorie Client | C42: Non-régression | D42: Ouverture et affichage de l'écran | E42: Profil ayant le droit du menu | F42: 1. Ouvrir GESTION DES TIERS-PAYANTS > Catégorie Client 2. Utiliser la recherche / les filtres de l'écran 3. Imprimer ou exporter si l'écran le propose | G42: L'écran s'ouvre sans message d'erreur ; la liste se charge ; filtres et impression/export fonctionnent ; aucune erreur au Centre de support | H42: Basse | N42: OK | O42: recette/recette-ecrans.js : ouvert par le menu, chargé en 1.8 s — exécuté le 24/10/2026 sur le banc

Sheet Menu pharmacien
A1: PRESTIGE — Cahier de recette — MENU PHARMACIEN
A2: Version testée : | E2: Base de test (jamais la production) :
A4: Synthèse du module | I4: Mode d'emploi
A5: Total des cas | C5: =COUNTA($A$13:$A$16) -> 4 | E5: Avancement (testés hors N/A) | G5: =IF(($C$5-$C$10)=0,0,($C$7+$C$8+$C$9)/($C$5-$C$10)) -> 0 | I5: Remplir uniquement les cellules jaunes : Testeur, Date (jj/mm/aaaa), Statut (liste), Résultat obtenu, N° ticket.
A6: Non testé | C6: =C5-COUNTIF($K$13:$K$16,"OK")-COUNTIF($K$13:$K$16,"KO")-COUNTIF($K$13:$K$16,"Bloqué")-COUNTIF($K$13:$K$16,"N/A") -> 4 | D6: =IF($C$5=0,0,C6/$C$5) -> 1 | E6: Taux de réussite (OK / testés) | G6: =IF(($C$7+$C$8+$C$9)=0,0,$C$7/($C$7+$C$8+$C$9)) -> 0 | I6: Statut : Non testé (vide) · OK · KO (décrire et ouvrir un ticket) · Bloqué · N/A (sans objet).
A7: OK | C7: =COUNTIF($K$13:$K$16,"OK") -> 0 | D7: =IF($C$5=0,0,C7/$C$5) -> 0 | E7: KO en priorité Haute | G7: =COUNTIFS($K$13:$K$16,"KO",$H$13:$H$16,"Haute") -> 0 | I7: Exemple : Testeur « A. KONÉ » · Date 24/10/2026 · Statut KO · Résultat « Ticket sans le nom du vendeur » · Ticket « SUP-0042 ».
A8: KO | C8: =COUNTIF($K$13:$K$16,"KO") -> 0 | D8: =IF($C$5=0,0,C8/$C$5) -> 0 | E8: Exécution automatique : OK / OK partiel / KO / non exécuté | G8: =COUNTIF(N13:N16,"OK")&" / "&COUNTIF(N13:N16,"OK PARTIEL")&" / "&COUNTIF(N13:N16,"KO")&" / "&COUNTIF(N13:N16,"NON EXÉCUTÉ") -> 4 / 0 / 0 / 0 | I8: Tests sur la copie de travail uniquement, jamais la base de production ; sauvegarder la base avant chaque série.
A9: Bloqué | C9: =COUNTIF($K$13:$K$16,"Bloqué") -> 0 | D9: =IF($C$5=0,0,C9/$C$5) -> 0 | I9: Ajouter un cas : insérer une ligne dans le tableau. Colonnes grises : résultat de l'exécution automatique sur le banc (ne pas modifier).
A10: N/A | C10: =COUNTIF($K$13:$K$16,"N/A") -> 0 | D10: =IF($C$5=0,0,C10/$C$5) -> 0
A12: N° | B12: Écran | C12: Type de test | D12: Cas de test | E12: Prérequis | F12: Étapes | G12: Résultat attendu | H12: Priorité | I12: Testeur | J12: Date | K12: Statut | L12: Résultat obtenu / anomalie | M12: N° ticket | N12: Résultat (exécution automatique) | O12: Détail / preuve de l'exécution automatique
